2025-02-13 16:02:05,638 - log_util.py[DEBUG]: Cloud-init v. 24.4-0ubuntu1~22.04.1 running 'init-local' at Thu, 13 Feb 2025 16:02:05 +0000. Up 5.76 seconds.
2025-02-13 16:02:05,638 - main.py[INFO]: PID [1] started cloud-init 'init-local'.
2025-02-13 16:02:05,638 - main.py[DEBUG]: No kernel command line url found.
2025-02-13 16:02:05,638 - main.py[DEBUG]: Closing stdin
2025-02-13 16:02:05,641 - util.py[DEBUG]: Writing to /var/log/cloud-init.log - ab: [640] 0 bytes
2025-02-13 16:02:05,642 - util.py[DEBUG]: Changing the ownership of /var/log/cloud-init.log to 104:4
2025-02-13 16:02:05,642 - util.py[DEBUG]: Writing to /var/lib/cloud/data/python-version - wb: [644] 4 bytes
2025-02-13 16:02:05,643 - util.py[DEBUG]: Attempting to remove /var/lib/cloud/instance/boot-finished
2025-02-13 16:02:05,651 - handlers.py[DEBUG]: start: init-local/check-cache: attempting to read from cache [check]
2025-02-13 16:02:05,651 - util.py[DEBUG]: Reading from /var/lib/cloud/instance/obj.pkl (quiet=False)
2025-02-13 16:02:05,651 - stages.py[DEBUG]: no cache found
2025-02-13 16:02:05,651 - handlers.py[DEBUG]: finish: init-local/check-cache: SUCCESS: no cache found
2025-02-13 16:02:05,663 - stages.py[DEBUG]: Using distro class <class 'cloudinit.distros.ubuntu.Distro'>
2025-02-13 16:02:05,663 - sources[DEBUG]: Looking for data source in: ['Akamai', 'None'], via packages ['', 'cloudinit.sources'] that matches dependencies ['FILESYSTEM']
2025-02-13 16:02:05,675 - sources[DEBUG]: Searching for local data source in: ['DataSourceAkamaiLocal']
2025-02-13 16:02:05,675 - handlers.py[DEBUG]: start: init-local/search-AkamaiLocal: searching for local data from DataSourceAkamaiLocal
2025-02-13 16:02:05,675 - sources[DEBUG]: Seeing if we can get any data from <class 'cloudinit.sources.DataSourceAkamai.DataSourceAkamaiLocal'>
2025-02-13 16:02:05,675 - DataSourceAkamai.py[DEBUG]: Setting up Akamai DataSource
2025-02-13 16:02:05,675 - dmi.py[DEBUG]: querying dmi data /sys/class/dmi/id/board_serial
2025-02-13 16:02:05,675 - dmi.py[DEBUG]: did not find /sys/class/dmi/id/board_serial
2025-02-13 16:02:05,676 - subp.py[DEBUG]: Running command ['/usr/sbin/dmidecode', '--string', 'baseboard-serial-number'] with allowed return codes [0] (shell=False, capture=True)
2025-02-13 16:02:05,679 - dmi.py[DEBUG]: dmidecode returned '' for 'baseboard-serial-number'
2025-02-13 16:02:05,679 - sources[DEBUG]: Update datasource metadata and network config due to events: boot-new-instance
2025-02-13 16:02:05,679 - sources[DEBUG]: Detected DataSourceAkamaiLocal
2025-02-13 16:02:05,680 - DataSourceAkamai.py[DEBUG]: Getting data from Akamai DataSource
2025-02-13 16:02:05,680 - dmi.py[DEBUG]: querying dmi data /sys/class/dmi/id/sys_vendor
2025-02-13 16:02:05,680 - dmi.py[DEBUG]: querying dmi data /sys/class/dmi/id/product_serial
2025-02-13 16:02:05,680 - util.py[DEBUG]: Reading from /sys/class/net/eth0/addr_assign_type (quiet=False)
2025-02-13 16:02:05,680 - util.py[DEBUG]: Reading 2 bytes from /sys/class/net/eth0/addr_assign_type
2025-02-13 16:02:05,680 - util.py[DEBUG]: Reading from /sys/class/net/eth0/uevent (quiet=False)
2025-02-13 16:02:05,680 - util.py[DEBUG]: Reading 25 bytes from /sys/class/net/eth0/uevent
2025-02-13 16:02:05,680 - util.py[DEBUG]: Reading from /sys/class/net/eth0/address (quiet=False)
2025-02-13 16:02:05,680 - util.py[DEBUG]: Reading 18 bytes from /sys/class/net/eth0/address
2025-02-13 16:02:05,680 - net[DEBUG]: ovs-vsctl not in PATH; not detecting Open vSwitch interfaces
2025-02-13 16:02:05,680 - util.py[DEBUG]: Reading from /sys/class/net/eth0/device/device (quiet=False)
2025-02-13 16:02:05,681 - util.py[DEBUG]: Reading 7 bytes from /sys/class/net/eth0/device/device
2025-02-13 16:02:05,681 - util.py[DEBUG]: Reading from /sys/class/net/lo/addr_assign_type (quiet=False)
2025-02-13 16:02:05,681 - util.py[DEBUG]: Reading 2 bytes from /sys/class/net/lo/addr_assign_type
2025-02-13 16:02:05,681 - util.py[DEBUG]: Reading from /sys/class/net/lo/uevent (quiet=False)
2025-02-13 16:02:05,681 - util.py[DEBUG]: Reading 23 bytes from /sys/class/net/lo/uevent
2025-02-13 16:02:05,681 - util.py[DEBUG]: Reading from /sys/class/net/lo/address (quiet=False)
2025-02-13 16:02:05,681 - util.py[DEBUG]: Reading 18 bytes from /sys/class/net/lo/address
2025-02-13 16:02:05,681 - util.py[DEBUG]: Reading from /sys/class/net/lo/device/device (quiet=False)
2025-02-13 16:02:05,681 - util.py[DEBUG]: Reading from /sys/class/net/eth0/type (quiet=False)
2025-02-13 16:02:05,681 - util.py[DEBUG]: Reading 2 bytes from /sys/class/net/eth0/type
2025-02-13 16:02:05,681 - util.py[DEBUG]: Reading from /sys/class/net/lo/type (quiet=False)
2025-02-13 16:02:05,681 - util.py[DEBUG]: Reading 4 bytes from /sys/class/net/lo/type
2025-02-13 16:02:05,681 - ephemeral.py[DEBUG]: No connectivity URLs provided. Skipping connectivity check before ephemeral network setup.
2025-02-13 16:02:05,681 - ephemeral.py[DEBUG]: No connectivity to IMDS, attempting DHCP setup.
2025-02-13 16:02:05,681 - util.py[DEBUG]: Reading from /sys/class/net/eth0/operstate (quiet=False)
2025-02-13 16:02:05,682 - util.py[DEBUG]: Reading 5 bytes from /sys/class/net/eth0/operstate
2025-02-13 16:02:05,682 - subp.py[DEBUG]: Running command ['ip', 'link', 'set', 'dev', 'eth0', 'up'] with allowed return codes [0] (shell=False, capture=True)
2025-02-13 16:02:05,697 - performance.py[DEBUG]: Running ['ip', 'link', 'set', 'dev', 'eth0', 'up'] took 0.016 seconds
2025-02-13 16:02:05,698 - ephemeral.py[DEBUG]: Successfully brought up eth0 for ephemeral ipv6 networking.
2025-02-13 16:02:05,698 - url_helper.py[DEBUG]: [0/5] open 'http://[fd00:a9fe:a9fe::1]/v1/token' with {'url': 'http://[fd00:a9fe:a9fe::1]/v1/token', 'stream': False, 'allow_redirects': True, 'method': 'PUT', 'timeout': 30.0, 'headers': {'Metadata-Token-Expiry-Seconds': '300', 'User-Agent': 'Cloud-Init/24.4-0ubuntu1~22.04.1'}} configuration
2025-02-13 16:02:05,707 - url_helper.py[DEBUG]: Please wait 2 seconds while we wait to try again
2025-02-13 16:02:07,707 - url_helper.py[DEBUG]: [1/5] open 'http://[fd00:a9fe:a9fe::1]/v1/token' with {'url': 'http://[fd00:a9fe:a9fe::1]/v1/token', 'stream': False, 'allow_redirects': True, 'method': 'PUT', 'timeout': 30.0, 'headers': {'Metadata-Token-Expiry-Seconds': '300', 'User-Agent': 'Cloud-Init/24.4-0ubuntu1~22.04.1'}} configuration
2025-02-13 16:02:08,099 - url_helper.py[DEBUG]: Read from http://[fd00:a9fe:a9fe::1]/v1/token (200, 64b) after 2 attempts
2025-02-13 16:02:08,100 - url_helper.py[DEBUG]: [0/3] open 'http://[fd00:a9fe:a9fe::1]/v1/instance' with {'url': 'http://[fd00:a9fe:a9fe::1]/v1/instance', 'stream': False, 'allow_redirects': True, 'method': 'GET', 'timeout': 30.0, 'headers': {'Accept': 'application/json', 'Metadata-Token': 'ed15c3abfd193a36cdc01c42c43704746ae9944d8d7cd21915ab2fed4a3e45c0', 'User-Agent': 'Cloud-Init/24.4-0ubuntu1~22.04.1'}} configuration
2025-02-13 16:02:08,989 - url_helper.py[DEBUG]: Read from http://[fd00:a9fe:a9fe::1]/v1/instance (200, 407b) after 1 attempts
2025-02-13 16:02:08,990 - url_helper.py[DEBUG]: [0/3] open 'http://[fd00:a9fe:a9fe::1]/v1/user-data' with {'url': 'http://[fd00:a9fe:a9fe::1]/v1/user-data', 'stream': False, 'allow_redirects': True, 'method': 'GET', 'timeout': 30.0, 'headers': {'Metadata-Token': 'ed15c3abfd193a36cdc01c42c43704746ae9944d8d7cd21915ab2fed4a3e45c0', 'User-Agent': 'Cloud-Init/24.4-0ubuntu1~22.04.1'}} configuration
2025-02-13 16:02:09,502 - url_helper.py[DEBUG]: Read from http://[fd00:a9fe:a9fe::1]/v1/user-data (200, 0b) after 1 attempts
2025-02-13 16:02:09,503 - util.py[DEBUG]: Reading from /etc/hosts (quiet=False)
2025-02-13 16:02:09,503 - util.py[DEBUG]: Reading 181 bytes from /etc/hosts
2025-02-13 16:02:09,505 - util.py[DEBUG]: Writing to /run/cloud-init/cloud-id-akamai - wb: [644] 7 bytes
2025-02-13 16:02:09,505 - util.py[DEBUG]: Creating symbolic link from '/run/cloud-init/cloud-id' => '/run/cloud-init/cloud-id-akamai'
2025-02-13 16:02:09,506 - atomic_helper.py[DEBUG]: Atomically writing to file /run/cloud-init/instance-data-sensitive.json (via temporary file /run/cloud-init/tmpa7gr5544) - w: [600] 8726 bytes/chars
2025-02-13 16:02:09,506 - atomic_helper.py[DEBUG]: Atomically writing to file /run/cloud-init/instance-data.json (via temporary file /run/cloud-init/tmpxitcsn9w) - w: [644] 1941 bytes/chars
2025-02-13 16:02:09,506 - performance.py[DEBUG]: Getting metadata took 3.827 seconds
2025-02-13 16:02:09,506 - handlers.py[DEBUG]: finish: init-local/search-AkamaiLocal: SUCCESS: found local data from DataSourceAkamaiLocal
2025-02-13 16:02:09,506 - util.py[DEBUG]: Attempting to remove /var/lib/cloud/instance
2025-02-13 16:02:09,507 - stages.py[INFO]: Loaded datasource DataSourceAkamaiLocal - DataSourceAkamaiLocal
2025-02-13 16:02:09,507 - util.py[DEBUG]: Reading from /etc/cloud/cloud.cfg (quiet=False)
2025-02-13 16:02:09,507 - util.py[DEBUG]: Reading 3766 bytes from /etc/cloud/cloud.cfg
2025-02-13 16:02:09,507 - util.py[DEBUG]: Attempting to load yaml from string of length 3766 with allowed root types (<class 'dict'>,)
2025-02-13 16:02:09,519 - util.py[DEBUG]: Reading from /etc/cloud/cloud.cfg.d/99-linode.cfg (quiet=False)
2025-02-13 16:02:09,519 - util.py[DEBUG]: Reading 492 bytes from /etc/cloud/cloud.cfg.d/99-linode.cfg
2025-02-13 16:02:09,519 - util.py[DEBUG]: Attempting to load yaml from string of length 492 with allowed root types (<class 'dict'>,)
2025-02-13 16:02:09,521 - util.py[DEBUG]: Reading from /etc/cloud/cloud.cfg.d/90_dpkg.cfg (quiet=False)
2025-02-13 16:02:09,521 - util.py[DEBUG]: Reading 333 bytes from /etc/cloud/cloud.cfg.d/90_dpkg.cfg
2025-02-13 16:02:09,521 - util.py[DEBUG]: Attempting to load yaml from string of length 333 with allowed root types (<class 'dict'>,)
2025-02-13 16:02:09,523 - util.py[DEBUG]: Reading from /etc/cloud/cloud.cfg.d/05_logging.cfg (quiet=False)
2025-02-13 16:02:09,523 - util.py[DEBUG]: Reading 2071 bytes from /etc/cloud/cloud.cfg.d/05_logging.cfg
2025-02-13 16:02:09,523 - util.py[DEBUG]: Attempting to load yaml from string of length 2071 with allowed root types (<class 'dict'>,)
2025-02-13 16:02:09,527 - util.py[DEBUG]: Reading from /run/cloud-init/cloud.cfg (quiet=False)
2025-02-13 16:02:09,527 - util.py[DEBUG]: Reading 34 bytes from /run/cloud-init/cloud.cfg
2025-02-13 16:02:09,527 - util.py[DEBUG]: Attempting to load yaml from string of length 34 with allowed root types (<class 'dict'>,)
2025-02-13 16:02:09,527 - util.py[DEBUG]: Attempting to load yaml from string of length 0 with allowed root types (<class 'dict'>,)
2025-02-13 16:02:09,527 - util.py[DEBUG]: loaded blob returned None, returning default.
2025-02-13 16:02:09,528 - util.py[DEBUG]: Attempting to remove /var/lib/cloud/instance
2025-02-13 16:02:09,528 - util.py[DEBUG]: Creating symbolic link from '/var/lib/cloud/instance' => '/var/lib/cloud/instances/71855604'
2025-02-13 16:02:09,529 - util.py[DEBUG]: Reading from /var/lib/cloud/instances/71855604/datasource (quiet=False)
2025-02-13 16:02:09,530 - util.py[DEBUG]: Writing to /var/lib/cloud/instances/71855604/datasource - wb: [644] 45 bytes
2025-02-13 16:02:09,530 - util.py[DEBUG]: Writing to /var/lib/cloud/data/previous-datasource - wb: [644] 45 bytes
2025-02-13 16:02:09,530 - util.py[DEBUG]: Reading from /var/lib/cloud/data/instance-id (quiet=False)
2025-02-13 16:02:09,530 - stages.py[DEBUG]: previous iid found to be NO_PREVIOUS_INSTANCE_ID
2025-02-13 16:02:09,530 - util.py[DEBUG]: Writing to /var/lib/cloud/data/instance-id - wb: [644] 9 bytes
2025-02-13 16:02:09,531 - util.py[DEBUG]: Writing to /run/cloud-init/.instance-id - wb: [644] 9 bytes
2025-02-13 16:02:09,531 - util.py[DEBUG]: Writing to /var/lib/cloud/data/previous-instance-id - wb: [644] 24 bytes
2025-02-13 16:02:09,532 - util.py[DEBUG]: Writing to /var/lib/cloud/instance/obj.pkl - wb: [400] 7026 bytes
2025-02-13 16:02:09,532 - main.py[DEBUG]: [local] init will now be targeting instance id: 71855604. new=True
2025-02-13 16:02:09,532 - util.py[DEBUG]: Reading from /etc/cloud/cloud.cfg (quiet=False)
2025-02-13 16:02:09,532 - util.py[DEBUG]: Reading 3766 bytes from /etc/cloud/cloud.cfg
2025-02-13 16:02:09,532 - util.py[DEBUG]: Attempting to load yaml from string of length 3766 with allowed root types (<class 'dict'>,)
2025-02-13 16:02:09,544 - util.py[DEBUG]: Reading from /etc/cloud/cloud.cfg.d/99-linode.cfg (quiet=False)
2025-02-13 16:02:09,544 - util.py[DEBUG]: Reading 492 bytes from /etc/cloud/cloud.cfg.d/99-linode.cfg
2025-02-13 16:02:09,544 - util.py[DEBUG]: Attempting to load yaml from string of length 492 with allowed root types (<class 'dict'>,)
2025-02-13 16:02:09,546 - util.py[DEBUG]: Reading from /etc/cloud/cloud.cfg.d/90_dpkg.cfg (quiet=False)
2025-02-13 16:02:09,546 - util.py[DEBUG]: Reading 333 bytes from /etc/cloud/cloud.cfg.d/90_dpkg.cfg
2025-02-13 16:02:09,546 - util.py[DEBUG]: Attempting to load yaml from string of length 333 with allowed root types (<class 'dict'>,)
2025-02-13 16:02:09,548 - util.py[DEBUG]: Reading from /etc/cloud/cloud.cfg.d/05_logging.cfg (quiet=False)
2025-02-13 16:02:09,548 - util.py[DEBUG]: Reading 2071 bytes from /etc/cloud/cloud.cfg.d/05_logging.cfg
2025-02-13 16:02:09,548 - util.py[DEBUG]: Attempting to load yaml from string of length 2071 with allowed root types (<class 'dict'>,)
2025-02-13 16:02:09,552 - util.py[DEBUG]: Reading from /run/cloud-init/cloud.cfg (quiet=False)
2025-02-13 16:02:09,552 - util.py[DEBUG]: Reading 34 bytes from /run/cloud-init/cloud.cfg
2025-02-13 16:02:09,552 - util.py[DEBUG]: Attempting to load yaml from string of length 34 with allowed root types (<class 'dict'>,)
2025-02-13 16:02:09,552 - util.py[DEBUG]: Attempting to load yaml from string of length 0 with allowed root types (<class 'dict'>,)
2025-02-13 16:02:09,552 - util.py[DEBUG]: loaded blob returned None, returning default.
2025-02-13 16:02:09,553 - stages.py[DEBUG]: Using distro class <class 'cloudinit.distros.ubuntu.Distro'>
2025-02-13 16:02:09,554 - util.py[DEBUG]: Reading from /sys/class/net/eth0/address (quiet=False)
2025-02-13 16:02:09,554 - util.py[DEBUG]: Reading 18 bytes from /sys/class/net/eth0/address
2025-02-13 16:02:09,555 - util.py[DEBUG]: Reading from /sys/class/net/lo/address (quiet=False)
2025-02-13 16:02:09,555 - util.py[DEBUG]: Reading 18 bytes from /sys/class/net/lo/address
2025-02-13 16:02:09,555 - stages.py[DEBUG]: network config disabled by system_cfg
2025-02-13 16:02:09,555 - stages.py[INFO]: network config is disabled by system_cfg
2025-02-13 16:02:09,555 - main.py[DEBUG]: Network connectivity determined unnecessary for cloud-init's network stage. Reason: user data: no configuration found, vendor data: no configuration found, vendor data2: no configuration found
2025-02-13 16:02:09,555 - util.py[DEBUG]: Writing to /run/cloud-init/.skip-network - wb: [644] 0 bytes
2025-02-13 16:02:09,555 - main.py[DEBUG]: [local] Exiting. datasource DataSourceAkamaiLocal not in local mode.
2025-02-13 16:02:09,555 - util.py[DEBUG]: Reading from /proc/uptime (quiet=False)
2025-02-13 16:02:09,556 - util.py[DEBUG]: Reading 10 bytes from /proc/uptime
2025-02-13 16:02:09,556 - atomic_helper.py[DEBUG]: Atomically writing to file /var/lib/cloud/data/status.json (via temporary file /var/lib/cloud/data/tmpukr2jbyb) - w: [644] 502 bytes/chars
2025-02-13 16:02:09,556 - performance.py[DEBUG]: cloud-init stage: 'init-local' took 4.103 seconds
2025-02-13 16:02:09,556 - handlers.py[DEBUG]: finish: init-local: SUCCESS: searching for local datasources
2025-02-13 16:02:13,345 - log_util.py[DEBUG]: Cloud-init v. 24.4-0ubuntu1~22.04.1 running 'init' at Thu, 13 Feb 2025 16:02:13 +0000. Up 13.53 seconds.
2025-02-13 16:02:13,345 - main.py[INFO]: PID [1] started cloud-init 'init'.
2025-02-13 16:02:13,346 - main.py[DEBUG]: No kernel command line url found.
2025-02-13 16:02:13,346 - main.py[DEBUG]: Closing stdin
2025-02-13 16:02:13,348 - util.py[DEBUG]: Writing to /var/log/cloud-init.log - ab: [640] 0 bytes
2025-02-13 16:02:13,348 - util.py[DEBUG]: Changing the ownership of /var/log/cloud-init.log to 104:4
2025-02-13 16:02:13,348 - util.py[DEBUG]: Reading from /var/lib/cloud/data/python-version (quiet=False)
2025-02-13 16:02:13,348 - util.py[DEBUG]: Reading 4 bytes from /var/lib/cloud/data/python-version
2025-02-13 16:02:13,349 - subp.py[DEBUG]: Running command ['ip', '--json', 'addr'] with allowed return codes [0] (shell=False, capture=True)
2025-02-13 16:02:13,355 - subp.py[DEBUG]: Running command ['ip', '-o', 'route', 'list'] with allowed return codes [0] (shell=False, capture=True)
2025-02-13 16:02:13,356 - subp.py[DEBUG]: Running command ['ip', '--oneline', '-6', 'route', 'list', 'table', 'all'] with allowed return codes [0, 1] (shell=False, capture=True)
2025-02-13 16:02:13,364 - handlers.py[DEBUG]: start: init-network/check-cache: attempting to read from cache [trust]
2025-02-13 16:02:13,364 - util.py[DEBUG]: Reading from /var/lib/cloud/instance/obj.pkl (quiet=False)
2025-02-13 16:02:13,364 - util.py[DEBUG]: Reading 7026 bytes from /var/lib/cloud/instance/obj.pkl
2025-02-13 16:02:13,370 - util.py[DEBUG]: Reading from /run/cloud-init/.instance-id (quiet=False)
2025-02-13 16:02:13,370 - util.py[DEBUG]: Reading 9 bytes from /run/cloud-init/.instance-id
2025-02-13 16:02:13,370 - stages.py[DEBUG]: restored from cache with run check: DataSourceAkamaiLocal
2025-02-13 16:02:13,370 - handlers.py[DEBUG]: finish: init-network/check-cache: SUCCESS: restored from cache with run check: DataSourceAkamaiLocal
2025-02-13 16:02:13,370 - util.py[DEBUG]: Reading from /etc/cloud/cloud.cfg (quiet=False)
2025-02-13 16:02:13,370 - util.py[DEBUG]: Reading 3766 bytes from /etc/cloud/cloud.cfg
2025-02-13 16:02:13,370 - util.py[DEBUG]: Attempting to load yaml from string of length 3766 with allowed root types (<class 'dict'>,)
2025-02-13 16:02:13,395 - util.py[DEBUG]: Reading from /etc/cloud/cloud.cfg.d/99-linode.cfg (quiet=False)
2025-02-13 16:02:13,395 - util.py[DEBUG]: Reading 492 bytes from /etc/cloud/cloud.cfg.d/99-linode.cfg
2025-02-13 16:02:13,397 - util.py[DEBUG]: Attempting to load yaml from string of length 492 with allowed root types (<class 'dict'>,)
2025-02-13 16:02:13,398 - util.py[DEBUG]: Reading from /etc/cloud/cloud.cfg.d/90_dpkg.cfg (quiet=False)
2025-02-13 16:02:13,399 - util.py[DEBUG]: Reading 333 bytes from /etc/cloud/cloud.cfg.d/90_dpkg.cfg
2025-02-13 16:02:13,399 - util.py[DEBUG]: Attempting to load yaml from string of length 333 with allowed root types (<class 'dict'>,)
2025-02-13 16:02:13,404 - util.py[DEBUG]: Reading from /etc/cloud/cloud.cfg.d/05_logging.cfg (quiet=False)
2025-02-13 16:02:13,404 - util.py[DEBUG]: Reading 2071 bytes from /etc/cloud/cloud.cfg.d/05_logging.cfg
2025-02-13 16:02:13,404 - util.py[DEBUG]: Attempting to load yaml from string of length 2071 with allowed root types (<class 'dict'>,)
2025-02-13 16:02:13,411 - util.py[DEBUG]: Reading from /run/cloud-init/cloud.cfg (quiet=False)
2025-02-13 16:02:13,413 - util.py[DEBUG]: Reading 34 bytes from /run/cloud-init/cloud.cfg
2025-02-13 16:02:13,413 - util.py[DEBUG]: Attempting to load yaml from string of length 34 with allowed root types (<class 'dict'>,)
2025-02-13 16:02:13,413 - util.py[DEBUG]: Attempting to load yaml from string of length 0 with allowed root types (<class 'dict'>,)
2025-02-13 16:02:13,413 - util.py[DEBUG]: loaded blob returned None, returning default.
2025-02-13 16:02:13,414 - stages.py[INFO]: Instance link already exists, not recreating it.
2025-02-13 16:02:13,414 - util.py[DEBUG]: Reading from /var/lib/cloud/instances/71855604/datasource (quiet=False)
2025-02-13 16:02:13,415 - util.py[DEBUG]: Reading 45 bytes from /var/lib/cloud/instances/71855604/datasource
2025-02-13 16:02:13,415 - util.py[DEBUG]: Writing to /var/lib/cloud/instances/71855604/datasource - wb: [644] 45 bytes
2025-02-13 16:02:13,417 - util.py[DEBUG]: Writing to /var/lib/cloud/data/previous-datasource - wb: [644] 45 bytes
2025-02-13 16:02:13,419 - util.py[DEBUG]: Reading from /var/lib/cloud/data/instance-id (quiet=False)
2025-02-13 16:02:13,419 - util.py[DEBUG]: Reading 9 bytes from /var/lib/cloud/data/instance-id
2025-02-13 16:02:13,419 - stages.py[DEBUG]: previous iid found to be 71855604
2025-02-13 16:02:13,419 - util.py[DEBUG]: Writing to /var/lib/cloud/data/instance-id - wb: [644] 9 bytes
2025-02-13 16:02:13,419 - util.py[DEBUG]: Writing to /run/cloud-init/.instance-id - wb: [644] 9 bytes
2025-02-13 16:02:13,420 - util.py[DEBUG]: Writing to /var/lib/cloud/data/previous-instance-id - wb: [644] 9 bytes
2025-02-13 16:02:13,422 - util.py[DEBUG]: Writing to /var/lib/cloud/instance/obj.pkl - wb: [400] 7038 bytes
2025-02-13 16:02:13,422 - stages.py[INFO]: Not re-loading configuration, instance id and datasource have not changed.
2025-02-13 16:02:13,423 - main.py[DEBUG]: [net] init will now be targeting instance id: 71855604. new=False
2025-02-13 16:02:13,423 - util.py[DEBUG]: Reading from /sys/class/net/eth0/address (quiet=False)
2025-02-13 16:02:13,423 - util.py[DEBUG]: Reading 18 bytes from /sys/class/net/eth0/address
2025-02-13 16:02:13,423 - util.py[DEBUG]: Reading from /sys/class/net/lo/address (quiet=False)
2025-02-13 16:02:13,424 - util.py[DEBUG]: Reading 18 bytes from /sys/class/net/lo/address
2025-02-13 16:02:13,424 - stages.py[DEBUG]: network config disabled by system_cfg
2025-02-13 16:02:13,424 - stages.py[INFO]: network config is disabled by system_cfg
2025-02-13 16:02:13,424 - handlers.py[DEBUG]: start: init-network/setup-datasource: setting up datasource
2025-02-13 16:02:13,424 - handlers.py[DEBUG]: finish: init-network/setup-datasource: SUCCESS: setting up datasource
2025-02-13 16:02:13,424 - util.py[DEBUG]: Writing to /var/lib/cloud/instances/71855604/user-data.txt - wb: [600] 0 bytes
2025-02-13 16:02:13,428 - util.py[DEBUG]: Writing to /var/lib/cloud/instances/71855604/user-data.txt.i - wb: [600] 308 bytes
2025-02-13 16:02:13,429 - util.py[DEBUG]: Writing to /var/lib/cloud/instances/71855604/vendor-data.txt - wb: [600] 0 bytes
2025-02-13 16:02:13,430 - util.py[DEBUG]: Writing to /var/lib/cloud/instances/71855604/vendor-data.txt.i - wb: [600] 308 bytes
2025-02-13 16:02:13,430 - util.py[DEBUG]: Writing to /var/lib/cloud/instances/71855604/vendor-data2.txt - wb: [600] 0 bytes
2025-02-13 16:02:13,434 - util.py[DEBUG]: Writing to /var/lib/cloud/instances/71855604/vendor-data2.txt.i - wb: [600] 308 bytes
2025-02-13 16:02:13,434 - stages.py[DEBUG]: Using distro class <class 'cloudinit.distros.ubuntu.Distro'>
2025-02-13 16:02:13,437 - util.py[DEBUG]: Writing to /var/lib/cloud/instances/71855604/sem/consume_data - wb: [644] 24 bytes
2025-02-13 16:02:13,437 - helpers.py[DEBUG]: Running consume_data using lock (<FileLock using file '/var/lib/cloud/instances/71855604/sem/consume_data'>)
2025-02-13 16:02:13,437 - handlers.py[DEBUG]: start: init-network/consume-user-data: reading and applying user-data
2025-02-13 16:02:13,438 - stages.py[DEBUG]: Added default handler for {'text/cloud-config-jsonp', 'text/cloud-config'} from CloudConfigPartHandler: [['text/cloud-config', 'text/cloud-config-jsonp']]
2025-02-13 16:02:13,438 - stages.py[DEBUG]: Added default handler for {'text/x-shellscript'} from ShellScriptPartHandler: [['text/x-shellscript']]
2025-02-13 16:02:13,438 - stages.py[DEBUG]: Added default handler for {'text/x-shellscript-per-boot'} from ShellScriptByFreqPartHandler: [['text/x-shellscript-per-boot']]
2025-02-13 16:02:13,438 - stages.py[DEBUG]: Added default handler for {'text/x-shellscript-per-instance'} from ShellScriptByFreqPartHandler: [['text/x-shellscript-per-instance']]
2025-02-13 16:02:13,438 - stages.py[DEBUG]: Added default handler for {'text/x-shellscript-per-once'} from ShellScriptByFreqPartHandler: [['text/x-shellscript-per-once']]
2025-02-13 16:02:13,438 - stages.py[DEBUG]: Added default handler for {'text/cloud-boothook'} from BootHookPartHandler: [['text/cloud-boothook']]
2025-02-13 16:02:13,438 - stages.py[DEBUG]: Added default handler for {'text/jinja2'} from JinjaTemplatePartHandler: [['text/jinja2']]
2025-02-13 16:02:13,438 - handlers[DEBUG]: Calling handler CloudConfigPartHandler: [['text/cloud-config', 'text/cloud-config-jsonp']] (__begin__, None, 3) with frequency once-per-instance
2025-02-13 16:02:13,438 - handlers[DEBUG]: Calling handler ShellScriptPartHandler: [['text/x-shellscript']] (__begin__, None, 2) with frequency once-per-instance
2025-02-13 16:02:13,438 - handlers[DEBUG]: Calling handler ShellScriptByFreqPartHandler: [['text/x-shellscript-per-boot']] (__begin__, None, 2) with frequency once-per-instance
2025-02-13 16:02:13,438 - handlers[DEBUG]: Calling handler ShellScriptByFreqPartHandler: [['text/x-shellscript-per-instance']] (__begin__, None, 2) with frequency once-per-instance
2025-02-13 16:02:13,438 - handlers[DEBUG]: Calling handler ShellScriptByFreqPartHandler: [['text/x-shellscript-per-once']] (__begin__, None, 2) with frequency once-per-instance
2025-02-13 16:02:13,438 - handlers[DEBUG]: Calling handler BootHookPartHandler: [['text/cloud-boothook']] (__begin__, None, 2) with frequency once-per-instance
2025-02-13 16:02:13,438 - handlers[DEBUG]: Calling handler JinjaTemplatePartHandler: [['text/jinja2']] (__begin__, None, 3) with frequency once-per-instance
2025-02-13 16:02:13,438 - handlers[DEBUG]: {'MIME-Version': '1.0', 'Content-Type': 'text/x-not-multipart', 'Content-Disposition': 'attachment; filename="part-001"'}
2025-02-13 16:02:13,438 - handlers[DEBUG]: Empty payload of type text/x-not-multipart
2025-02-13 16:02:13,439 - handlers[DEBUG]: Calling handler CloudConfigPartHandler: [['text/cloud-config', 'text/cloud-config-jsonp']] (__end__, None, 3) with frequency once-per-instance
2025-02-13 16:02:13,439 - util.py[DEBUG]: Writing to /var/lib/cloud/instances/71855604/cloud-config.txt - wb: [600] 0 bytes
2025-02-13 16:02:13,442 - handlers[DEBUG]: Calling handler ShellScriptPartHandler: [['text/x-shellscript']] (__end__, None, 2) with frequency once-per-instance
2025-02-13 16:02:13,442 - handlers[DEBUG]: Calling handler ShellScriptByFreqPartHandler: [['text/x-shellscript-per-boot']] (__end__, None, 2) with frequency once-per-instance
2025-02-13 16:02:13,442 - handlers[DEBUG]: Calling handler ShellScriptByFreqPartHandler: [['text/x-shellscript-per-instance']] (__end__, None, 2) with frequency once-per-instance
2025-02-13 16:02:13,442 - handlers[DEBUG]: Calling handler ShellScriptByFreqPartHandler: [['text/x-shellscript-per-once']] (__end__, None, 2) with frequency once-per-instance
2025-02-13 16:02:13,442 - handlers[DEBUG]: Calling handler BootHookPartHandler: [['text/cloud-boothook']] (__end__, None, 2) with frequency once-per-instance
2025-02-13 16:02:13,442 - handlers[DEBUG]: Calling handler JinjaTemplatePartHandler: [['text/jinja2']] (__end__, None, 3) with frequency once-per-instance
2025-02-13 16:02:13,442 - handlers.py[DEBUG]: finish: init-network/consume-user-data: SUCCESS: reading and applying user-data
2025-02-13 16:02:13,442 - handlers.py[DEBUG]: start: init-network/consume-vendor-data: reading and applying vendor-data
2025-02-13 16:02:13,442 - stages.py[DEBUG]: no vendordata from datasource
2025-02-13 16:02:13,442 - handlers.py[DEBUG]: finish: init-network/consume-vendor-data: SUCCESS: reading and applying vendor-data
2025-02-13 16:02:13,442 - handlers.py[DEBUG]: start: init-network/consume-vendor-data2: reading and applying vendor-data2
2025-02-13 16:02:13,442 - stages.py[DEBUG]: no vendordata2 from datasource
2025-02-13 16:02:13,442 - handlers.py[DEBUG]: finish: init-network/consume-vendor-data2: SUCCESS: reading and applying vendor-data2
2025-02-13 16:02:13,443 - util.py[DEBUG]: Reading from /etc/cloud/cloud.cfg (quiet=False)
2025-02-13 16:02:13,443 - util.py[DEBUG]: Reading 3766 bytes from /etc/cloud/cloud.cfg
2025-02-13 16:02:13,443 - util.py[DEBUG]: Attempting to load yaml from string of length 3766 with allowed root types (<class 'dict'>,)
2025-02-13 16:02:13,459 - util.py[DEBUG]: Reading from /etc/cloud/cloud.cfg.d/99-linode.cfg (quiet=False)
2025-02-13 16:02:13,459 - util.py[DEBUG]: Reading 492 bytes from /etc/cloud/cloud.cfg.d/99-linode.cfg
2025-02-13 16:02:13,459 - util.py[DEBUG]: Attempting to load yaml from string of length 492 with allowed root types (<class 'dict'>,)
2025-02-13 16:02:13,461 - util.py[DEBUG]: Reading from /etc/cloud/cloud.cfg.d/90_dpkg.cfg (quiet=False)
2025-02-13 16:02:13,461 - util.py[DEBUG]: Reading 333 bytes from /etc/cloud/cloud.cfg.d/90_dpkg.cfg
2025-02-13 16:02:13,461 - util.py[DEBUG]: Attempting to load yaml from string of length 333 with allowed root types (<class 'dict'>,)
2025-02-13 16:02:13,463 - util.py[DEBUG]: Reading from /etc/cloud/cloud.cfg.d/05_logging.cfg (quiet=False)
2025-02-13 16:02:13,463 - util.py[DEBUG]: Reading 2071 bytes from /etc/cloud/cloud.cfg.d/05_logging.cfg
2025-02-13 16:02:13,463 - util.py[DEBUG]: Attempting to load yaml from string of length 2071 with allowed root types (<class 'dict'>,)
2025-02-13 16:02:13,466 - util.py[DEBUG]: Reading from /run/cloud-init/cloud.cfg (quiet=False)
2025-02-13 16:02:13,466 - util.py[DEBUG]: Reading 34 bytes from /run/cloud-init/cloud.cfg
2025-02-13 16:02:13,466 - util.py[DEBUG]: Attempting to load yaml from string of length 34 with allowed root types (<class 'dict'>,)
2025-02-13 16:02:13,467 - util.py[DEBUG]: Attempting to load yaml from string of length 0 with allowed root types (<class 'dict'>,)
2025-02-13 16:02:13,467 - util.py[DEBUG]: loaded blob returned None, returning default.
2025-02-13 16:02:13,467 - util.py[DEBUG]: Reading from /var/lib/cloud/instance/cloud-config.txt (quiet=False)
2025-02-13 16:02:13,467 - util.py[DEBUG]: Reading 0 bytes from /var/lib/cloud/instance/cloud-config.txt
2025-02-13 16:02:13,467 - util.py[DEBUG]: Attempting to load yaml from string of length 0 with allowed root types (<class 'dict'>,)
2025-02-13 16:02:13,468 - util.py[DEBUG]: loaded blob returned None, returning default.
2025-02-13 16:02:13,469 - atomic_helper.py[DEBUG]: Atomically writing to file /run/cloud-init/combined-cloud-config.json (via temporary file /run/cloud-init/tmpwp6xzcc4) - w: [600] 5471 bytes/chars
2025-02-13 16:02:13,469 - util.py[DEBUG]: Reading from /run/cloud-init/instance-data-sensitive.json (quiet=False)
2025-02-13 16:02:13,469 - util.py[DEBUG]: Reading 8726 bytes from /run/cloud-init/instance-data-sensitive.json
2025-02-13 16:02:13,470 - atomic_helper.py[DEBUG]: Atomically writing to file /run/cloud-init/instance-data-sensitive.json (via temporary file /run/cloud-init/tmp2ywxyzzc) - w: [600] 10709 bytes/chars
2025-02-13 16:02:13,470 - main.py[DEBUG]: Skipping user-data validation. No user-data found.
2025-02-13 16:02:13,470 - util.py[DEBUG]: Reading from /var/lib/cloud/instance/cloud-config.txt (quiet=False)
2025-02-13 16:02:13,470 - util.py[DEBUG]: Reading 0 bytes from /var/lib/cloud/instance/cloud-config.txt
2025-02-13 16:02:13,470 - util.py[DEBUG]: Attempting to load yaml from string of length 0 with allowed root types (<class 'dict'>,)
2025-02-13 16:02:13,470 - util.py[DEBUG]: loaded blob returned None, returning default.
2025-02-13 16:02:13,473 - handlers.py[DEBUG]: start: init-network/activate-datasource: activating datasource
2025-02-13 16:02:13,473 - util.py[DEBUG]: Writing to /var/lib/cloud/instance/obj.pkl - wb: [400] 9370 bytes
2025-02-13 16:02:13,474 - handlers.py[DEBUG]: finish: init-network/activate-datasource: SUCCESS: activating datasource
2025-02-13 16:02:13,474 - main.py[DEBUG]: no di_report found in config.
2025-02-13 16:02:13,486 - stages.py[DEBUG]: Using distro class <class 'cloudinit.distros.ubuntu.Distro'>
2025-02-13 16:02:13,487 - modules.py[INFO]: Skipping modules 'bootcmd,write_files,disk_setup,update_etc_hosts,ca_certs,rsyslog' because no applicable config is provided.
2025-02-13 16:02:13,487 - modules.py[DEBUG]: Running module seed_random (<module 'cloudinit.config.cc_seed_random' from '/usr/lib/python3/dist-packages/cloudinit/config/cc_seed_random.py'>) with frequency once-per-instance
2025-02-13 16:02:13,488 - handlers.py[DEBUG]: start: init-network/config-seed_random: running config-seed_random with frequency once-per-instance
2025-02-13 16:02:13,488 - util.py[DEBUG]: Writing to /var/lib/cloud/instances/71855604/sem/config_seed_random - wb: [644] 24 bytes
2025-02-13 16:02:13,488 - helpers.py[DEBUG]: Running config-seed_random using lock (<FileLock using file '/var/lib/cloud/instances/71855604/sem/config_seed_random'>)
2025-02-13 16:02:13,488 - cc_seed_random.py[DEBUG]: no command provided
2025-02-13 16:02:13,488 - handlers.py[DEBUG]: finish: init-network/config-seed_random: SUCCESS: config-seed_random ran successfully and took 0.001 seconds
2025-02-13 16:02:13,488 - modules.py[DEBUG]: Running module growpart (<module 'cloudinit.config.cc_growpart' from '/usr/lib/python3/dist-packages/cloudinit/config/cc_growpart.py'>) with frequency always
2025-02-13 16:02:13,489 - handlers.py[DEBUG]: start: init-network/config-growpart: running config-growpart with frequency always
2025-02-13 16:02:13,489 - helpers.py[DEBUG]: Running config-growpart using lock (<cloudinit.helpers.DummyLock object at 0x7feb426888b0>)
2025-02-13 16:02:13,489 - cc_growpart.py[DEBUG]: No 'growpart' entry in cfg.  Using default: {'mode': 'auto', 'devices': ['/'], 'ignore_growroot_disabled': False}
2025-02-13 16:02:13,489 - subp.py[DEBUG]: Running command ['growpart', '--help'] with allowed return codes [0] (shell=False, capture=True)
2025-02-13 16:02:13,492 - util.py[DEBUG]: Reading from /proc/567/mountinfo (quiet=False)
2025-02-13 16:02:13,492 - util.py[DEBUG]: Reading 2056 bytes from /proc/567/mountinfo
2025-02-13 16:02:13,492 - cc_growpart.py[DEBUG]: growpart found fs=ext4
2025-02-13 16:02:13,492 - cc_growpart.py[DEBUG]: '/' SKIPPED: device_part_info(/dev/sda) failed: /dev/sda not a partition
2025-02-13 16:02:13,493 - handlers.py[DEBUG]: finish: init-network/config-growpart: SUCCESS: config-growpart ran successfully and took 0.004 seconds
2025-02-13 16:02:13,493 - modules.py[DEBUG]: Running module resizefs (<module 'cloudinit.config.cc_resizefs' from '/usr/lib/python3/dist-packages/cloudinit/config/cc_resizefs.py'>) with frequency always
2025-02-13 16:02:13,493 - handlers.py[DEBUG]: start: init-network/config-resizefs: running config-resizefs with frequency always
2025-02-13 16:02:13,493 - helpers.py[DEBUG]: Running config-resizefs using lock (<cloudinit.helpers.DummyLock object at 0x7feb426880a0>)
2025-02-13 16:02:13,493 - util.py[DEBUG]: Reading from /proc/567/mountinfo (quiet=False)
2025-02-13 16:02:13,493 - util.py[DEBUG]: Reading 2056 bytes from /proc/567/mountinfo
2025-02-13 16:02:13,493 - cc_resizefs.py[DEBUG]: resize_info: dev=/dev/sda mnt_point=/ path=/
2025-02-13 16:02:13,493 - cc_resizefs.py[DEBUG]: Resizing / (ext4) using resize2fs /dev/sda
2025-02-13 16:02:13,493 - subp.py[DEBUG]: Running command ('resize2fs', '/dev/sda') with allowed return codes [0] (shell=False, capture=True)
2025-02-13 16:02:13,509 - performance.py[DEBUG]: Running ('resize2fs', '/dev/sda') took 0.015 seconds
2025-02-13 16:02:13,509 - cc_resizefs.py[DEBUG]: Resized root filesystem (type=ext4, val=True)
2025-02-13 16:02:13,509 - handlers.py[DEBUG]: finish: init-network/config-resizefs: SUCCESS: config-resizefs ran successfully and took 0.016 seconds
2025-02-13 16:02:13,509 - modules.py[DEBUG]: Running module mounts (<module 'cloudinit.config.cc_mounts' from '/usr/lib/python3/dist-packages/cloudinit/config/cc_mounts.py'>) with frequency once-per-instance
2025-02-13 16:02:13,509 - handlers.py[DEBUG]: start: init-network/config-mounts: running config-mounts with frequency once-per-instance
2025-02-13 16:02:13,509 - util.py[DEBUG]: Writing to /var/lib/cloud/instances/71855604/sem/config_mounts - wb: [644] 23 bytes
2025-02-13 16:02:13,510 - helpers.py[DEBUG]: Running config-mounts using lock (<FileLock using file '/var/lib/cloud/instances/71855604/sem/config_mounts'>)
2025-02-13 16:02:13,510 - cc_mounts.py[DEBUG]: mounts configuration is []
2025-02-13 16:02:13,510 - util.py[DEBUG]: Reading from /etc/fstab (quiet=False)
2025-02-13 16:02:13,511 - util.py[DEBUG]: Reading 481 bytes from /etc/fstab
2025-02-13 16:02:13,511 - cc_mounts.py[DEBUG]: Attempting to determine the real name of ephemeral0
2025-02-13 16:02:13,511 - cc_mounts.py[DEBUG]: changed ephemeral0 => None
2025-02-13 16:02:13,511 - cc_mounts.py[DEBUG]: Ignoring nonexistent default named mount ephemeral0
2025-02-13 16:02:13,511 - cc_mounts.py[DEBUG]: Attempting to determine the real name of swap
2025-02-13 16:02:13,511 - cc_mounts.py[DEBUG]: changed swap => None
2025-02-13 16:02:13,511 - cc_mounts.py[DEBUG]: Ignoring nonexistent default named mount swap
2025-02-13 16:02:13,511 - cc_mounts.py[DEBUG]: no need to setup swap
2025-02-13 16:02:13,511 - cc_mounts.py[DEBUG]: No modifications to fstab needed
2025-02-13 16:02:13,511 - handlers.py[DEBUG]: finish: init-network/config-mounts: SUCCESS: config-mounts ran successfully and took 0.002 seconds
2025-02-13 16:02:13,511 - modules.py[DEBUG]: Running module set_hostname (<module 'cloudinit.config.cc_set_hostname' from '/usr/lib/python3/dist-packages/cloudinit/config/cc_set_hostname.py'>) with frequency once-per-instance
2025-02-13 16:02:13,512 - handlers.py[DEBUG]: start: init-network/config-set_hostname: running config-set_hostname with frequency once-per-instance
2025-02-13 16:02:13,512 - util.py[DEBUG]: Writing to /var/lib/cloud/instances/71855604/sem/config_set_hostname - wb: [644] 24 bytes
2025-02-13 16:02:13,512 - helpers.py[DEBUG]: Running config-set_hostname using lock (<FileLock using file '/var/lib/cloud/instances/71855604/sem/config_set_hostname'>)
2025-02-13 16:02:13,512 - util.py[DEBUG]: Reading from /etc/hosts (quiet=False)
2025-02-13 16:02:13,512 - util.py[DEBUG]: Reading 181 bytes from /etc/hosts
2025-02-13 16:02:13,512 - util.py[DEBUG]: Reading from /etc/hosts (quiet=False)
2025-02-13 16:02:13,513 - util.py[DEBUG]: Reading 181 bytes from /etc/hosts
2025-02-13 16:02:13,513 - cc_set_hostname.py[DEBUG]: Hostname is localhost. Let other services handle this.
2025-02-13 16:02:13,513 - handlers.py[DEBUG]: finish: init-network/config-set_hostname: SUCCESS: config-set_hostname ran successfully and took 0.001 seconds
2025-02-13 16:02:13,513 - modules.py[DEBUG]: Running module update_hostname (<module 'cloudinit.config.cc_update_hostname' from '/usr/lib/python3/dist-packages/cloudinit/config/cc_update_hostname.py'>) with frequency always
2025-02-13 16:02:13,513 - handlers.py[DEBUG]: start: init-network/config-update_hostname: running config-update_hostname with frequency always
2025-02-13 16:02:13,513 - helpers.py[DEBUG]: Running config-update_hostname using lock (<cloudinit.helpers.DummyLock object at 0x7feb42688220>)
2025-02-13 16:02:13,513 - util.py[DEBUG]: Reading from /etc/hosts (quiet=False)
2025-02-13 16:02:13,513 - util.py[DEBUG]: Reading 181 bytes from /etc/hosts
2025-02-13 16:02:13,513 - util.py[DEBUG]: Reading from /etc/hosts (quiet=False)
2025-02-13 16:02:13,513 - util.py[DEBUG]: Reading 181 bytes from /etc/hosts
2025-02-13 16:02:13,513 - cc_update_hostname.py[DEBUG]: Hostname is localhost. Let other services handle this.
2025-02-13 16:02:13,513 - handlers.py[DEBUG]: finish: init-network/config-update_hostname: SUCCESS: config-update_hostname ran successfully and took 0.000 seconds
2025-02-13 16:02:13,513 - modules.py[DEBUG]: Running module users_groups (<module 'cloudinit.config.cc_users_groups' from '/usr/lib/python3/dist-packages/cloudinit/config/cc_users_groups.py'>) with frequency once-per-instance
2025-02-13 16:02:13,514 - handlers.py[DEBUG]: start: init-network/config-users_groups: running config-users_groups with frequency once-per-instance
2025-02-13 16:02:13,514 - util.py[DEBUG]: Writing to /var/lib/cloud/instances/71855604/sem/config_users_groups - wb: [644] 24 bytes
2025-02-13 16:02:13,514 - helpers.py[DEBUG]: Running config-users_groups using lock (<FileLock using file '/var/lib/cloud/instances/71855604/sem/config_users_groups'>)
2025-02-13 16:02:13,514 - handlers.py[DEBUG]: finish: init-network/config-users_groups: SUCCESS: config-users_groups ran successfully and took 0.000 seconds
2025-02-13 16:02:13,514 - modules.py[DEBUG]: Running module ssh (<module 'cloudinit.config.cc_ssh' from '/usr/lib/python3/dist-packages/cloudinit/config/cc_ssh.py'>) with frequency once-per-instance
2025-02-13 16:02:13,514 - handlers.py[DEBUG]: start: init-network/config-ssh: running config-ssh with frequency once-per-instance
2025-02-13 16:02:13,514 - util.py[DEBUG]: Writing to /var/lib/cloud/instances/71855604/sem/config_ssh - wb: [644] 24 bytes
2025-02-13 16:02:13,515 - helpers.py[DEBUG]: Running config-ssh using lock (<FileLock using file '/var/lib/cloud/instances/71855604/sem/config_ssh'>)
2025-02-13 16:02:13,519 - util.py[DEBUG]: Reading from /proc/sys/crypto/fips_enabled (quiet=False)
2025-02-13 16:02:13,519 - subp.py[DEBUG]: Running command ['ssh-keygen', '-t', 'rsa', '-N', '', '-f', '/etc/ssh/ssh_host_rsa_key'] with allowed return codes [0] (shell=False, capture=True)
2025-02-13 16:02:14,209 - performance.py[DEBUG]: Running ['ssh-keygen', '-t', 'rsa', '-N', '', '-f', '/etc/ssh/ssh_host_rsa_key'] took 0.689 seconds
2025-02-13 16:02:14,209 - subp.py[DEBUG]: Running command ['ssh-keygen', '-t', 'ecdsa', '-N', '', '-f', '/etc/ssh/ssh_host_ecdsa_key'] with allowed return codes [0] (shell=False, capture=True)
2025-02-13 16:02:14,214 - subp.py[DEBUG]: Running command ['ssh-keygen', '-t', 'ed25519', '-N', '', '-f', '/etc/ssh/ssh_host_ed25519_key'] with allowed return codes [0] (shell=False, capture=True)
2025-02-13 16:02:14,220 - util.py[DEBUG]: Reading from /etc/ssh/ssh_host_rsa_key.pub (quiet=False)
2025-02-13 16:02:14,220 - util.py[DEBUG]: Reading 568 bytes from /etc/ssh/ssh_host_rsa_key.pub
2025-02-13 16:02:14,220 - util.py[DEBUG]: Reading from /etc/ssh/ssh_host_ed25519_key.pub (quiet=False)
2025-02-13 16:02:14,220 - util.py[DEBUG]: Reading 96 bytes from /etc/ssh/ssh_host_ed25519_key.pub
2025-02-13 16:02:14,220 - util.py[DEBUG]: Reading from /etc/ssh/ssh_host_ecdsa_key.pub (quiet=False)
2025-02-13 16:02:14,220 - util.py[DEBUG]: Reading 176 bytes from /etc/ssh/ssh_host_ecdsa_key.pub
2025-02-13 16:02:14,221 - util.py[DEBUG]: Reading from /etc/ssh/sshd_config (quiet=False)
2025-02-13 16:02:14,221 - util.py[DEBUG]: Reading 3237 bytes from /etc/ssh/sshd_config
2025-02-13 16:02:14,222 - util.py[DEBUG]: Reading from /root/.ssh/authorized_keys (quiet=False)
2025-02-13 16:02:14,222 - util.py[DEBUG]: Reading 1486 bytes from /root/.ssh/authorized_keys
2025-02-13 16:02:14,222 - util.py[DEBUG]: Writing to /root/.ssh/authorized_keys - wb: [600] 1487 bytes
2025-02-13 16:02:14,223 - handlers.py[DEBUG]: finish: init-network/config-ssh: SUCCESS: config-ssh ran successfully and took 0.709 seconds
2025-02-13 16:02:14,223 - modules.py[DEBUG]: Running module set_passwords (<module 'cloudinit.config.cc_set_passwords' from '/usr/lib/python3/dist-packages/cloudinit/config/cc_set_passwords.py'>) with frequency once-per-instance
2025-02-13 16:02:14,223 - handlers.py[DEBUG]: start: init-network/config-set_passwords: running config-set_passwords with frequency once-per-instance
2025-02-13 16:02:14,223 - util.py[DEBUG]: Writing to /var/lib/cloud/instances/71855604/sem/config_set_passwords - wb: [644] 24 bytes
2025-02-13 16:02:14,224 - helpers.py[DEBUG]: Running config-set_passwords using lock (<FileLock using file '/var/lib/cloud/instances/71855604/sem/config_set_passwords'>)
2025-02-13 16:02:14,224 - cc_set_passwords.py[DEBUG]: Leaving SSH config 'PasswordAuthentication' unchanged. ssh_pwauth=None
2025-02-13 16:02:14,224 - handlers.py[DEBUG]: finish: init-network/config-set_passwords: SUCCESS: config-set_passwords ran successfully and took 0.000 seconds
2025-02-13 16:02:14,224 - main.py[DEBUG]: Ran 9 modules with 0 failures
2025-02-13 16:02:14,224 - util.py[DEBUG]: Reading from /proc/uptime (quiet=False)
2025-02-13 16:02:14,224 - util.py[DEBUG]: Reading 11 bytes from /proc/uptime
2025-02-13 16:02:14,224 - atomic_helper.py[DEBUG]: Atomically writing to file /var/lib/cloud/data/status.json (via temporary file /var/lib/cloud/data/tmpnrgc7613) - w: [644] 504 bytes/chars
2025-02-13 16:02:14,224 - performance.py[DEBUG]: cloud-init stage: 'init-network' took 0.936 seconds
2025-02-13 16:02:14,224 - handlers.py[DEBUG]: finish: init-network: SUCCESS: searching for network datasources
2025-02-13 16:02:15,421 - log_util.py[DEBUG]: Cloud-init v. 24.4-0ubuntu1~22.04.1 running 'modules:config' at Thu, 13 Feb 2025 16:02:15 +0000. Up 15.49 seconds.
2025-02-13 16:02:15,421 - main.py[INFO]: PID [1] started cloud-init 'modules:config'.
2025-02-13 16:02:15,446 - stages.py[DEBUG]: Using distro class <class 'cloudinit.distros.ubuntu.Distro'>
2025-02-13 16:02:15,448 - modules.py[INFO]: Skipping modules 'wireguard,snap,ubuntu_autoinstall,keyboard,apt_pipelining,ubuntu_pro,ntp,timezone,disable_ec2_metadata,runcmd' because no applicable config is provided.
2025-02-13 16:02:15,449 - modules.py[DEBUG]: Running module ssh_import_id (<module 'cloudinit.config.cc_ssh_import_id' from '/usr/lib/python3/dist-packages/cloudinit/config/cc_ssh_import_id.py'>) with frequency once-per-instance
2025-02-13 16:02:15,449 - handlers.py[DEBUG]: start: modules-config/config-ssh_import_id: running config-ssh_import_id with frequency once-per-instance
2025-02-13 16:02:15,449 - util.py[DEBUG]: Writing to /var/lib/cloud/instances/71855604/sem/config_ssh_import_id - wb: [644] 24 bytes
2025-02-13 16:02:15,449 - helpers.py[DEBUG]: Running config-ssh_import_id using lock (<FileLock using file '/var/lib/cloud/instances/71855604/sem/config_ssh_import_id'>)
2025-02-13 16:02:15,449 - cc_ssh_import_id.py[DEBUG]: Skipping module named ssh_import_id, no 'ssh_import_id' directives found.
2025-02-13 16:02:15,450 - handlers.py[DEBUG]: finish: modules-config/config-ssh_import_id: SUCCESS: config-ssh_import_id ran successfully and took 0.001 seconds
2025-02-13 16:02:15,450 - modules.py[DEBUG]: Running module locale (<module 'cloudinit.config.cc_locale' from '/usr/lib/python3/dist-packages/cloudinit/config/cc_locale.py'>) with frequency once-per-instance
2025-02-13 16:02:15,450 - handlers.py[DEBUG]: start: modules-config/config-locale: running config-locale with frequency once-per-instance
2025-02-13 16:02:15,450 - util.py[DEBUG]: Writing to /var/lib/cloud/instances/71855604/sem/config_locale - wb: [644] 24 bytes
2025-02-13 16:02:15,450 - helpers.py[DEBUG]: Running config-locale using lock (<FileLock using file '/var/lib/cloud/instances/71855604/sem/config_locale'>)
2025-02-13 16:02:15,450 - util.py[DEBUG]: Reading from /etc/default/locale (quiet=False)
2025-02-13 16:02:15,450 - util.py[DEBUG]: Reading 52 bytes from /etc/default/locale
2025-02-13 16:02:15,451 - cc_locale.py[DEBUG]: Setting locale to en_US.UTF-8
2025-02-13 16:02:15,451 - debian.py[DEBUG]: System locale set to en_US.UTF-8 via /etc/default/locale
2025-02-13 16:02:15,451 - debian.py[DEBUG]: System has 'LANG=en_US.UTF-8' requested 'en_US.UTF-8', skipping regeneration.
2025-02-13 16:02:15,451 - handlers.py[DEBUG]: finish: modules-config/config-locale: SUCCESS: config-locale ran successfully and took 0.001 seconds
2025-02-13 16:02:15,451 - modules.py[DEBUG]: Running module grub_dpkg (<module 'cloudinit.config.cc_grub_dpkg' from '/usr/lib/python3/dist-packages/cloudinit/config/cc_grub_dpkg.py'>) with frequency once-per-instance
2025-02-13 16:02:15,451 - handlers.py[DEBUG]: start: modules-config/config-grub_dpkg: running config-grub_dpkg with frequency once-per-instance
2025-02-13 16:02:15,452 - util.py[DEBUG]: Writing to /var/lib/cloud/instances/71855604/sem/config_grub_dpkg - wb: [644] 24 bytes
2025-02-13 16:02:15,453 - helpers.py[DEBUG]: Running config-grub_dpkg using lock (<FileLock using file '/var/lib/cloud/instances/71855604/sem/config_grub_dpkg'>)
2025-02-13 16:02:15,454 - subp.py[DEBUG]: Running command ['grub-probe', '-t', 'disk', '/boot'] with allowed return codes [0] (shell=False, capture=True)
2025-02-13 16:02:15,464 - subp.py[DEBUG]: Running command ['udevadm', 'info', '--root', '--query=symlink', '/dev/sda'] with allowed return codes [0] (shell=False, capture=True)
2025-02-13 16:02:15,470 - cc_grub_dpkg.py[DEBUG]: considering these device symlinks: /dev/disk/by-uuid/c4b52a3f-818a-c891-ac4a-b949bf511e72,/dev/disk/by-id/scsi-0QEMU_QEMU_HARDDISK_drive-scsi-disk-0,/dev/disk/by-path/pci-0000:00:02.0-scsi-0:0:0:0,/dev/disk/by-label/linode-root
2025-02-13 16:02:15,470 - cc_grub_dpkg.py[DEBUG]: filtered to these disk/by-id symlinks: /dev/disk/by-id/scsi-0QEMU_QEMU_HARDDISK_drive-scsi-disk-0
2025-02-13 16:02:15,470 - cc_grub_dpkg.py[DEBUG]: selected /dev/disk/by-id/scsi-0QEMU_QEMU_HARDDISK_drive-scsi-disk-0
2025-02-13 16:02:15,470 - cc_grub_dpkg.py[DEBUG]: Setting grub debconf-set-selections with 'grub-pc grub-pc/install_devices string /dev/disk/by-id/scsi-0QEMU_QEMU_HARDDISK_drive-scsi-disk-0
grub-pc grub-pc/install_devices_empty boolean false
'
2025-02-13 16:02:15,470 - subp.py[DEBUG]: Running command ['debconf-set-selections'] with allowed return codes [0] (shell=False, capture=True)
2025-02-13 16:02:15,630 - performance.py[DEBUG]: Running ['debconf-set-selections'] took 0.159 seconds
2025-02-13 16:02:15,630 - handlers.py[DEBUG]: finish: modules-config/config-grub_dpkg: SUCCESS: config-grub_dpkg ran successfully and took 0.179 seconds
2025-02-13 16:02:15,630 - modules.py[DEBUG]: Running module apt_configure (<module 'cloudinit.config.cc_apt_configure' from '/usr/lib/python3/dist-packages/cloudinit/config/cc_apt_configure.py'>) with frequency once-per-instance
2025-02-13 16:02:15,630 - handlers.py[DEBUG]: start: modules-config/config-apt_configure: running config-apt_configure with frequency once-per-instance
2025-02-13 16:02:15,631 - util.py[DEBUG]: Writing to /var/lib/cloud/instances/71855604/sem/config_apt_configure - wb: [644] 22 bytes
2025-02-13 16:02:15,631 - helpers.py[DEBUG]: Running config-apt_configure using lock (<FileLock using file '/var/lib/cloud/instances/71855604/sem/config_apt_configure'>)
2025-02-13 16:02:15,631 - cc_apt_configure.py[DEBUG]: debconf_selections was not set in config
2025-02-13 16:02:15,632 - cc_apt_configure.py[DEBUG]: handling apt config: {'preserve_sources_list': True}
2025-02-13 16:02:15,632 - subp.py[DEBUG]: Running command ['lsb_release', '--all'] with allowed return codes [0] (shell=False, capture=True)
2025-02-13 16:02:15,677 - performance.py[DEBUG]: Running ['lsb_release', '--all'] took 0.045 seconds
2025-02-13 16:02:15,677 - subp.py[DEBUG]: Running command ['dpkg', '--print-architecture'] with allowed return codes [0] (shell=False, capture=True)
2025-02-13 16:02:15,680 - cc_apt_configure.py[DEBUG]: got primary mirror: None
2025-02-13 16:02:15,680 - cc_apt_configure.py[DEBUG]: got security mirror: None
2025-02-13 16:02:15,681 - util.py[DEBUG]: search for mirror in candidates: '['http://es-mad.clouds.archive.ubuntu.com/ubuntu/']'
2025-02-13 16:02:16,186 - performance.py[DEBUG]: Resolving URL took 0.505 seconds
2025-02-13 16:02:16,186 - util.py[DEBUG]: found working mirror: 'http://es-mad.clouds.archive.ubuntu.com/ubuntu/'
2025-02-13 16:02:16,186 - util.py[DEBUG]: search for mirror in candidates: '[]'
2025-02-13 16:02:16,186 - distros[DEBUG]: filtered distro mirror info: {'primary': 'http://es-mad.clouds.archive.ubuntu.com/ubuntu/', 'security': 'http://security.ubuntu.com/ubuntu'}
2025-02-13 16:02:16,186 - cc_apt_configure.py[DEBUG]: Apt Mirror info: {'primary': 'http://es-mad.clouds.archive.ubuntu.com/ubuntu/', 'security': 'http://security.ubuntu.com/ubuntu', 'PRIMARY': 'http://es-mad.clouds.archive.ubuntu.com/ubuntu/', 'SECURITY': 'http://security.ubuntu.com/ubuntu', 'MIRROR': 'http://es-mad.clouds.archive.ubuntu.com/ubuntu/'}
2025-02-13 16:02:16,187 - handlers.py[DEBUG]: finish: modules-config/config-apt_configure: SUCCESS: config-apt_configure ran successfully and took 0.556 seconds
2025-02-13 16:02:16,187 - modules.py[DEBUG]: Running module byobu (<module 'cloudinit.config.cc_byobu' from '/usr/lib/python3/dist-packages/cloudinit/config/cc_byobu.py'>) with frequency once-per-instance
2025-02-13 16:02:16,187 - handlers.py[DEBUG]: start: modules-config/config-byobu: running config-byobu with frequency once-per-instance
2025-02-13 16:02:16,188 - util.py[DEBUG]: Writing to /var/lib/cloud/instances/71855604/sem/config_byobu - wb: [644] 24 bytes
2025-02-13 16:02:16,188 - helpers.py[DEBUG]: Running config-byobu using lock (<FileLock using file '/var/lib/cloud/instances/71855604/sem/config_byobu'>)
2025-02-13 16:02:16,188 - cc_byobu.py[DEBUG]: Skipping module named byobu, no 'byobu' values found
2025-02-13 16:02:16,188 - handlers.py[DEBUG]: finish: modules-config/config-byobu: SUCCESS: config-byobu ran successfully and took 0.001 seconds
2025-02-13 16:02:16,188 - main.py[DEBUG]: Ran 5 modules with 0 failures
2025-02-13 16:02:16,188 - util.py[DEBUG]: Reading from /proc/uptime (quiet=False)
2025-02-13 16:02:16,188 - util.py[DEBUG]: Reading 11 bytes from /proc/uptime
2025-02-13 16:02:16,189 - atomic_helper.py[DEBUG]: Atomically writing to file /var/lib/cloud/data/status.json (via temporary file /var/lib/cloud/data/tmppy3c87q2) - w: [644] 505 bytes/chars
2025-02-13 16:02:16,189 - performance.py[DEBUG]: cloud-init stage: 'modules-config' took 0.969 seconds
2025-02-13 16:02:16,189 - handlers.py[DEBUG]: finish: modules-config: SUCCESS: running modules for config
2025-02-13 16:02:16,564 - log_util.py[DEBUG]: Cloud-init v. 24.4-0ubuntu1~22.04.1 running 'modules:final' at Thu, 13 Feb 2025 16:02:16 +0000. Up 16.72 seconds.
2025-02-13 16:02:16,564 - main.py[INFO]: PID [1] started cloud-init 'modules:final'.
2025-02-13 16:02:16,584 - stages.py[DEBUG]: Using distro class <class 'cloudinit.distros.ubuntu.Distro'>
2025-02-13 16:02:16,586 - modules.py[INFO]: Skipping modules 'package_update_upgrade_install,fan,landscape,lxd,ubuntu_drivers,write_files_deferred,puppet,chef,ansible,mcollective,salt_minion,phone_home,power_state_change' because no applicable config is provided.
2025-02-13 16:02:16,587 - modules.py[DEBUG]: Running module reset_rmc (<module 'cloudinit.config.cc_reset_rmc' from '/usr/lib/python3/dist-packages/cloudinit/config/cc_reset_rmc.py'>) with frequency once-per-instance
2025-02-13 16:02:16,587 - handlers.py[DEBUG]: start: modules-final/config-reset_rmc: running config-reset_rmc with frequency once-per-instance
2025-02-13 16:02:16,587 - util.py[DEBUG]: Writing to /var/lib/cloud/instances/71855604/sem/config_reset_rmc - wb: [644] 24 bytes
2025-02-13 16:02:16,588 - helpers.py[DEBUG]: Running config-reset_rmc using lock (<FileLock using file '/var/lib/cloud/instances/71855604/sem/config_reset_rmc'>)
2025-02-13 16:02:16,588 - cc_reset_rmc.py[DEBUG]: module disabled, RSCT_PATH not present
2025-02-13 16:02:16,588 - handlers.py[DEBUG]: finish: modules-final/config-reset_rmc: SUCCESS: config-reset_rmc ran successfully and took 0.001 seconds
2025-02-13 16:02:16,588 - modules.py[DEBUG]: Running module scripts_vendor (<module 'cloudinit.config.cc_scripts_vendor' from '/usr/lib/python3/dist-packages/cloudinit/config/cc_scripts_vendor.py'>) with frequency once-per-instance
2025-02-13 16:02:16,588 - handlers.py[DEBUG]: start: modules-final/config-scripts_vendor: running config-scripts_vendor with frequency once-per-instance
2025-02-13 16:02:16,588 - util.py[DEBUG]: Writing to /var/lib/cloud/instances/71855604/sem/config_scripts_vendor - wb: [644] 23 bytes
2025-02-13 16:02:16,589 - helpers.py[DEBUG]: Running config-scripts_vendor using lock (<FileLock using file '/var/lib/cloud/instances/71855604/sem/config_scripts_vendor'>)
2025-02-13 16:02:16,589 - handlers.py[DEBUG]: finish: modules-final/config-scripts_vendor: SUCCESS: config-scripts_vendor ran successfully and took 0.000 seconds
2025-02-13 16:02:16,589 - modules.py[DEBUG]: Running module scripts_per_once (<module 'cloudinit.config.cc_scripts_per_once' from '/usr/lib/python3/dist-packages/cloudinit/config/cc_scripts_per_once.py'>) with frequency once
2025-02-13 16:02:16,589 - handlers.py[DEBUG]: start: modules-final/config-scripts_per_once: running config-scripts_per_once with frequency once
2025-02-13 16:02:16,589 - util.py[DEBUG]: Writing to /var/lib/cloud/sem/config_scripts_per_once.once - wb: [644] 24 bytes
2025-02-13 16:02:16,589 - helpers.py[DEBUG]: Running config-scripts_per_once using lock (<FileLock using file '/var/lib/cloud/sem/config_scripts_per_once.once'>)
2025-02-13 16:02:16,590 - handlers.py[DEBUG]: finish: modules-final/config-scripts_per_once: SUCCESS: config-scripts_per_once ran successfully and took 0.000 seconds
2025-02-13 16:02:16,590 - modules.py[DEBUG]: Running module scripts_per_boot (<module 'cloudinit.config.cc_scripts_per_boot' from '/usr/lib/python3/dist-packages/cloudinit/config/cc_scripts_per_boot.py'>) with frequency always
2025-02-13 16:02:16,590 - handlers.py[DEBUG]: start: modules-final/config-scripts_per_boot: running config-scripts_per_boot with frequency always
2025-02-13 16:02:16,590 - helpers.py[DEBUG]: Running config-scripts_per_boot using lock (<cloudinit.helpers.DummyLock object at 0x7f8f0b053910>)
2025-02-13 16:02:16,590 - handlers.py[DEBUG]: finish: modules-final/config-scripts_per_boot: SUCCESS: config-scripts_per_boot ran successfully and took 0.000 seconds
2025-02-13 16:02:16,590 - modules.py[DEBUG]: Running module scripts_per_instance (<module 'cloudinit.config.cc_scripts_per_instance' from '/usr/lib/python3/dist-packages/cloudinit/config/cc_scripts_per_instance.py'>) with frequency once-per-instance
2025-02-13 16:02:16,590 - handlers.py[DEBUG]: start: modules-final/config-scripts_per_instance: running config-scripts_per_instance with frequency once-per-instance
2025-02-13 16:02:16,590 - util.py[DEBUG]: Writing to /var/lib/cloud/instances/71855604/sem/config_scripts_per_instance - wb: [644] 24 bytes
2025-02-13 16:02:16,591 - helpers.py[DEBUG]: Running config-scripts_per_instance using lock (<FileLock using file '/var/lib/cloud/instances/71855604/sem/config_scripts_per_instance'>)
2025-02-13 16:02:16,591 - handlers.py[DEBUG]: finish: modules-final/config-scripts_per_instance: SUCCESS: config-scripts_per_instance ran successfully and took 0.000 seconds
2025-02-13 16:02:16,591 - modules.py[DEBUG]: Running module scripts_user (<module 'cloudinit.config.cc_scripts_user' from '/usr/lib/python3/dist-packages/cloudinit/config/cc_scripts_user.py'>) with frequency once-per-instance
2025-02-13 16:02:16,591 - handlers.py[DEBUG]: start: modules-final/config-scripts_user: running config-scripts_user with frequency once-per-instance
2025-02-13 16:02:16,591 - util.py[DEBUG]: Writing to /var/lib/cloud/instances/71855604/sem/config_scripts_user - wb: [644] 24 bytes
2025-02-13 16:02:16,591 - helpers.py[DEBUG]: Running config-scripts_user using lock (<FileLock using file '/var/lib/cloud/instances/71855604/sem/config_scripts_user'>)
2025-02-13 16:02:16,592 - handlers.py[DEBUG]: finish: modules-final/config-scripts_user: SUCCESS: config-scripts_user ran successfully and took 0.000 seconds
2025-02-13 16:02:16,592 - modules.py[DEBUG]: Running module ssh_authkey_fingerprints (<module 'cloudinit.config.cc_ssh_authkey_fingerprints' from '/usr/lib/python3/dist-packages/cloudinit/config/cc_ssh_authkey_fingerprints.py'>) with frequency once-per-instance
2025-02-13 16:02:16,592 - handlers.py[DEBUG]: start: modules-final/config-ssh_authkey_fingerprints: running config-ssh_authkey_fingerprints with frequency once-per-instance
2025-02-13 16:02:16,592 - util.py[DEBUG]: Writing to /var/lib/cloud/instances/71855604/sem/config_ssh_authkey_fingerprints - wb: [644] 24 bytes
2025-02-13 16:02:16,592 - helpers.py[DEBUG]: Running config-ssh_authkey_fingerprints using lock (<FileLock using file '/var/lib/cloud/instances/71855604/sem/config_ssh_authkey_fingerprints'>)
2025-02-13 16:02:16,592 - handlers.py[DEBUG]: finish: modules-final/config-ssh_authkey_fingerprints: SUCCESS: config-ssh_authkey_fingerprints ran successfully and took 0.000 seconds
2025-02-13 16:02:16,592 - modules.py[DEBUG]: Running module keys_to_console (<module 'cloudinit.config.cc_keys_to_console' from '/usr/lib/python3/dist-packages/cloudinit/config/cc_keys_to_console.py'>) with frequency once-per-instance
2025-02-13 16:02:16,592 - handlers.py[DEBUG]: start: modules-final/config-keys_to_console: running config-keys_to_console with frequency once-per-instance
2025-02-13 16:02:16,593 - util.py[DEBUG]: Writing to /var/lib/cloud/instances/71855604/sem/config_keys_to_console - wb: [644] 23 bytes
2025-02-13 16:02:16,593 - helpers.py[DEBUG]: Running config-keys_to_console using lock (<FileLock using file '/var/lib/cloud/instances/71855604/sem/config_keys_to_console'>)
2025-02-13 16:02:16,593 - subp.py[DEBUG]: Running command ['/usr/lib/cloud-init/write-ssh-key-fingerprints', '', ''] with allowed return codes [0] (shell=False, capture=True)
2025-02-13 16:02:16,623 - performance.py[DEBUG]: Running ['/usr/lib/cloud-init/write-ssh-key-fingerprints', '', ''] took 0.030 seconds
2025-02-13 16:02:16,644 - performance.py[DEBUG]: Writing to console took 0.020 seconds
2025-02-13 16:02:16,644 - handlers.py[DEBUG]: finish: modules-final/config-keys_to_console: SUCCESS: config-keys_to_console ran successfully and took 0.051 seconds
2025-02-13 16:02:16,644 - modules.py[DEBUG]: Running module install_hotplug (<module 'cloudinit.config.cc_install_hotplug' from '/usr/lib/python3/dist-packages/cloudinit/config/cc_install_hotplug.py'>) with frequency once-per-instance
2025-02-13 16:02:16,644 - handlers.py[DEBUG]: start: modules-final/config-install_hotplug: running config-install_hotplug with frequency once-per-instance
2025-02-13 16:02:16,644 - util.py[DEBUG]: Writing to /var/lib/cloud/instances/71855604/sem/config_install_hotplug - wb: [644] 24 bytes
2025-02-13 16:02:16,645 - helpers.py[DEBUG]: Running config-install_hotplug using lock (<FileLock using file '/var/lib/cloud/instances/71855604/sem/config_install_hotplug'>)
2025-02-13 16:02:16,645 - util.py[DEBUG]: Reading from /var/lib/cloud/hotplug.enabled (quiet=False)
2025-02-13 16:02:16,645 - util.py[DEBUG]: File not found: /var/lib/cloud/hotplug.enabled
2025-02-13 16:02:16,645 - stages.py[DEBUG]: Allowed events: {<EventScope.NETWORK: 'network'>: {<EventType.BOOT_NEW_INSTANCE: 'boot-new-instance'>}}
2025-02-13 16:02:16,645 - stages.py[DEBUG]: Event Denied: scopes=['network'] EventType=hotplug
2025-02-13 16:02:16,645 - cc_install_hotplug.py[DEBUG]: Skipping hotplug install, not enabled
2025-02-13 16:02:16,646 - handlers.py[DEBUG]: finish: modules-final/config-install_hotplug: SUCCESS: config-install_hotplug ran successfully and took 0.001 seconds
2025-02-13 16:02:16,646 - modules.py[DEBUG]: Running module final_message (<module 'cloudinit.config.cc_final_message' from '/usr/lib/python3/dist-packages/cloudinit/config/cc_final_message.py'>) with frequency always
2025-02-13 16:02:16,646 - handlers.py[DEBUG]: start: modules-final/config-final_message: running config-final_message with frequency always
2025-02-13 16:02:16,646 - helpers.py[DEBUG]: Running config-final_message using lock (<cloudinit.helpers.DummyLock object at 0x7f8f0b053e20>)
2025-02-13 16:02:16,646 - util.py[DEBUG]: Reading from /proc/uptime (quiet=False)
2025-02-13 16:02:16,646 - util.py[DEBUG]: Reading 11 bytes from /proc/uptime
2025-02-13 16:02:16,653 - log_util.py[DEBUG]: Cloud-init v. 24.4-0ubuntu1~22.04.1 finished at Thu, 13 Feb 2025 16:02:16 +0000. Datasource DataSourceAkamaiLocal.  Up 16.85 seconds
2025-02-13 16:02:16,653 - util.py[DEBUG]: Writing to /var/lib/cloud/instance/boot-finished - wb: [644] 67 bytes
2025-02-13 16:02:16,654 - handlers.py[DEBUG]: finish: modules-final/config-final_message: SUCCESS: config-final_message ran successfully and took 0.008 seconds
2025-02-13 16:02:16,654 - main.py[DEBUG]: Ran 10 modules with 0 failures
2025-02-13 16:02:16,654 - util.py[DEBUG]: Reading from /proc/uptime (quiet=False)
2025-02-13 16:02:16,654 - util.py[DEBUG]: Reading 11 bytes from /proc/uptime
2025-02-13 16:02:16,654 - atomic_helper.py[DEBUG]: Atomically writing to file /var/lib/cloud/data/status.json (via temporary file /var/lib/cloud/data/tmp353s86v_) - w: [644] 507 bytes/chars
2025-02-13 16:02:16,655 - atomic_helper.py[DEBUG]: Atomically writing to file /var/lib/cloud/data/result.json (via temporary file /var/lib/cloud/data/tmpd6g2wlrb) - w: [644] 72 bytes/chars
2025-02-13 16:02:16,655 - util.py[DEBUG]: Creating symbolic link from '/run/cloud-init/result.json' => '../../var/lib/cloud/data/result.json'
2025-02-13 16:02:16,655 - performance.py[DEBUG]: cloud-init stage: 'modules-final' took 0.176 seconds
2025-02-13 16:02:16,655 - handlers.py[DEBUG]: finish: modules-final: SUCCESS: running modules for final
2025-02-13 16:44:14,802 - log_util.py[DEBUG]: Cloud-init v. 24.4-0ubuntu1~22.04.1 running 'init-local' at Thu, 13 Feb 2025 16:44:14 +0000. Up 5.95 seconds.
2025-02-13 16:44:14,806 - main.py[INFO]: PID [1] started cloud-init 'init-local'.
2025-02-13 16:44:14,806 - main.py[DEBUG]: No kernel command line url found.
2025-02-13 16:44:14,806 - main.py[DEBUG]: Closing stdin
2025-02-13 16:44:14,809 - util.py[DEBUG]: Writing to /var/log/cloud-init.log - ab: [640] 0 bytes
2025-02-13 16:44:14,809 - util.py[DEBUG]: Changing the ownership of /var/log/cloud-init.log to 104:4
2025-02-13 16:44:14,809 - util.py[DEBUG]: Reading from /var/lib/cloud/data/python-version (quiet=False)
2025-02-13 16:44:14,813 - util.py[DEBUG]: Reading 4 bytes from /var/lib/cloud/data/python-version
2025-02-13 16:44:14,813 - util.py[DEBUG]: Attempting to remove /var/lib/cloud/instance/boot-finished
2025-02-13 16:44:14,813 - handlers.py[DEBUG]: start: init-local/check-cache: attempting to read from cache [check]
2025-02-13 16:44:14,813 - util.py[DEBUG]: Reading from /var/lib/cloud/instance/obj.pkl (quiet=False)
2025-02-13 16:44:14,817 - util.py[DEBUG]: Reading 9370 bytes from /var/lib/cloud/instance/obj.pkl
2025-02-13 16:44:14,826 - dmi.py[DEBUG]: querying dmi data /sys/class/dmi/id/product_serial
2025-02-13 16:44:14,828 - stages.py[DEBUG]: restored from checked cache: DataSourceAkamaiLocal
2025-02-13 16:44:14,828 - handlers.py[DEBUG]: finish: init-local/check-cache: SUCCESS: restored from checked cache: DataSourceAkamaiLocal
2025-02-13 16:44:14,828 - util.py[DEBUG]: Reading from /etc/cloud/cloud.cfg (quiet=False)
2025-02-13 16:44:14,828 - util.py[DEBUG]: Reading 3766 bytes from /etc/cloud/cloud.cfg
2025-02-13 16:44:14,828 - util.py[DEBUG]: Attempting to load yaml from string of length 3766 with allowed root types (<class 'dict'>,)
2025-02-13 16:44:14,853 - util.py[DEBUG]: Reading from /etc/cloud/cloud.cfg.d/99-linode.cfg (quiet=False)
2025-02-13 16:44:14,853 - util.py[DEBUG]: Reading 492 bytes from /etc/cloud/cloud.cfg.d/99-linode.cfg
2025-02-13 16:44:14,853 - util.py[DEBUG]: Attempting to load yaml from string of length 492 with allowed root types (<class 'dict'>,)
2025-02-13 16:44:14,857 - util.py[DEBUG]: Reading from /etc/cloud/cloud.cfg.d/90_dpkg.cfg (quiet=False)
2025-02-13 16:44:14,857 - util.py[DEBUG]: Reading 333 bytes from /etc/cloud/cloud.cfg.d/90_dpkg.cfg
2025-02-13 16:44:14,857 - util.py[DEBUG]: Attempting to load yaml from string of length 333 with allowed root types (<class 'dict'>,)
2025-02-13 16:44:14,861 - util.py[DEBUG]: Reading from /etc/cloud/cloud.cfg.d/05_logging.cfg (quiet=False)
2025-02-13 16:44:14,861 - util.py[DEBUG]: Reading 2071 bytes from /etc/cloud/cloud.cfg.d/05_logging.cfg
2025-02-13 16:44:14,861 - util.py[DEBUG]: Attempting to load yaml from string of length 2071 with allowed root types (<class 'dict'>,)
2025-02-13 16:44:14,869 - util.py[DEBUG]: Reading from /run/cloud-init/cloud.cfg (quiet=False)
2025-02-13 16:44:14,869 - util.py[DEBUG]: Reading 34 bytes from /run/cloud-init/cloud.cfg
2025-02-13 16:44:14,869 - util.py[DEBUG]: Attempting to load yaml from string of length 34 with allowed root types (<class 'dict'>,)
2025-02-13 16:44:14,869 - util.py[DEBUG]: Attempting to load yaml from string of length 0 with allowed root types (<class 'dict'>,)
2025-02-13 16:44:14,869 - util.py[DEBUG]: loaded blob returned None, returning default.
2025-02-13 16:44:14,870 - util.py[DEBUG]: Reading from /var/lib/cloud/instance/cloud-config.txt (quiet=False)
2025-02-13 16:44:14,870 - util.py[DEBUG]: Reading 0 bytes from /var/lib/cloud/instance/cloud-config.txt
2025-02-13 16:44:14,870 - util.py[DEBUG]: Attempting to load yaml from string of length 0 with allowed root types (<class 'dict'>,)
2025-02-13 16:44:14,870 - util.py[DEBUG]: loaded blob returned None, returning default.
2025-02-13 16:44:14,872 - util.py[DEBUG]: Reading from /etc/hosts (quiet=False)
2025-02-13 16:44:14,872 - util.py[DEBUG]: Reading 181 bytes from /etc/hosts
2025-02-13 16:44:14,874 - util.py[DEBUG]: Writing to /run/cloud-init/cloud-id-akamai - wb: [644] 7 bytes
2025-02-13 16:44:14,874 - util.py[DEBUG]: Creating symbolic link from '/run/cloud-init/cloud-id' => '/run/cloud-init/cloud-id-akamai'
2025-02-13 16:44:14,876 - atomic_helper.py[DEBUG]: Atomically writing to file /run/cloud-init/instance-data-sensitive.json (via temporary file /run/cloud-init/tmpil3kox1_) - w: [600] 8726 bytes/chars
2025-02-13 16:44:14,877 - atomic_helper.py[DEBUG]: Atomically writing to file /run/cloud-init/instance-data.json (via temporary file /run/cloud-init/tmpu6ogjp8h) - w: [644] 1941 bytes/chars
2025-02-13 16:44:14,877 - stages.py[INFO]: Instance link already exists, not recreating it.
2025-02-13 16:44:14,877 - util.py[DEBUG]: Reading from /var/lib/cloud/instances/71855604/datasource (quiet=False)
2025-02-13 16:44:14,878 - util.py[DEBUG]: Reading 45 bytes from /var/lib/cloud/instances/71855604/datasource
2025-02-13 16:44:14,878 - util.py[DEBUG]: Writing to /var/lib/cloud/instances/71855604/datasource - wb: [644] 45 bytes
2025-02-13 16:44:14,879 - util.py[DEBUG]: Writing to /var/lib/cloud/data/previous-datasource - wb: [644] 45 bytes
2025-02-13 16:44:14,881 - util.py[DEBUG]: Reading from /var/lib/cloud/data/instance-id (quiet=False)
2025-02-13 16:44:14,881 - util.py[DEBUG]: Reading 9 bytes from /var/lib/cloud/data/instance-id
2025-02-13 16:44:14,881 - stages.py[DEBUG]: previous iid found to be 71855604
2025-02-13 16:44:14,882 - util.py[DEBUG]: Writing to /var/lib/cloud/data/instance-id - wb: [644] 9 bytes
2025-02-13 16:44:14,882 - util.py[DEBUG]: Writing to /run/cloud-init/.instance-id - wb: [644] 9 bytes
2025-02-13 16:44:14,882 - util.py[DEBUG]: Writing to /var/lib/cloud/data/previous-instance-id - wb: [644] 9 bytes
2025-02-13 16:44:14,883 - util.py[DEBUG]: Writing to /var/lib/cloud/instance/obj.pkl - wb: [400] 9381 bytes
2025-02-13 16:44:14,885 - stages.py[INFO]: Not re-loading configuration, instance id and datasource have not changed.
2025-02-13 16:44:14,886 - main.py[DEBUG]: [local] init will now be targeting instance id: 71855604. new=False
2025-02-13 16:44:14,886 - stages.py[DEBUG]: Using distro class <class 'cloudinit.distros.ubuntu.Distro'>
2025-02-13 16:44:14,888 - util.py[DEBUG]: Reading from /sys/class/net/eth0/address (quiet=False)
2025-02-13 16:44:14,888 - util.py[DEBUG]: Reading 18 bytes from /sys/class/net/eth0/address
2025-02-13 16:44:14,888 - util.py[DEBUG]: Reading from /sys/class/net/lo/address (quiet=False)
2025-02-13 16:44:14,888 - util.py[DEBUG]: Reading 18 bytes from /sys/class/net/lo/address
2025-02-13 16:44:14,888 - stages.py[DEBUG]: network config disabled by system_cfg
2025-02-13 16:44:14,888 - stages.py[INFO]: network config is disabled by system_cfg
2025-02-13 16:44:14,888 - main.py[DEBUG]: Network connectivity determined unnecessary for cloud-init's network stage. Reason: user data: no configuration found, vendor data: no configuration found, vendor data2: no configuration found
2025-02-13 16:44:14,888 - util.py[DEBUG]: Writing to /run/cloud-init/.skip-network - wb: [644] 0 bytes
2025-02-13 16:44:14,888 - main.py[DEBUG]: [local] Exiting. datasource DataSourceAkamaiLocal not in local mode.
2025-02-13 16:44:14,889 - util.py[DEBUG]: Reading from /proc/uptime (quiet=False)
2025-02-13 16:44:14,889 - util.py[DEBUG]: Reading 10 bytes from /proc/uptime
2025-02-13 16:44:14,889 - atomic_helper.py[DEBUG]: Atomically writing to file /var/lib/cloud/data/status.json (via temporary file /var/lib/cloud/data/tmpnoa_0r5v) - w: [644] 502 bytes/chars
2025-02-13 16:44:14,892 - performance.py[DEBUG]: cloud-init stage: 'init-local' took 0.196 seconds
2025-02-13 16:44:14,892 - handlers.py[DEBUG]: finish: init-local: SUCCESS: searching for local datasources
2025-02-13 16:44:19,599 - log_util.py[DEBUG]: Cloud-init v. 24.4-0ubuntu1~22.04.1 running 'init' at Thu, 13 Feb 2025 16:44:19 +0000. Up 10.77 seconds.
2025-02-13 16:44:19,599 - main.py[INFO]: PID [1] started cloud-init 'init'.
2025-02-13 16:44:19,599 - main.py[DEBUG]: No kernel command line url found.
2025-02-13 16:44:19,600 - main.py[DEBUG]: Closing stdin
2025-02-13 16:44:19,601 - util.py[DEBUG]: Writing to /var/log/cloud-init.log - ab: [640] 0 bytes
2025-02-13 16:44:19,602 - util.py[DEBUG]: Changing the ownership of /var/log/cloud-init.log to 104:4
2025-02-13 16:44:19,602 - util.py[DEBUG]: Reading from /var/lib/cloud/data/python-version (quiet=False)
2025-02-13 16:44:19,602 - util.py[DEBUG]: Reading 4 bytes from /var/lib/cloud/data/python-version
2025-02-13 16:44:19,606 - subp.py[DEBUG]: Running command ['ip', '--json', 'addr'] with allowed return codes [0] (shell=False, capture=True)
2025-02-13 16:44:19,615 - subp.py[DEBUG]: Running command ['ip', '-o', 'route', 'list'] with allowed return codes [0] (shell=False, capture=True)
2025-02-13 16:44:19,617 - subp.py[DEBUG]: Running command ['ip', '--oneline', '-6', 'route', 'list', 'table', 'all'] with allowed return codes [0, 1] (shell=False, capture=True)
2025-02-13 16:44:19,619 - handlers.py[DEBUG]: start: init-network/check-cache: attempting to read from cache [trust]
2025-02-13 16:44:19,619 - util.py[DEBUG]: Reading from /var/lib/cloud/instance/obj.pkl (quiet=False)
2025-02-13 16:44:19,620 - util.py[DEBUG]: Reading 9381 bytes from /var/lib/cloud/instance/obj.pkl
2025-02-13 16:44:19,628 - util.py[DEBUG]: Reading from /run/cloud-init/.instance-id (quiet=False)
2025-02-13 16:44:19,628 - util.py[DEBUG]: Reading 9 bytes from /run/cloud-init/.instance-id
2025-02-13 16:44:19,628 - stages.py[DEBUG]: restored from cache with run check: DataSourceAkamaiLocal
2025-02-13 16:44:19,628 - handlers.py[DEBUG]: finish: init-network/check-cache: SUCCESS: restored from cache with run check: DataSourceAkamaiLocal
2025-02-13 16:44:19,628 - util.py[DEBUG]: Reading from /etc/cloud/cloud.cfg (quiet=False)
2025-02-13 16:44:19,628 - util.py[DEBUG]: Reading 3766 bytes from /etc/cloud/cloud.cfg
2025-02-13 16:44:19,628 - util.py[DEBUG]: Attempting to load yaml from string of length 3766 with allowed root types (<class 'dict'>,)
2025-02-13 16:44:19,653 - util.py[DEBUG]: Reading from /etc/cloud/cloud.cfg.d/99-linode.cfg (quiet=False)
2025-02-13 16:44:19,653 - util.py[DEBUG]: Reading 492 bytes from /etc/cloud/cloud.cfg.d/99-linode.cfg
2025-02-13 16:44:19,653 - util.py[DEBUG]: Attempting to load yaml from string of length 492 with allowed root types (<class 'dict'>,)
2025-02-13 16:44:19,659 - util.py[DEBUG]: Reading from /etc/cloud/cloud.cfg.d/90_dpkg.cfg (quiet=False)
2025-02-13 16:44:19,659 - util.py[DEBUG]: Reading 333 bytes from /etc/cloud/cloud.cfg.d/90_dpkg.cfg
2025-02-13 16:44:19,659 - util.py[DEBUG]: Attempting to load yaml from string of length 333 with allowed root types (<class 'dict'>,)
2025-02-13 16:44:19,661 - util.py[DEBUG]: Reading from /etc/cloud/cloud.cfg.d/05_logging.cfg (quiet=False)
2025-02-13 16:44:19,661 - util.py[DEBUG]: Reading 2071 bytes from /etc/cloud/cloud.cfg.d/05_logging.cfg
2025-02-13 16:44:19,661 - util.py[DEBUG]: Attempting to load yaml from string of length 2071 with allowed root types (<class 'dict'>,)
2025-02-13 16:44:19,669 - util.py[DEBUG]: Reading from /run/cloud-init/cloud.cfg (quiet=False)
2025-02-13 16:44:19,670 - util.py[DEBUG]: Reading 34 bytes from /run/cloud-init/cloud.cfg
2025-02-13 16:44:19,670 - util.py[DEBUG]: Attempting to load yaml from string of length 34 with allowed root types (<class 'dict'>,)
2025-02-13 16:44:19,670 - util.py[DEBUG]: Attempting to load yaml from string of length 0 with allowed root types (<class 'dict'>,)
2025-02-13 16:44:19,670 - util.py[DEBUG]: loaded blob returned None, returning default.
2025-02-13 16:44:19,672 - util.py[DEBUG]: Reading from /var/lib/cloud/instance/cloud-config.txt (quiet=False)
2025-02-13 16:44:19,672 - util.py[DEBUG]: Reading 0 bytes from /var/lib/cloud/instance/cloud-config.txt
2025-02-13 16:44:19,672 - util.py[DEBUG]: Attempting to load yaml from string of length 0 with allowed root types (<class 'dict'>,)
2025-02-13 16:44:19,673 - util.py[DEBUG]: loaded blob returned None, returning default.
2025-02-13 16:44:19,673 - stages.py[INFO]: Instance link already exists, not recreating it.
2025-02-13 16:44:19,673 - util.py[DEBUG]: Reading from /var/lib/cloud/instances/71855604/datasource (quiet=False)
2025-02-13 16:44:19,674 - util.py[DEBUG]: Reading 45 bytes from /var/lib/cloud/instances/71855604/datasource
2025-02-13 16:44:19,674 - util.py[DEBUG]: Writing to /var/lib/cloud/instances/71855604/datasource - wb: [644] 45 bytes
2025-02-13 16:44:19,678 - util.py[DEBUG]: Writing to /var/lib/cloud/data/previous-datasource - wb: [644] 45 bytes
2025-02-13 16:44:19,678 - util.py[DEBUG]: Reading from /var/lib/cloud/data/instance-id (quiet=False)
2025-02-13 16:44:19,678 - util.py[DEBUG]: Reading 9 bytes from /var/lib/cloud/data/instance-id
2025-02-13 16:44:19,678 - stages.py[DEBUG]: previous iid found to be 71855604
2025-02-13 16:44:19,678 - util.py[DEBUG]: Writing to /var/lib/cloud/data/instance-id - wb: [644] 9 bytes
2025-02-13 16:44:19,679 - util.py[DEBUG]: Writing to /run/cloud-init/.instance-id - wb: [644] 9 bytes
2025-02-13 16:44:19,679 - util.py[DEBUG]: Writing to /var/lib/cloud/data/previous-instance-id - wb: [644] 9 bytes
2025-02-13 16:44:19,681 - util.py[DEBUG]: Writing to /var/lib/cloud/instance/obj.pkl - wb: [400] 9381 bytes
2025-02-13 16:44:19,682 - stages.py[INFO]: Not re-loading configuration, instance id and datasource have not changed.
2025-02-13 16:44:19,682 - main.py[DEBUG]: [net] init will now be targeting instance id: 71855604. new=False
2025-02-13 16:44:19,682 - util.py[DEBUG]: Reading from /sys/class/net/eth0/address (quiet=False)
2025-02-13 16:44:19,682 - util.py[DEBUG]: Reading 18 bytes from /sys/class/net/eth0/address
2025-02-13 16:44:19,682 - util.py[DEBUG]: Reading from /sys/class/net/lo/address (quiet=False)
2025-02-13 16:44:19,683 - util.py[DEBUG]: Reading 18 bytes from /sys/class/net/lo/address
2025-02-13 16:44:19,683 - stages.py[DEBUG]: network config disabled by system_cfg
2025-02-13 16:44:19,683 - stages.py[INFO]: network config is disabled by system_cfg
2025-02-13 16:44:19,683 - handlers.py[DEBUG]: start: init-network/setup-datasource: setting up datasource
2025-02-13 16:44:19,683 - handlers.py[DEBUG]: finish: init-network/setup-datasource: SUCCESS: setting up datasource
2025-02-13 16:44:19,683 - util.py[DEBUG]: Writing to /var/lib/cloud/instances/71855604/user-data.txt - wb: [600] 0 bytes
2025-02-13 16:44:19,684 - util.py[DEBUG]: Writing to /var/lib/cloud/instances/71855604/user-data.txt.i - wb: [600] 308 bytes
2025-02-13 16:44:19,687 - util.py[DEBUG]: Writing to /var/lib/cloud/instances/71855604/vendor-data.txt - wb: [600] 0 bytes
2025-02-13 16:44:19,688 - util.py[DEBUG]: Writing to /var/lib/cloud/instances/71855604/vendor-data.txt.i - wb: [600] 308 bytes
2025-02-13 16:44:19,688 - util.py[DEBUG]: Writing to /var/lib/cloud/instances/71855604/vendor-data2.txt - wb: [600] 0 bytes
2025-02-13 16:44:19,689 - util.py[DEBUG]: Writing to /var/lib/cloud/instances/71855604/vendor-data2.txt.i - wb: [600] 308 bytes
2025-02-13 16:44:19,691 - stages.py[DEBUG]: Using distro class <class 'cloudinit.distros.ubuntu.Distro'>
2025-02-13 16:44:19,694 - helpers.py[DEBUG]: consume_data already ran (freq=once-per-instance)
2025-02-13 16:44:19,694 - handlers.py[DEBUG]: start: init-network/consume-user-data: reading and applying user-data
2025-02-13 16:44:19,696 - stages.py[DEBUG]: Added default handler for {'text/cloud-config', 'text/cloud-config-jsonp'} from CloudConfigPartHandler: [['text/cloud-config', 'text/cloud-config-jsonp']]
2025-02-13 16:44:19,696 - stages.py[DEBUG]: Added default handler for {'text/x-shellscript'} from ShellScriptPartHandler: [['text/x-shellscript']]
2025-02-13 16:44:19,696 - stages.py[DEBUG]: Added default handler for {'text/x-shellscript-per-boot'} from ShellScriptByFreqPartHandler: [['text/x-shellscript-per-boot']]
2025-02-13 16:44:19,696 - stages.py[DEBUG]: Added default handler for {'text/x-shellscript-per-instance'} from ShellScriptByFreqPartHandler: [['text/x-shellscript-per-instance']]
2025-02-13 16:44:19,696 - stages.py[DEBUG]: Added default handler for {'text/x-shellscript-per-once'} from ShellScriptByFreqPartHandler: [['text/x-shellscript-per-once']]
2025-02-13 16:44:19,696 - stages.py[DEBUG]: Added default handler for {'text/cloud-boothook'} from BootHookPartHandler: [['text/cloud-boothook']]
2025-02-13 16:44:19,696 - stages.py[DEBUG]: Added default handler for {'text/jinja2'} from JinjaTemplatePartHandler: [['text/jinja2']]
2025-02-13 16:44:19,696 - handlers[DEBUG]: Calling handler CloudConfigPartHandler: [['text/cloud-config', 'text/cloud-config-jsonp']] (__begin__, None, 3) with frequency always
2025-02-13 16:44:19,696 - handlers[DEBUG]: Calling handler ShellScriptPartHandler: [['text/x-shellscript']] (__begin__, None, 2) with frequency always
2025-02-13 16:44:19,696 - handlers[DEBUG]: Calling handler ShellScriptByFreqPartHandler: [['text/x-shellscript-per-boot']] (__begin__, None, 2) with frequency always
2025-02-13 16:44:19,696 - handlers[DEBUG]: Calling handler ShellScriptByFreqPartHandler: [['text/x-shellscript-per-instance']] (__begin__, None, 2) with frequency always
2025-02-13 16:44:19,696 - handlers[DEBUG]: Calling handler ShellScriptByFreqPartHandler: [['text/x-shellscript-per-once']] (__begin__, None, 2) with frequency always
2025-02-13 16:44:19,696 - handlers[DEBUG]: Calling handler BootHookPartHandler: [['text/cloud-boothook']] (__begin__, None, 2) with frequency always
2025-02-13 16:44:19,697 - handlers[DEBUG]: Calling handler JinjaTemplatePartHandler: [['text/jinja2']] (__begin__, None, 3) with frequency always
2025-02-13 16:44:19,697 - handlers[DEBUG]: {'MIME-Version': '1.0', 'Content-Type': 'text/x-not-multipart', 'Content-Disposition': 'attachment; filename="part-001"'}
2025-02-13 16:44:19,697 - handlers[DEBUG]: Empty payload of type text/x-not-multipart
2025-02-13 16:44:19,697 - handlers[DEBUG]: Calling handler CloudConfigPartHandler: [['text/cloud-config', 'text/cloud-config-jsonp']] (__end__, None, 3) with frequency always
2025-02-13 16:44:19,697 - util.py[DEBUG]: Writing to /var/lib/cloud/instances/71855604/cloud-config.txt - wb: [600] 0 bytes
2025-02-13 16:44:19,699 - handlers[DEBUG]: Calling handler ShellScriptPartHandler: [['text/x-shellscript']] (__end__, None, 2) with frequency always
2025-02-13 16:44:19,699 - handlers[DEBUG]: Calling handler ShellScriptByFreqPartHandler: [['text/x-shellscript-per-boot']] (__end__, None, 2) with frequency always
2025-02-13 16:44:19,699 - handlers[DEBUG]: Calling handler ShellScriptByFreqPartHandler: [['text/x-shellscript-per-instance']] (__end__, None, 2) with frequency always
2025-02-13 16:44:19,699 - handlers[DEBUG]: Calling handler ShellScriptByFreqPartHandler: [['text/x-shellscript-per-once']] (__end__, None, 2) with frequency always
2025-02-13 16:44:19,699 - handlers[DEBUG]: Calling handler BootHookPartHandler: [['text/cloud-boothook']] (__end__, None, 2) with frequency always
2025-02-13 16:44:19,699 - handlers[DEBUG]: Calling handler JinjaTemplatePartHandler: [['text/jinja2']] (__end__, None, 3) with frequency always
2025-02-13 16:44:19,699 - handlers.py[DEBUG]: finish: init-network/consume-user-data: SUCCESS: reading and applying user-data
2025-02-13 16:44:19,699 - handlers.py[DEBUG]: start: init-network/consume-vendor-data: reading and applying vendor-data
2025-02-13 16:44:19,699 - stages.py[DEBUG]: no vendordata from datasource
2025-02-13 16:44:19,699 - handlers.py[DEBUG]: finish: init-network/consume-vendor-data: SUCCESS: reading and applying vendor-data
2025-02-13 16:44:19,700 - handlers.py[DEBUG]: start: init-network/consume-vendor-data2: reading and applying vendor-data2
2025-02-13 16:44:19,700 - stages.py[DEBUG]: no vendordata2 from datasource
2025-02-13 16:44:19,700 - handlers.py[DEBUG]: finish: init-network/consume-vendor-data2: SUCCESS: reading and applying vendor-data2
2025-02-13 16:44:19,700 - util.py[DEBUG]: Reading from /etc/cloud/cloud.cfg (quiet=False)
2025-02-13 16:44:19,700 - util.py[DEBUG]: Reading 3766 bytes from /etc/cloud/cloud.cfg
2025-02-13 16:44:19,700 - util.py[DEBUG]: Attempting to load yaml from string of length 3766 with allowed root types (<class 'dict'>,)
2025-02-13 16:44:19,719 - util.py[DEBUG]: Reading from /etc/cloud/cloud.cfg.d/99-linode.cfg (quiet=False)
2025-02-13 16:44:19,719 - util.py[DEBUG]: Reading 492 bytes from /etc/cloud/cloud.cfg.d/99-linode.cfg
2025-02-13 16:44:19,719 - util.py[DEBUG]: Attempting to load yaml from string of length 492 with allowed root types (<class 'dict'>,)
2025-02-13 16:44:19,720 - util.py[DEBUG]: Reading from /etc/cloud/cloud.cfg.d/90_dpkg.cfg (quiet=False)
2025-02-13 16:44:19,720 - util.py[DEBUG]: Reading 333 bytes from /etc/cloud/cloud.cfg.d/90_dpkg.cfg
2025-02-13 16:44:19,721 - util.py[DEBUG]: Attempting to load yaml from string of length 333 with allowed root types (<class 'dict'>,)
2025-02-13 16:44:19,722 - util.py[DEBUG]: Reading from /etc/cloud/cloud.cfg.d/05_logging.cfg (quiet=False)
2025-02-13 16:44:19,723 - util.py[DEBUG]: Reading 2071 bytes from /etc/cloud/cloud.cfg.d/05_logging.cfg
2025-02-13 16:44:19,723 - util.py[DEBUG]: Attempting to load yaml from string of length 2071 with allowed root types (<class 'dict'>,)
2025-02-13 16:44:19,726 - util.py[DEBUG]: Reading from /run/cloud-init/cloud.cfg (quiet=False)
2025-02-13 16:44:19,726 - util.py[DEBUG]: Reading 34 bytes from /run/cloud-init/cloud.cfg
2025-02-13 16:44:19,726 - util.py[DEBUG]: Attempting to load yaml from string of length 34 with allowed root types (<class 'dict'>,)
2025-02-13 16:44:19,726 - util.py[DEBUG]: Attempting to load yaml from string of length 0 with allowed root types (<class 'dict'>,)
2025-02-13 16:44:19,727 - util.py[DEBUG]: loaded blob returned None, returning default.
2025-02-13 16:44:19,727 - util.py[DEBUG]: Reading from /var/lib/cloud/instance/cloud-config.txt (quiet=False)
2025-02-13 16:44:19,727 - util.py[DEBUG]: Reading 0 bytes from /var/lib/cloud/instance/cloud-config.txt
2025-02-13 16:44:19,727 - util.py[DEBUG]: Attempting to load yaml from string of length 0 with allowed root types (<class 'dict'>,)
2025-02-13 16:44:19,727 - util.py[DEBUG]: loaded blob returned None, returning default.
2025-02-13 16:44:19,729 - atomic_helper.py[DEBUG]: Atomically writing to file /run/cloud-init/combined-cloud-config.json (via temporary file /run/cloud-init/tmpgnmb46g4) - w: [600] 5471 bytes/chars
2025-02-13 16:44:19,729 - util.py[DEBUG]: Reading from /run/cloud-init/instance-data-sensitive.json (quiet=False)
2025-02-13 16:44:19,729 - util.py[DEBUG]: Reading 8726 bytes from /run/cloud-init/instance-data-sensitive.json
2025-02-13 16:44:19,729 - atomic_helper.py[DEBUG]: Atomically writing to file /run/cloud-init/instance-data-sensitive.json (via temporary file /run/cloud-init/tmpmr7p1x1z) - w: [600] 10709 bytes/chars
2025-02-13 16:44:19,729 - main.py[DEBUG]: Skipping user-data validation. No user-data found.
2025-02-13 16:44:19,730 - util.py[DEBUG]: Reading from /var/lib/cloud/instance/cloud-config.txt (quiet=False)
2025-02-13 16:44:19,730 - util.py[DEBUG]: Reading 0 bytes from /var/lib/cloud/instance/cloud-config.txt
2025-02-13 16:44:19,730 - util.py[DEBUG]: Attempting to load yaml from string of length 0 with allowed root types (<class 'dict'>,)
2025-02-13 16:44:19,730 - util.py[DEBUG]: loaded blob returned None, returning default.
2025-02-13 16:44:19,732 - handlers.py[DEBUG]: start: init-network/activate-datasource: activating datasource
2025-02-13 16:44:19,733 - util.py[DEBUG]: Writing to /var/lib/cloud/instance/obj.pkl - wb: [400] 9372 bytes
2025-02-13 16:44:19,734 - handlers.py[DEBUG]: finish: init-network/activate-datasource: SUCCESS: activating datasource
2025-02-13 16:44:19,734 - main.py[DEBUG]: no di_report found in config.
2025-02-13 16:44:19,747 - stages.py[DEBUG]: Using distro class <class 'cloudinit.distros.ubuntu.Distro'>
2025-02-13 16:44:19,748 - modules.py[INFO]: Skipping modules 'bootcmd,write_files,disk_setup,update_etc_hosts,ca_certs,rsyslog' because no applicable config is provided.
2025-02-13 16:44:19,749 - modules.py[DEBUG]: Running module seed_random (<module 'cloudinit.config.cc_seed_random' from '/usr/lib/python3/dist-packages/cloudinit/config/cc_seed_random.py'>) with frequency once-per-instance
2025-02-13 16:44:19,749 - handlers.py[DEBUG]: start: init-network/config-seed_random: running config-seed_random with frequency once-per-instance
2025-02-13 16:44:19,749 - helpers.py[DEBUG]: config-seed_random already ran (freq=once-per-instance)
2025-02-13 16:44:19,749 - handlers.py[DEBUG]: finish: init-network/config-seed_random: SUCCESS: config-seed_random previously ran
2025-02-13 16:44:19,749 - modules.py[DEBUG]: Running module growpart (<module 'cloudinit.config.cc_growpart' from '/usr/lib/python3/dist-packages/cloudinit/config/cc_growpart.py'>) with frequency always
2025-02-13 16:44:19,749 - handlers.py[DEBUG]: start: init-network/config-growpart: running config-growpart with frequency always
2025-02-13 16:44:19,749 - helpers.py[DEBUG]: Running config-growpart using lock (<cloudinit.helpers.DummyLock object at 0x7ff5274c4ee0>)
2025-02-13 16:44:19,749 - cc_growpart.py[DEBUG]: No 'growpart' entry in cfg.  Using default: {'mode': 'auto', 'devices': ['/'], 'ignore_growroot_disabled': False}
2025-02-13 16:44:19,749 - subp.py[DEBUG]: Running command ['growpart', '--help'] with allowed return codes [0] (shell=False, capture=True)
2025-02-13 16:44:19,752 - util.py[DEBUG]: Reading from /proc/629/mountinfo (quiet=False)
2025-02-13 16:44:19,753 - util.py[DEBUG]: Reading 2056 bytes from /proc/629/mountinfo
2025-02-13 16:44:19,753 - cc_growpart.py[DEBUG]: growpart found fs=ext4
2025-02-13 16:44:19,753 - cc_growpart.py[DEBUG]: '/' SKIPPED: device_part_info(/dev/sda) failed: /dev/sda not a partition
2025-02-13 16:44:19,753 - handlers.py[DEBUG]: finish: init-network/config-growpart: SUCCESS: config-growpart ran successfully and took 0.004 seconds
2025-02-13 16:44:19,753 - modules.py[DEBUG]: Running module resizefs (<module 'cloudinit.config.cc_resizefs' from '/usr/lib/python3/dist-packages/cloudinit/config/cc_resizefs.py'>) with frequency always
2025-02-13 16:44:19,753 - handlers.py[DEBUG]: start: init-network/config-resizefs: running config-resizefs with frequency always
2025-02-13 16:44:19,753 - helpers.py[DEBUG]: Running config-resizefs using lock (<cloudinit.helpers.DummyLock object at 0x7ff5274c5ae0>)
2025-02-13 16:44:19,753 - util.py[DEBUG]: Reading from /proc/629/mountinfo (quiet=False)
2025-02-13 16:44:19,753 - util.py[DEBUG]: Reading 2056 bytes from /proc/629/mountinfo
2025-02-13 16:44:19,753 - cc_resizefs.py[DEBUG]: resize_info: dev=/dev/sda mnt_point=/ path=/
2025-02-13 16:44:19,754 - cc_resizefs.py[DEBUG]: Resizing / (ext4) using resize2fs /dev/sda
2025-02-13 16:44:19,754 - subp.py[DEBUG]: Running command ('resize2fs', '/dev/sda') with allowed return codes [0] (shell=False, capture=True)
2025-02-13 16:44:19,768 - performance.py[DEBUG]: Running ('resize2fs', '/dev/sda') took 0.014 seconds
2025-02-13 16:44:19,768 - cc_resizefs.py[DEBUG]: Resized root filesystem (type=ext4, val=True)
2025-02-13 16:44:19,768 - handlers.py[DEBUG]: finish: init-network/config-resizefs: SUCCESS: config-resizefs ran successfully and took 0.015 seconds
2025-02-13 16:44:19,768 - modules.py[DEBUG]: Running module mounts (<module 'cloudinit.config.cc_mounts' from '/usr/lib/python3/dist-packages/cloudinit/config/cc_mounts.py'>) with frequency once-per-instance
2025-02-13 16:44:19,769 - handlers.py[DEBUG]: start: init-network/config-mounts: running config-mounts with frequency once-per-instance
2025-02-13 16:44:19,769 - helpers.py[DEBUG]: config-mounts already ran (freq=once-per-instance)
2025-02-13 16:44:19,769 - handlers.py[DEBUG]: finish: init-network/config-mounts: SUCCESS: config-mounts previously ran
2025-02-13 16:44:19,769 - modules.py[DEBUG]: Running module set_hostname (<module 'cloudinit.config.cc_set_hostname' from '/usr/lib/python3/dist-packages/cloudinit/config/cc_set_hostname.py'>) with frequency once-per-instance
2025-02-13 16:44:19,769 - handlers.py[DEBUG]: start: init-network/config-set_hostname: running config-set_hostname with frequency once-per-instance
2025-02-13 16:44:19,769 - helpers.py[DEBUG]: config-set_hostname already ran (freq=once-per-instance)
2025-02-13 16:44:19,769 - handlers.py[DEBUG]: finish: init-network/config-set_hostname: SUCCESS: config-set_hostname previously ran
2025-02-13 16:44:19,770 - modules.py[DEBUG]: Running module update_hostname (<module 'cloudinit.config.cc_update_hostname' from '/usr/lib/python3/dist-packages/cloudinit/config/cc_update_hostname.py'>) with frequency always
2025-02-13 16:44:19,770 - handlers.py[DEBUG]: start: init-network/config-update_hostname: running config-update_hostname with frequency always
2025-02-13 16:44:19,770 - helpers.py[DEBUG]: Running config-update_hostname using lock (<cloudinit.helpers.DummyLock object at 0x7ff5274c7040>)
2025-02-13 16:44:19,770 - util.py[DEBUG]: Reading from /etc/hosts (quiet=False)
2025-02-13 16:44:19,770 - util.py[DEBUG]: Reading 181 bytes from /etc/hosts
2025-02-13 16:44:19,770 - util.py[DEBUG]: Reading from /etc/hosts (quiet=False)
2025-02-13 16:44:19,770 - util.py[DEBUG]: Reading 181 bytes from /etc/hosts
2025-02-13 16:44:19,770 - cc_update_hostname.py[DEBUG]: Hostname is localhost. Let other services handle this.
2025-02-13 16:44:19,770 - handlers.py[DEBUG]: finish: init-network/config-update_hostname: SUCCESS: config-update_hostname ran successfully and took 0.001 seconds
2025-02-13 16:44:19,770 - modules.py[DEBUG]: Running module users_groups (<module 'cloudinit.config.cc_users_groups' from '/usr/lib/python3/dist-packages/cloudinit/config/cc_users_groups.py'>) with frequency once-per-instance
2025-02-13 16:44:19,771 - handlers.py[DEBUG]: start: init-network/config-users_groups: running config-users_groups with frequency once-per-instance
2025-02-13 16:44:19,771 - helpers.py[DEBUG]: config-users_groups already ran (freq=once-per-instance)
2025-02-13 16:44:19,771 - handlers.py[DEBUG]: finish: init-network/config-users_groups: SUCCESS: config-users_groups previously ran
2025-02-13 16:44:19,771 - modules.py[DEBUG]: Running module ssh (<module 'cloudinit.config.cc_ssh' from '/usr/lib/python3/dist-packages/cloudinit/config/cc_ssh.py'>) with frequency once-per-instance
2025-02-13 16:44:19,771 - handlers.py[DEBUG]: start: init-network/config-ssh: running config-ssh with frequency once-per-instance
2025-02-13 16:44:19,771 - helpers.py[DEBUG]: config-ssh already ran (freq=once-per-instance)
2025-02-13 16:44:19,771 - handlers.py[DEBUG]: finish: init-network/config-ssh: SUCCESS: config-ssh previously ran
2025-02-13 16:44:19,771 - modules.py[DEBUG]: Running module set_passwords (<module 'cloudinit.config.cc_set_passwords' from '/usr/lib/python3/dist-packages/cloudinit/config/cc_set_passwords.py'>) with frequency once-per-instance
2025-02-13 16:44:19,771 - handlers.py[DEBUG]: start: init-network/config-set_passwords: running config-set_passwords with frequency once-per-instance
2025-02-13 16:44:19,771 - helpers.py[DEBUG]: config-set_passwords already ran (freq=once-per-instance)
2025-02-13 16:44:19,772 - handlers.py[DEBUG]: finish: init-network/config-set_passwords: SUCCESS: config-set_passwords previously ran
2025-02-13 16:44:19,772 - main.py[DEBUG]: Ran 9 modules with 0 failures
2025-02-13 16:44:19,772 - util.py[DEBUG]: Reading from /proc/uptime (quiet=False)
2025-02-13 16:44:19,772 - util.py[DEBUG]: Reading 11 bytes from /proc/uptime
2025-02-13 16:44:19,772 - atomic_helper.py[DEBUG]: Atomically writing to file /var/lib/cloud/data/status.json (via temporary file /var/lib/cloud/data/tmpdh3p9zqd) - w: [644] 504 bytes/chars
2025-02-13 16:44:19,772 - performance.py[DEBUG]: cloud-init stage: 'init-network' took 0.230 seconds
2025-02-13 16:44:19,773 - handlers.py[DEBUG]: finish: init-network: SUCCESS: searching for network datasources
2025-02-13 16:44:21,365 - log_util.py[DEBUG]: Cloud-init v. 24.4-0ubuntu1~22.04.1 running 'modules:config' at Thu, 13 Feb 2025 16:44:21 +0000. Up 12.38 seconds.
2025-02-13 16:44:21,365 - main.py[INFO]: PID [1] started cloud-init 'modules:config'.
2025-02-13 16:44:21,397 - stages.py[DEBUG]: Using distro class <class 'cloudinit.distros.ubuntu.Distro'>
2025-02-13 16:44:21,404 - modules.py[INFO]: Skipping modules 'wireguard,snap,ubuntu_autoinstall,keyboard,apt_pipelining,ubuntu_pro,ntp,timezone,disable_ec2_metadata,runcmd' because no applicable config is provided.
2025-02-13 16:44:21,405 - modules.py[DEBUG]: Running module ssh_import_id (<module 'cloudinit.config.cc_ssh_import_id' from '/usr/lib/python3/dist-packages/cloudinit/config/cc_ssh_import_id.py'>) with frequency once-per-instance
2025-02-13 16:44:21,406 - handlers.py[DEBUG]: start: modules-config/config-ssh_import_id: running config-ssh_import_id with frequency once-per-instance
2025-02-13 16:44:21,407 - helpers.py[DEBUG]: config-ssh_import_id already ran (freq=once-per-instance)
2025-02-13 16:44:21,407 - handlers.py[DEBUG]: finish: modules-config/config-ssh_import_id: SUCCESS: config-ssh_import_id previously ran
2025-02-13 16:44:21,407 - modules.py[DEBUG]: Running module locale (<module 'cloudinit.config.cc_locale' from '/usr/lib/python3/dist-packages/cloudinit/config/cc_locale.py'>) with frequency once-per-instance
2025-02-13 16:44:21,408 - handlers.py[DEBUG]: start: modules-config/config-locale: running config-locale with frequency once-per-instance
2025-02-13 16:44:21,409 - helpers.py[DEBUG]: config-locale already ran (freq=once-per-instance)
2025-02-13 16:44:21,409 - handlers.py[DEBUG]: finish: modules-config/config-locale: SUCCESS: config-locale previously ran
2025-02-13 16:44:21,410 - modules.py[DEBUG]: Running module grub_dpkg (<module 'cloudinit.config.cc_grub_dpkg' from '/usr/lib/python3/dist-packages/cloudinit/config/cc_grub_dpkg.py'>) with frequency once-per-instance
2025-02-13 16:44:21,410 - handlers.py[DEBUG]: start: modules-config/config-grub_dpkg: running config-grub_dpkg with frequency once-per-instance
2025-02-13 16:44:21,411 - helpers.py[DEBUG]: config-grub_dpkg already ran (freq=once-per-instance)
2025-02-13 16:44:21,411 - handlers.py[DEBUG]: finish: modules-config/config-grub_dpkg: SUCCESS: config-grub_dpkg previously ran
2025-02-13 16:44:21,412 - modules.py[DEBUG]: Running module apt_configure (<module 'cloudinit.config.cc_apt_configure' from '/usr/lib/python3/dist-packages/cloudinit/config/cc_apt_configure.py'>) with frequency once-per-instance
2025-02-13 16:44:21,413 - handlers.py[DEBUG]: start: modules-config/config-apt_configure: running config-apt_configure with frequency once-per-instance
2025-02-13 16:44:21,414 - helpers.py[DEBUG]: config-apt_configure already ran (freq=once-per-instance)
2025-02-13 16:44:21,414 - handlers.py[DEBUG]: finish: modules-config/config-apt_configure: SUCCESS: config-apt_configure previously ran
2025-02-13 16:44:21,415 - modules.py[DEBUG]: Running module byobu (<module 'cloudinit.config.cc_byobu' from '/usr/lib/python3/dist-packages/cloudinit/config/cc_byobu.py'>) with frequency once-per-instance
2025-02-13 16:44:21,415 - handlers.py[DEBUG]: start: modules-config/config-byobu: running config-byobu with frequency once-per-instance
2025-02-13 16:44:21,415 - helpers.py[DEBUG]: config-byobu already ran (freq=once-per-instance)
2025-02-13 16:44:21,416 - handlers.py[DEBUG]: finish: modules-config/config-byobu: SUCCESS: config-byobu previously ran
2025-02-13 16:44:21,416 - main.py[DEBUG]: Ran 5 modules with 0 failures
2025-02-13 16:44:21,416 - util.py[DEBUG]: Reading from /proc/uptime (quiet=False)
2025-02-13 16:44:21,417 - util.py[DEBUG]: Reading 11 bytes from /proc/uptime
2025-02-13 16:44:21,418 - atomic_helper.py[DEBUG]: Atomically writing to file /var/lib/cloud/data/status.json (via temporary file /var/lib/cloud/data/tmpoy8i5ubm) - w: [644] 506 bytes/chars
2025-02-13 16:44:21,419 - performance.py[DEBUG]: cloud-init stage: 'modules-config' took 0.329 seconds
2025-02-13 16:44:21,419 - handlers.py[DEBUG]: finish: modules-config: SUCCESS: running modules for config
2025-02-13 16:44:21,851 - log_util.py[DEBUG]: Cloud-init v. 24.4-0ubuntu1~22.04.1 running 'modules:final' at Thu, 13 Feb 2025 16:44:21 +0000. Up 13.00 seconds.
2025-02-13 16:44:21,851 - main.py[INFO]: PID [1] started cloud-init 'modules:final'.
2025-02-13 16:44:21,873 - stages.py[DEBUG]: Using distro class <class 'cloudinit.distros.ubuntu.Distro'>
2025-02-13 16:44:21,875 - modules.py[INFO]: Skipping modules 'package_update_upgrade_install,fan,landscape,lxd,ubuntu_drivers,write_files_deferred,puppet,chef,ansible,mcollective,salt_minion,phone_home,power_state_change' because no applicable config is provided.
2025-02-13 16:44:21,875 - modules.py[DEBUG]: Running module reset_rmc (<module 'cloudinit.config.cc_reset_rmc' from '/usr/lib/python3/dist-packages/cloudinit/config/cc_reset_rmc.py'>) with frequency once-per-instance
2025-02-13 16:44:21,875 - handlers.py[DEBUG]: start: modules-final/config-reset_rmc: running config-reset_rmc with frequency once-per-instance
2025-02-13 16:44:21,876 - helpers.py[DEBUG]: config-reset_rmc already ran (freq=once-per-instance)
2025-02-13 16:44:21,876 - handlers.py[DEBUG]: finish: modules-final/config-reset_rmc: SUCCESS: config-reset_rmc previously ran
2025-02-13 16:44:21,876 - modules.py[DEBUG]: Running module scripts_vendor (<module 'cloudinit.config.cc_scripts_vendor' from '/usr/lib/python3/dist-packages/cloudinit/config/cc_scripts_vendor.py'>) with frequency once-per-instance
2025-02-13 16:44:21,876 - handlers.py[DEBUG]: start: modules-final/config-scripts_vendor: running config-scripts_vendor with frequency once-per-instance
2025-02-13 16:44:21,876 - helpers.py[DEBUG]: config-scripts_vendor already ran (freq=once-per-instance)
2025-02-13 16:44:21,876 - handlers.py[DEBUG]: finish: modules-final/config-scripts_vendor: SUCCESS: config-scripts_vendor previously ran
2025-02-13 16:44:21,876 - modules.py[DEBUG]: Running module scripts_per_once (<module 'cloudinit.config.cc_scripts_per_once' from '/usr/lib/python3/dist-packages/cloudinit/config/cc_scripts_per_once.py'>) with frequency once
2025-02-13 16:44:21,876 - handlers.py[DEBUG]: start: modules-final/config-scripts_per_once: running config-scripts_per_once with frequency once
2025-02-13 16:44:21,877 - helpers.py[DEBUG]: config-scripts_per_once already ran (freq=once)
2025-02-13 16:44:21,877 - handlers.py[DEBUG]: finish: modules-final/config-scripts_per_once: SUCCESS: config-scripts_per_once previously ran
2025-02-13 16:44:21,877 - modules.py[DEBUG]: Running module scripts_per_boot (<module 'cloudinit.config.cc_scripts_per_boot' from '/usr/lib/python3/dist-packages/cloudinit/config/cc_scripts_per_boot.py'>) with frequency always
2025-02-13 16:44:21,877 - handlers.py[DEBUG]: start: modules-final/config-scripts_per_boot: running config-scripts_per_boot with frequency always
2025-02-13 16:44:21,877 - helpers.py[DEBUG]: Running config-scripts_per_boot using lock (<cloudinit.helpers.DummyLock object at 0x7f3ee1f5fbe0>)
2025-02-13 16:44:21,877 - handlers.py[DEBUG]: finish: modules-final/config-scripts_per_boot: SUCCESS: config-scripts_per_boot ran successfully and took 0.000 seconds
2025-02-13 16:44:21,877 - modules.py[DEBUG]: Running module scripts_per_instance (<module 'cloudinit.config.cc_scripts_per_instance' from '/usr/lib/python3/dist-packages/cloudinit/config/cc_scripts_per_instance.py'>) with frequency once-per-instance
2025-02-13 16:44:21,878 - handlers.py[DEBUG]: start: modules-final/config-scripts_per_instance: running config-scripts_per_instance with frequency once-per-instance
2025-02-13 16:44:21,878 - helpers.py[DEBUG]: config-scripts_per_instance already ran (freq=once-per-instance)
2025-02-13 16:44:21,878 - handlers.py[DEBUG]: finish: modules-final/config-scripts_per_instance: SUCCESS: config-scripts_per_instance previously ran
2025-02-13 16:44:21,878 - modules.py[DEBUG]: Running module scripts_user (<module 'cloudinit.config.cc_scripts_user' from '/usr/lib/python3/dist-packages/cloudinit/config/cc_scripts_user.py'>) with frequency once-per-instance
2025-02-13 16:44:21,878 - handlers.py[DEBUG]: start: modules-final/config-scripts_user: running config-scripts_user with frequency once-per-instance
2025-02-13 16:44:21,878 - helpers.py[DEBUG]: config-scripts_user already ran (freq=once-per-instance)
2025-02-13 16:44:21,878 - handlers.py[DEBUG]: finish: modules-final/config-scripts_user: SUCCESS: config-scripts_user previously ran
2025-02-13 16:44:21,878 - modules.py[DEBUG]: Running module ssh_authkey_fingerprints (<module 'cloudinit.config.cc_ssh_authkey_fingerprints' from '/usr/lib/python3/dist-packages/cloudinit/config/cc_ssh_authkey_fingerprints.py'>) with frequency once-per-instance
2025-02-13 16:44:21,878 - handlers.py[DEBUG]: start: modules-final/config-ssh_authkey_fingerprints: running config-ssh_authkey_fingerprints with frequency once-per-instance
2025-02-13 16:44:21,878 - helpers.py[DEBUG]: config-ssh_authkey_fingerprints already ran (freq=once-per-instance)
2025-02-13 16:44:21,878 - handlers.py[DEBUG]: finish: modules-final/config-ssh_authkey_fingerprints: SUCCESS: config-ssh_authkey_fingerprints previously ran
2025-02-13 16:44:21,879 - modules.py[DEBUG]: Running module keys_to_console (<module 'cloudinit.config.cc_keys_to_console' from '/usr/lib/python3/dist-packages/cloudinit/config/cc_keys_to_console.py'>) with frequency once-per-instance
2025-02-13 16:44:21,879 - handlers.py[DEBUG]: start: modules-final/config-keys_to_console: running config-keys_to_console with frequency once-per-instance
2025-02-13 16:44:21,879 - helpers.py[DEBUG]: config-keys_to_console already ran (freq=once-per-instance)
2025-02-13 16:44:21,879 - handlers.py[DEBUG]: finish: modules-final/config-keys_to_console: SUCCESS: config-keys_to_console previously ran
2025-02-13 16:44:21,879 - modules.py[DEBUG]: Running module install_hotplug (<module 'cloudinit.config.cc_install_hotplug' from '/usr/lib/python3/dist-packages/cloudinit/config/cc_install_hotplug.py'>) with frequency once-per-instance
2025-02-13 16:44:21,879 - handlers.py[DEBUG]: start: modules-final/config-install_hotplug: running config-install_hotplug with frequency once-per-instance
2025-02-13 16:44:21,879 - helpers.py[DEBUG]: config-install_hotplug already ran (freq=once-per-instance)
2025-02-13 16:44:21,879 - handlers.py[DEBUG]: finish: modules-final/config-install_hotplug: SUCCESS: config-install_hotplug previously ran
2025-02-13 16:44:21,879 - modules.py[DEBUG]: Running module final_message (<module 'cloudinit.config.cc_final_message' from '/usr/lib/python3/dist-packages/cloudinit/config/cc_final_message.py'>) with frequency always
2025-02-13 16:44:21,879 - handlers.py[DEBUG]: start: modules-final/config-final_message: running config-final_message with frequency always
2025-02-13 16:44:21,879 - helpers.py[DEBUG]: Running config-final_message using lock (<cloudinit.helpers.DummyLock object at 0x7f3ee1f5ffa0>)
2025-02-13 16:44:21,879 - util.py[DEBUG]: Reading from /proc/uptime (quiet=False)
2025-02-13 16:44:21,880 - util.py[DEBUG]: Reading 11 bytes from /proc/uptime
2025-02-13 16:44:21,887 - log_util.py[DEBUG]: Cloud-init v. 24.4-0ubuntu1~22.04.1 finished at Thu, 13 Feb 2025 16:44:21 +0000. Datasource DataSourceAkamaiLocal.  Up 13.08 seconds
2025-02-13 16:44:21,887 - util.py[DEBUG]: Writing to /var/lib/cloud/instance/boot-finished - wb: [644] 67 bytes
2025-02-13 16:44:21,887 - handlers.py[DEBUG]: finish: modules-final/config-final_message: SUCCESS: config-final_message ran successfully and took 0.008 seconds
2025-02-13 16:44:21,887 - main.py[DEBUG]: Ran 10 modules with 0 failures
2025-02-13 16:44:21,888 - util.py[DEBUG]: Reading from /proc/uptime (quiet=False)
2025-02-13 16:44:21,888 - util.py[DEBUG]: Reading 11 bytes from /proc/uptime
2025-02-13 16:44:21,888 - atomic_helper.py[DEBUG]: Atomically writing to file /var/lib/cloud/data/status.json (via temporary file /var/lib/cloud/data/tmpfw4dnm5s) - w: [644] 507 bytes/chars
2025-02-13 16:44:21,888 - atomic_helper.py[DEBUG]: Atomically writing to file /var/lib/cloud/data/result.json (via temporary file /var/lib/cloud/data/tmpbilxx07s) - w: [644] 72 bytes/chars
2025-02-13 16:44:21,888 - util.py[DEBUG]: Creating symbolic link from '/run/cloud-init/result.json' => '../../var/lib/cloud/data/result.json'
2025-02-13 16:44:21,888 - performance.py[DEBUG]: cloud-init stage: 'modules-final' took 0.110 seconds
2025-02-13 16:44:21,889 - handlers.py[DEBUG]: finish: modules-final: SUCCESS: running modules for final
2025-02-13 17:06:39,875 - log_util.py[DEBUG]: Cloud-init v. 24.4-0ubuntu1~22.04.1 running 'init-local' at Thu, 13 Feb 2025 17:06:39 +0000. Up 6.03 seconds.
2025-02-13 17:06:39,877 - main.py[INFO]: PID [1] started cloud-init 'init-local'.
2025-02-13 17:06:39,877 - main.py[DEBUG]: No kernel command line url found.
2025-02-13 17:06:39,877 - main.py[DEBUG]: Closing stdin
2025-02-13 17:06:39,880 - util.py[DEBUG]: Writing to /var/log/cloud-init.log - ab: [640] 0 bytes
2025-02-13 17:06:39,881 - util.py[DEBUG]: Changing the ownership of /var/log/cloud-init.log to 104:4
2025-02-13 17:06:39,881 - util.py[DEBUG]: Reading from /var/lib/cloud/data/python-version (quiet=False)
2025-02-13 17:06:39,886 - util.py[DEBUG]: Reading 4 bytes from /var/lib/cloud/data/python-version
2025-02-13 17:06:39,886 - util.py[DEBUG]: Attempting to remove /var/lib/cloud/instance/boot-finished
2025-02-13 17:06:39,886 - handlers.py[DEBUG]: start: init-local/check-cache: attempting to read from cache [check]
2025-02-13 17:06:39,886 - util.py[DEBUG]: Reading from /var/lib/cloud/instance/obj.pkl (quiet=False)
2025-02-13 17:06:39,889 - util.py[DEBUG]: Reading 9372 bytes from /var/lib/cloud/instance/obj.pkl
2025-02-13 17:06:39,897 - dmi.py[DEBUG]: querying dmi data /sys/class/dmi/id/product_serial
2025-02-13 17:06:39,897 - stages.py[DEBUG]: restored from checked cache: DataSourceAkamaiLocal
2025-02-13 17:06:39,897 - handlers.py[DEBUG]: finish: init-local/check-cache: SUCCESS: restored from checked cache: DataSourceAkamaiLocal
2025-02-13 17:06:39,897 - util.py[DEBUG]: Reading from /etc/cloud/cloud.cfg (quiet=False)
2025-02-13 17:06:39,897 - util.py[DEBUG]: Reading 3766 bytes from /etc/cloud/cloud.cfg
2025-02-13 17:06:39,897 - util.py[DEBUG]: Attempting to load yaml from string of length 3766 with allowed root types (<class 'dict'>,)
2025-02-13 17:06:39,922 - util.py[DEBUG]: Reading from /etc/cloud/cloud.cfg.d/99-linode.cfg (quiet=False)
2025-02-13 17:06:39,922 - util.py[DEBUG]: Reading 492 bytes from /etc/cloud/cloud.cfg.d/99-linode.cfg
2025-02-13 17:06:39,922 - util.py[DEBUG]: Attempting to load yaml from string of length 492 with allowed root types (<class 'dict'>,)
2025-02-13 17:06:39,928 - util.py[DEBUG]: Reading from /etc/cloud/cloud.cfg.d/90_dpkg.cfg (quiet=False)
2025-02-13 17:06:39,928 - util.py[DEBUG]: Reading 333 bytes from /etc/cloud/cloud.cfg.d/90_dpkg.cfg
2025-02-13 17:06:39,928 - util.py[DEBUG]: Attempting to load yaml from string of length 333 with allowed root types (<class 'dict'>,)
2025-02-13 17:06:39,930 - util.py[DEBUG]: Reading from /etc/cloud/cloud.cfg.d/05_logging.cfg (quiet=False)
2025-02-13 17:06:39,930 - util.py[DEBUG]: Reading 2071 bytes from /etc/cloud/cloud.cfg.d/05_logging.cfg
2025-02-13 17:06:39,930 - util.py[DEBUG]: Attempting to load yaml from string of length 2071 with allowed root types (<class 'dict'>,)
2025-02-13 17:06:39,938 - util.py[DEBUG]: Reading from /run/cloud-init/cloud.cfg (quiet=False)
2025-02-13 17:06:39,938 - util.py[DEBUG]: Reading 34 bytes from /run/cloud-init/cloud.cfg
2025-02-13 17:06:39,938 - util.py[DEBUG]: Attempting to load yaml from string of length 34 with allowed root types (<class 'dict'>,)
2025-02-13 17:06:39,938 - util.py[DEBUG]: Attempting to load yaml from string of length 0 with allowed root types (<class 'dict'>,)
2025-02-13 17:06:39,938 - util.py[DEBUG]: loaded blob returned None, returning default.
2025-02-13 17:06:39,944 - util.py[DEBUG]: Reading from /var/lib/cloud/instance/cloud-config.txt (quiet=False)
2025-02-13 17:06:39,944 - util.py[DEBUG]: Reading 0 bytes from /var/lib/cloud/instance/cloud-config.txt
2025-02-13 17:06:39,944 - util.py[DEBUG]: Attempting to load yaml from string of length 0 with allowed root types (<class 'dict'>,)
2025-02-13 17:06:39,944 - util.py[DEBUG]: loaded blob returned None, returning default.
2025-02-13 17:06:39,945 - util.py[DEBUG]: Reading from /etc/hosts (quiet=False)
2025-02-13 17:06:39,945 - util.py[DEBUG]: Reading 181 bytes from /etc/hosts
2025-02-13 17:06:39,946 - util.py[DEBUG]: Writing to /run/cloud-init/cloud-id-akamai - wb: [644] 7 bytes
2025-02-13 17:06:39,946 - util.py[DEBUG]: Creating symbolic link from '/run/cloud-init/cloud-id' => '/run/cloud-init/cloud-id-akamai'
2025-02-13 17:06:39,950 - atomic_helper.py[DEBUG]: Atomically writing to file /run/cloud-init/instance-data-sensitive.json (via temporary file /run/cloud-init/tmpi9l3x5dk) - w: [600] 8726 bytes/chars
2025-02-13 17:06:39,950 - atomic_helper.py[DEBUG]: Atomically writing to file /run/cloud-init/instance-data.json (via temporary file /run/cloud-init/tmpspye4iuy) - w: [644] 1941 bytes/chars
2025-02-13 17:06:39,951 - stages.py[INFO]: Instance link already exists, not recreating it.
2025-02-13 17:06:39,951 - util.py[DEBUG]: Reading from /var/lib/cloud/instances/71855604/datasource (quiet=False)
2025-02-13 17:06:39,953 - util.py[DEBUG]: Reading 45 bytes from /var/lib/cloud/instances/71855604/datasource
2025-02-13 17:06:39,953 - util.py[DEBUG]: Writing to /var/lib/cloud/instances/71855604/datasource - wb: [644] 45 bytes
2025-02-13 17:06:39,954 - util.py[DEBUG]: Writing to /var/lib/cloud/data/previous-datasource - wb: [644] 45 bytes
2025-02-13 17:06:39,954 - util.py[DEBUG]: Reading from /var/lib/cloud/data/instance-id (quiet=False)
2025-02-13 17:06:39,955 - util.py[DEBUG]: Reading 9 bytes from /var/lib/cloud/data/instance-id
2025-02-13 17:06:39,955 - stages.py[DEBUG]: previous iid found to be 71855604
2025-02-13 17:06:39,955 - util.py[DEBUG]: Writing to /var/lib/cloud/data/instance-id - wb: [644] 9 bytes
2025-02-13 17:06:39,955 - util.py[DEBUG]: Writing to /run/cloud-init/.instance-id - wb: [644] 9 bytes
2025-02-13 17:06:39,955 - util.py[DEBUG]: Writing to /var/lib/cloud/data/previous-instance-id - wb: [644] 9 bytes
2025-02-13 17:06:39,959 - util.py[DEBUG]: Writing to /var/lib/cloud/instance/obj.pkl - wb: [400] 9381 bytes
2025-02-13 17:06:39,961 - stages.py[INFO]: Not re-loading configuration, instance id and datasource have not changed.
2025-02-13 17:06:39,961 - main.py[DEBUG]: [local] init will now be targeting instance id: 71855604. new=False
2025-02-13 17:06:39,962 - stages.py[DEBUG]: Using distro class <class 'cloudinit.distros.ubuntu.Distro'>
2025-02-13 17:06:39,965 - util.py[DEBUG]: Reading from /sys/class/net/eth0/address (quiet=False)
2025-02-13 17:06:39,965 - util.py[DEBUG]: Reading 18 bytes from /sys/class/net/eth0/address
2025-02-13 17:06:39,965 - util.py[DEBUG]: Reading from /sys/class/net/lo/address (quiet=False)
2025-02-13 17:06:39,965 - util.py[DEBUG]: Reading 18 bytes from /sys/class/net/lo/address
2025-02-13 17:06:39,965 - stages.py[DEBUG]: network config disabled by system_cfg
2025-02-13 17:06:39,965 - stages.py[INFO]: network config is disabled by system_cfg
2025-02-13 17:06:39,965 - main.py[DEBUG]: Network connectivity determined unnecessary for cloud-init's network stage. Reason: user data: no configuration found, vendor data: no configuration found, vendor data2: no configuration found
2025-02-13 17:06:39,965 - util.py[DEBUG]: Writing to /run/cloud-init/.skip-network - wb: [644] 0 bytes
2025-02-13 17:06:39,965 - main.py[DEBUG]: [local] Exiting. datasource DataSourceAkamaiLocal not in local mode.
2025-02-13 17:06:39,966 - util.py[DEBUG]: Reading from /proc/uptime (quiet=False)
2025-02-13 17:06:39,966 - util.py[DEBUG]: Reading 10 bytes from /proc/uptime
2025-02-13 17:06:39,966 - atomic_helper.py[DEBUG]: Atomically writing to file /var/lib/cloud/data/status.json (via temporary file /var/lib/cloud/data/tmptcev90_g) - w: [644] 502 bytes/chars
2025-02-13 17:06:39,966 - performance.py[DEBUG]: cloud-init stage: 'init-local' took 0.217 seconds
2025-02-13 17:06:39,971 - handlers.py[DEBUG]: finish: init-local: SUCCESS: searching for local datasources
2025-02-13 17:06:44,685 - log_util.py[DEBUG]: Cloud-init v. 24.4-0ubuntu1~22.04.1 running 'init' at Thu, 13 Feb 2025 17:06:44 +0000. Up 10.87 seconds.
2025-02-13 17:06:44,685 - main.py[INFO]: PID [1] started cloud-init 'init'.
2025-02-13 17:06:44,685 - main.py[DEBUG]: No kernel command line url found.
2025-02-13 17:06:44,685 - main.py[DEBUG]: Closing stdin
2025-02-13 17:06:44,687 - util.py[DEBUG]: Writing to /var/log/cloud-init.log - ab: [640] 0 bytes
2025-02-13 17:06:44,688 - util.py[DEBUG]: Changing the ownership of /var/log/cloud-init.log to 104:4
2025-02-13 17:06:44,688 - util.py[DEBUG]: Reading from /var/lib/cloud/data/python-version (quiet=False)
2025-02-13 17:06:44,688 - util.py[DEBUG]: Reading 4 bytes from /var/lib/cloud/data/python-version
2025-02-13 17:06:44,688 - subp.py[DEBUG]: Running command ['ip', '--json', 'addr'] with allowed return codes [0] (shell=False, capture=True)
2025-02-13 17:06:44,701 - performance.py[DEBUG]: Running ['ip', '--json', 'addr'] took 0.012 seconds
2025-02-13 17:06:44,701 - subp.py[DEBUG]: Running command ['ip', '-o', 'route', 'list'] with allowed return codes [0] (shell=False, capture=True)
2025-02-13 17:06:44,703 - subp.py[DEBUG]: Running command ['ip', '--oneline', '-6', 'route', 'list', 'table', 'all'] with allowed return codes [0, 1] (shell=False, capture=True)
2025-02-13 17:06:44,706 - handlers.py[DEBUG]: start: init-network/check-cache: attempting to read from cache [trust]
2025-02-13 17:06:44,706 - util.py[DEBUG]: Reading from /var/lib/cloud/instance/obj.pkl (quiet=False)
2025-02-13 17:06:44,706 - util.py[DEBUG]: Reading 9381 bytes from /var/lib/cloud/instance/obj.pkl
2025-02-13 17:06:44,714 - util.py[DEBUG]: Reading from /run/cloud-init/.instance-id (quiet=False)
2025-02-13 17:06:44,714 - util.py[DEBUG]: Reading 9 bytes from /run/cloud-init/.instance-id
2025-02-13 17:06:44,714 - stages.py[DEBUG]: restored from cache with run check: DataSourceAkamaiLocal
2025-02-13 17:06:44,714 - handlers.py[DEBUG]: finish: init-network/check-cache: SUCCESS: restored from cache with run check: DataSourceAkamaiLocal
2025-02-13 17:06:44,719 - util.py[DEBUG]: Reading from /etc/cloud/cloud.cfg (quiet=False)
2025-02-13 17:06:44,719 - util.py[DEBUG]: Reading 3766 bytes from /etc/cloud/cloud.cfg
2025-02-13 17:06:44,719 - util.py[DEBUG]: Attempting to load yaml from string of length 3766 with allowed root types (<class 'dict'>,)
2025-02-13 17:06:44,745 - util.py[DEBUG]: Reading from /etc/cloud/cloud.cfg.d/99-linode.cfg (quiet=False)
2025-02-13 17:06:44,745 - util.py[DEBUG]: Reading 492 bytes from /etc/cloud/cloud.cfg.d/99-linode.cfg
2025-02-13 17:06:44,745 - util.py[DEBUG]: Attempting to load yaml from string of length 492 with allowed root types (<class 'dict'>,)
2025-02-13 17:06:44,751 - util.py[DEBUG]: Reading from /etc/cloud/cloud.cfg.d/90_dpkg.cfg (quiet=False)
2025-02-13 17:06:44,751 - util.py[DEBUG]: Reading 333 bytes from /etc/cloud/cloud.cfg.d/90_dpkg.cfg
2025-02-13 17:06:44,751 - util.py[DEBUG]: Attempting to load yaml from string of length 333 with allowed root types (<class 'dict'>,)
2025-02-13 17:06:44,753 - util.py[DEBUG]: Reading from /etc/cloud/cloud.cfg.d/05_logging.cfg (quiet=False)
2025-02-13 17:06:44,754 - util.py[DEBUG]: Reading 2071 bytes from /etc/cloud/cloud.cfg.d/05_logging.cfg
2025-02-13 17:06:44,754 - util.py[DEBUG]: Attempting to load yaml from string of length 2071 with allowed root types (<class 'dict'>,)
2025-02-13 17:06:44,765 - util.py[DEBUG]: Reading from /run/cloud-init/cloud.cfg (quiet=False)
2025-02-13 17:06:44,765 - util.py[DEBUG]: Reading 34 bytes from /run/cloud-init/cloud.cfg
2025-02-13 17:06:44,765 - util.py[DEBUG]: Attempting to load yaml from string of length 34 with allowed root types (<class 'dict'>,)
2025-02-13 17:06:44,766 - util.py[DEBUG]: Attempting to load yaml from string of length 0 with allowed root types (<class 'dict'>,)
2025-02-13 17:06:44,766 - util.py[DEBUG]: loaded blob returned None, returning default.
2025-02-13 17:06:44,766 - util.py[DEBUG]: Reading from /var/lib/cloud/instance/cloud-config.txt (quiet=False)
2025-02-13 17:06:44,766 - util.py[DEBUG]: Reading 0 bytes from /var/lib/cloud/instance/cloud-config.txt
2025-02-13 17:06:44,766 - util.py[DEBUG]: Attempting to load yaml from string of length 0 with allowed root types (<class 'dict'>,)
2025-02-13 17:06:44,769 - util.py[DEBUG]: loaded blob returned None, returning default.
2025-02-13 17:06:44,769 - stages.py[INFO]: Instance link already exists, not recreating it.
2025-02-13 17:06:44,770 - util.py[DEBUG]: Reading from /var/lib/cloud/instances/71855604/datasource (quiet=False)
2025-02-13 17:06:44,770 - util.py[DEBUG]: Reading 45 bytes from /var/lib/cloud/instances/71855604/datasource
2025-02-13 17:06:44,770 - util.py[DEBUG]: Writing to /var/lib/cloud/instances/71855604/datasource - wb: [644] 45 bytes
2025-02-13 17:06:44,770 - util.py[DEBUG]: Writing to /var/lib/cloud/data/previous-datasource - wb: [644] 45 bytes
2025-02-13 17:06:44,772 - util.py[DEBUG]: Reading from /var/lib/cloud/data/instance-id (quiet=False)
2025-02-13 17:06:44,773 - util.py[DEBUG]: Reading 9 bytes from /var/lib/cloud/data/instance-id
2025-02-13 17:06:44,773 - stages.py[DEBUG]: previous iid found to be 71855604
2025-02-13 17:06:44,773 - util.py[DEBUG]: Writing to /var/lib/cloud/data/instance-id - wb: [644] 9 bytes
2025-02-13 17:06:44,775 - util.py[DEBUG]: Writing to /run/cloud-init/.instance-id - wb: [644] 9 bytes
2025-02-13 17:06:44,775 - util.py[DEBUG]: Writing to /var/lib/cloud/data/previous-instance-id - wb: [644] 9 bytes
2025-02-13 17:06:44,776 - util.py[DEBUG]: Writing to /var/lib/cloud/instance/obj.pkl - wb: [400] 9381 bytes
2025-02-13 17:06:44,778 - stages.py[INFO]: Not re-loading configuration, instance id and datasource have not changed.
2025-02-13 17:06:44,778 - main.py[DEBUG]: [net] init will now be targeting instance id: 71855604. new=False
2025-02-13 17:06:44,779 - util.py[DEBUG]: Reading from /sys/class/net/eth0/address (quiet=False)
2025-02-13 17:06:44,779 - util.py[DEBUG]: Reading 18 bytes from /sys/class/net/eth0/address
2025-02-13 17:06:44,779 - util.py[DEBUG]: Reading from /sys/class/net/lo/address (quiet=False)
2025-02-13 17:06:44,779 - util.py[DEBUG]: Reading 18 bytes from /sys/class/net/lo/address
2025-02-13 17:06:44,779 - stages.py[DEBUG]: network config disabled by system_cfg
2025-02-13 17:06:44,780 - stages.py[INFO]: network config is disabled by system_cfg
2025-02-13 17:06:44,780 - handlers.py[DEBUG]: start: init-network/setup-datasource: setting up datasource
2025-02-13 17:06:44,780 - handlers.py[DEBUG]: finish: init-network/setup-datasource: SUCCESS: setting up datasource
2025-02-13 17:06:44,780 - util.py[DEBUG]: Writing to /var/lib/cloud/instances/71855604/user-data.txt - wb: [600] 0 bytes
2025-02-13 17:06:44,780 - util.py[DEBUG]: Writing to /var/lib/cloud/instances/71855604/user-data.txt.i - wb: [600] 308 bytes
2025-02-13 17:06:44,784 - util.py[DEBUG]: Writing to /var/lib/cloud/instances/71855604/vendor-data.txt - wb: [600] 0 bytes
2025-02-13 17:06:44,784 - util.py[DEBUG]: Writing to /var/lib/cloud/instances/71855604/vendor-data.txt.i - wb: [600] 308 bytes
2025-02-13 17:06:44,785 - util.py[DEBUG]: Writing to /var/lib/cloud/instances/71855604/vendor-data2.txt - wb: [600] 0 bytes
2025-02-13 17:06:44,785 - util.py[DEBUG]: Writing to /var/lib/cloud/instances/71855604/vendor-data2.txt.i - wb: [600] 308 bytes
2025-02-13 17:06:44,788 - stages.py[DEBUG]: Using distro class <class 'cloudinit.distros.ubuntu.Distro'>
2025-02-13 17:06:44,790 - helpers.py[DEBUG]: consume_data already ran (freq=once-per-instance)
2025-02-13 17:06:44,790 - handlers.py[DEBUG]: start: init-network/consume-user-data: reading and applying user-data
2025-02-13 17:06:44,793 - stages.py[DEBUG]: Added default handler for {'text/cloud-config-jsonp', 'text/cloud-config'} from CloudConfigPartHandler: [['text/cloud-config', 'text/cloud-config-jsonp']]
2025-02-13 17:06:44,793 - stages.py[DEBUG]: Added default handler for {'text/x-shellscript'} from ShellScriptPartHandler: [['text/x-shellscript']]
2025-02-13 17:06:44,793 - stages.py[DEBUG]: Added default handler for {'text/x-shellscript-per-boot'} from ShellScriptByFreqPartHandler: [['text/x-shellscript-per-boot']]
2025-02-13 17:06:44,793 - stages.py[DEBUG]: Added default handler for {'text/x-shellscript-per-instance'} from ShellScriptByFreqPartHandler: [['text/x-shellscript-per-instance']]
2025-02-13 17:06:44,793 - stages.py[DEBUG]: Added default handler for {'text/x-shellscript-per-once'} from ShellScriptByFreqPartHandler: [['text/x-shellscript-per-once']]
2025-02-13 17:06:44,793 - stages.py[DEBUG]: Added default handler for {'text/cloud-boothook'} from BootHookPartHandler: [['text/cloud-boothook']]
2025-02-13 17:06:44,793 - stages.py[DEBUG]: Added default handler for {'text/jinja2'} from JinjaTemplatePartHandler: [['text/jinja2']]
2025-02-13 17:06:44,793 - handlers[DEBUG]: Calling handler CloudConfigPartHandler: [['text/cloud-config', 'text/cloud-config-jsonp']] (__begin__, None, 3) with frequency always
2025-02-13 17:06:44,793 - handlers[DEBUG]: Calling handler ShellScriptPartHandler: [['text/x-shellscript']] (__begin__, None, 2) with frequency always
2025-02-13 17:06:44,793 - handlers[DEBUG]: Calling handler ShellScriptByFreqPartHandler: [['text/x-shellscript-per-boot']] (__begin__, None, 2) with frequency always
2025-02-13 17:06:44,793 - handlers[DEBUG]: Calling handler ShellScriptByFreqPartHandler: [['text/x-shellscript-per-instance']] (__begin__, None, 2) with frequency always
2025-02-13 17:06:44,793 - handlers[DEBUG]: Calling handler ShellScriptByFreqPartHandler: [['text/x-shellscript-per-once']] (__begin__, None, 2) with frequency always
2025-02-13 17:06:44,793 - handlers[DEBUG]: Calling handler BootHookPartHandler: [['text/cloud-boothook']] (__begin__, None, 2) with frequency always
2025-02-13 17:06:44,793 - handlers[DEBUG]: Calling handler JinjaTemplatePartHandler: [['text/jinja2']] (__begin__, None, 3) with frequency always
2025-02-13 17:06:44,793 - handlers[DEBUG]: {'MIME-Version': '1.0', 'Content-Type': 'text/x-not-multipart', 'Content-Disposition': 'attachment; filename="part-001"'}
2025-02-13 17:06:44,793 - handlers[DEBUG]: Empty payload of type text/x-not-multipart
2025-02-13 17:06:44,794 - handlers[DEBUG]: Calling handler CloudConfigPartHandler: [['text/cloud-config', 'text/cloud-config-jsonp']] (__end__, None, 3) with frequency always
2025-02-13 17:06:44,794 - util.py[DEBUG]: Writing to /var/lib/cloud/instances/71855604/cloud-config.txt - wb: [600] 0 bytes
2025-02-13 17:06:44,796 - handlers[DEBUG]: Calling handler ShellScriptPartHandler: [['text/x-shellscript']] (__end__, None, 2) with frequency always
2025-02-13 17:06:44,796 - handlers[DEBUG]: Calling handler ShellScriptByFreqPartHandler: [['text/x-shellscript-per-boot']] (__end__, None, 2) with frequency always
2025-02-13 17:06:44,796 - handlers[DEBUG]: Calling handler ShellScriptByFreqPartHandler: [['text/x-shellscript-per-instance']] (__end__, None, 2) with frequency always
2025-02-13 17:06:44,796 - handlers[DEBUG]: Calling handler ShellScriptByFreqPartHandler: [['text/x-shellscript-per-once']] (__end__, None, 2) with frequency always
2025-02-13 17:06:44,796 - handlers[DEBUG]: Calling handler BootHookPartHandler: [['text/cloud-boothook']] (__end__, None, 2) with frequency always
2025-02-13 17:06:44,796 - handlers[DEBUG]: Calling handler JinjaTemplatePartHandler: [['text/jinja2']] (__end__, None, 3) with frequency always
2025-02-13 17:06:44,796 - handlers.py[DEBUG]: finish: init-network/consume-user-data: SUCCESS: reading and applying user-data
2025-02-13 17:06:44,796 - handlers.py[DEBUG]: start: init-network/consume-vendor-data: reading and applying vendor-data
2025-02-13 17:06:44,796 - stages.py[DEBUG]: no vendordata from datasource
2025-02-13 17:06:44,796 - handlers.py[DEBUG]: finish: init-network/consume-vendor-data: SUCCESS: reading and applying vendor-data
2025-02-13 17:06:44,796 - handlers.py[DEBUG]: start: init-network/consume-vendor-data2: reading and applying vendor-data2
2025-02-13 17:06:44,796 - stages.py[DEBUG]: no vendordata2 from datasource
2025-02-13 17:06:44,796 - handlers.py[DEBUG]: finish: init-network/consume-vendor-data2: SUCCESS: reading and applying vendor-data2
2025-02-13 17:06:44,796 - util.py[DEBUG]: Reading from /etc/cloud/cloud.cfg (quiet=False)
2025-02-13 17:06:44,796 - util.py[DEBUG]: Reading 3766 bytes from /etc/cloud/cloud.cfg
2025-02-13 17:06:44,797 - util.py[DEBUG]: Attempting to load yaml from string of length 3766 with allowed root types (<class 'dict'>,)
2025-02-13 17:06:44,811 - util.py[DEBUG]: Reading from /etc/cloud/cloud.cfg.d/99-linode.cfg (quiet=False)
2025-02-13 17:06:44,811 - util.py[DEBUG]: Reading 492 bytes from /etc/cloud/cloud.cfg.d/99-linode.cfg
2025-02-13 17:06:44,811 - util.py[DEBUG]: Attempting to load yaml from string of length 492 with allowed root types (<class 'dict'>,)
2025-02-13 17:06:44,813 - util.py[DEBUG]: Reading from /etc/cloud/cloud.cfg.d/90_dpkg.cfg (quiet=False)
2025-02-13 17:06:44,813 - util.py[DEBUG]: Reading 333 bytes from /etc/cloud/cloud.cfg.d/90_dpkg.cfg
2025-02-13 17:06:44,813 - util.py[DEBUG]: Attempting to load yaml from string of length 333 with allowed root types (<class 'dict'>,)
2025-02-13 17:06:44,815 - util.py[DEBUG]: Reading from /etc/cloud/cloud.cfg.d/05_logging.cfg (quiet=False)
2025-02-13 17:06:44,815 - util.py[DEBUG]: Reading 2071 bytes from /etc/cloud/cloud.cfg.d/05_logging.cfg
2025-02-13 17:06:44,815 - util.py[DEBUG]: Attempting to load yaml from string of length 2071 with allowed root types (<class 'dict'>,)
2025-02-13 17:06:44,819 - util.py[DEBUG]: Reading from /run/cloud-init/cloud.cfg (quiet=False)
2025-02-13 17:06:44,819 - util.py[DEBUG]: Reading 34 bytes from /run/cloud-init/cloud.cfg
2025-02-13 17:06:44,819 - util.py[DEBUG]: Attempting to load yaml from string of length 34 with allowed root types (<class 'dict'>,)
2025-02-13 17:06:44,820 - util.py[DEBUG]: Attempting to load yaml from string of length 0 with allowed root types (<class 'dict'>,)
2025-02-13 17:06:44,820 - util.py[DEBUG]: loaded blob returned None, returning default.
2025-02-13 17:06:44,820 - util.py[DEBUG]: Reading from /var/lib/cloud/instance/cloud-config.txt (quiet=False)
2025-02-13 17:06:44,820 - util.py[DEBUG]: Reading 0 bytes from /var/lib/cloud/instance/cloud-config.txt
2025-02-13 17:06:44,820 - util.py[DEBUG]: Attempting to load yaml from string of length 0 with allowed root types (<class 'dict'>,)
2025-02-13 17:06:44,821 - util.py[DEBUG]: loaded blob returned None, returning default.
2025-02-13 17:06:44,822 - atomic_helper.py[DEBUG]: Atomically writing to file /run/cloud-init/combined-cloud-config.json (via temporary file /run/cloud-init/tmppxsv1fu0) - w: [600] 5471 bytes/chars
2025-02-13 17:06:44,822 - util.py[DEBUG]: Reading from /run/cloud-init/instance-data-sensitive.json (quiet=False)
2025-02-13 17:06:44,822 - util.py[DEBUG]: Reading 8726 bytes from /run/cloud-init/instance-data-sensitive.json
2025-02-13 17:06:44,823 - atomic_helper.py[DEBUG]: Atomically writing to file /run/cloud-init/instance-data-sensitive.json (via temporary file /run/cloud-init/tmpkafbkybg) - w: [600] 10709 bytes/chars
2025-02-13 17:06:44,823 - main.py[DEBUG]: Skipping user-data validation. No user-data found.
2025-02-13 17:06:44,823 - util.py[DEBUG]: Reading from /var/lib/cloud/instance/cloud-config.txt (quiet=False)
2025-02-13 17:06:44,823 - util.py[DEBUG]: Reading 0 bytes from /var/lib/cloud/instance/cloud-config.txt
2025-02-13 17:06:44,823 - util.py[DEBUG]: Attempting to load yaml from string of length 0 with allowed root types (<class 'dict'>,)
2025-02-13 17:06:44,823 - util.py[DEBUG]: loaded blob returned None, returning default.
2025-02-13 17:06:44,826 - handlers.py[DEBUG]: start: init-network/activate-datasource: activating datasource
2025-02-13 17:06:44,827 - util.py[DEBUG]: Writing to /var/lib/cloud/instance/obj.pkl - wb: [400] 9372 bytes
2025-02-13 17:06:44,827 - handlers.py[DEBUG]: finish: init-network/activate-datasource: SUCCESS: activating datasource
2025-02-13 17:06:44,827 - main.py[DEBUG]: no di_report found in config.
2025-02-13 17:06:44,841 - stages.py[DEBUG]: Using distro class <class 'cloudinit.distros.ubuntu.Distro'>
2025-02-13 17:06:44,843 - modules.py[INFO]: Skipping modules 'bootcmd,write_files,disk_setup,update_etc_hosts,ca_certs,rsyslog' because no applicable config is provided.
2025-02-13 17:06:44,843 - modules.py[DEBUG]: Running module seed_random (<module 'cloudinit.config.cc_seed_random' from '/usr/lib/python3/dist-packages/cloudinit/config/cc_seed_random.py'>) with frequency once-per-instance
2025-02-13 17:06:44,844 - handlers.py[DEBUG]: start: init-network/config-seed_random: running config-seed_random with frequency once-per-instance
2025-02-13 17:06:44,844 - helpers.py[DEBUG]: config-seed_random already ran (freq=once-per-instance)
2025-02-13 17:06:44,844 - handlers.py[DEBUG]: finish: init-network/config-seed_random: SUCCESS: config-seed_random previously ran
2025-02-13 17:06:44,844 - modules.py[DEBUG]: Running module growpart (<module 'cloudinit.config.cc_growpart' from '/usr/lib/python3/dist-packages/cloudinit/config/cc_growpart.py'>) with frequency always
2025-02-13 17:06:44,844 - handlers.py[DEBUG]: start: init-network/config-growpart: running config-growpart with frequency always
2025-02-13 17:06:44,844 - helpers.py[DEBUG]: Running config-growpart using lock (<cloudinit.helpers.DummyLock object at 0x7f3f743ccee0>)
2025-02-13 17:06:44,844 - cc_growpart.py[DEBUG]: No 'growpart' entry in cfg.  Using default: {'mode': 'auto', 'devices': ['/'], 'ignore_growroot_disabled': False}
2025-02-13 17:06:44,844 - subp.py[DEBUG]: Running command ['growpart', '--help'] with allowed return codes [0] (shell=False, capture=True)
2025-02-13 17:06:44,848 - util.py[DEBUG]: Reading from /proc/629/mountinfo (quiet=False)
2025-02-13 17:06:44,848 - util.py[DEBUG]: Reading 2056 bytes from /proc/629/mountinfo
2025-02-13 17:06:44,848 - cc_growpart.py[DEBUG]: growpart found fs=ext4
2025-02-13 17:06:44,848 - cc_growpart.py[DEBUG]: '/' SKIPPED: device_part_info(/dev/sda) failed: /dev/sda not a partition
2025-02-13 17:06:44,848 - handlers.py[DEBUG]: finish: init-network/config-growpart: SUCCESS: config-growpart ran successfully and took 0.004 seconds
2025-02-13 17:06:44,848 - modules.py[DEBUG]: Running module resizefs (<module 'cloudinit.config.cc_resizefs' from '/usr/lib/python3/dist-packages/cloudinit/config/cc_resizefs.py'>) with frequency always
2025-02-13 17:06:44,848 - handlers.py[DEBUG]: start: init-network/config-resizefs: running config-resizefs with frequency always
2025-02-13 17:06:44,848 - helpers.py[DEBUG]: Running config-resizefs using lock (<cloudinit.helpers.DummyLock object at 0x7f3f743cdae0>)
2025-02-13 17:06:44,849 - util.py[DEBUG]: Reading from /proc/629/mountinfo (quiet=False)
2025-02-13 17:06:44,849 - util.py[DEBUG]: Reading 2056 bytes from /proc/629/mountinfo
2025-02-13 17:06:44,849 - cc_resizefs.py[DEBUG]: resize_info: dev=/dev/sda mnt_point=/ path=/
2025-02-13 17:06:44,849 - cc_resizefs.py[DEBUG]: Resizing / (ext4) using resize2fs /dev/sda
2025-02-13 17:06:44,849 - subp.py[DEBUG]: Running command ('resize2fs', '/dev/sda') with allowed return codes [0] (shell=False, capture=True)
2025-02-13 17:06:44,864 - performance.py[DEBUG]: Running ('resize2fs', '/dev/sda') took 0.015 seconds
2025-02-13 17:06:44,864 - cc_resizefs.py[DEBUG]: Resized root filesystem (type=ext4, val=True)
2025-02-13 17:06:44,864 - handlers.py[DEBUG]: finish: init-network/config-resizefs: SUCCESS: config-resizefs ran successfully and took 0.016 seconds
2025-02-13 17:06:44,865 - modules.py[DEBUG]: Running module mounts (<module 'cloudinit.config.cc_mounts' from '/usr/lib/python3/dist-packages/cloudinit/config/cc_mounts.py'>) with frequency once-per-instance
2025-02-13 17:06:44,865 - handlers.py[DEBUG]: start: init-network/config-mounts: running config-mounts with frequency once-per-instance
2025-02-13 17:06:44,865 - helpers.py[DEBUG]: config-mounts already ran (freq=once-per-instance)
2025-02-13 17:06:44,865 - handlers.py[DEBUG]: finish: init-network/config-mounts: SUCCESS: config-mounts previously ran
2025-02-13 17:06:44,865 - modules.py[DEBUG]: Running module set_hostname (<module 'cloudinit.config.cc_set_hostname' from '/usr/lib/python3/dist-packages/cloudinit/config/cc_set_hostname.py'>) with frequency once-per-instance
2025-02-13 17:06:44,866 - handlers.py[DEBUG]: start: init-network/config-set_hostname: running config-set_hostname with frequency once-per-instance
2025-02-13 17:06:44,866 - helpers.py[DEBUG]: config-set_hostname already ran (freq=once-per-instance)
2025-02-13 17:06:44,866 - handlers.py[DEBUG]: finish: init-network/config-set_hostname: SUCCESS: config-set_hostname previously ran
2025-02-13 17:06:44,866 - modules.py[DEBUG]: Running module update_hostname (<module 'cloudinit.config.cc_update_hostname' from '/usr/lib/python3/dist-packages/cloudinit/config/cc_update_hostname.py'>) with frequency always
2025-02-13 17:06:44,866 - handlers.py[DEBUG]: start: init-network/config-update_hostname: running config-update_hostname with frequency always
2025-02-13 17:06:44,866 - helpers.py[DEBUG]: Running config-update_hostname using lock (<cloudinit.helpers.DummyLock object at 0x7f3f743cf040>)
2025-02-13 17:06:44,866 - util.py[DEBUG]: Reading from /etc/hosts (quiet=False)
2025-02-13 17:06:44,866 - util.py[DEBUG]: Reading 181 bytes from /etc/hosts
2025-02-13 17:06:44,866 - util.py[DEBUG]: Reading from /etc/hosts (quiet=False)
2025-02-13 17:06:44,866 - util.py[DEBUG]: Reading 181 bytes from /etc/hosts
2025-02-13 17:06:44,866 - cc_update_hostname.py[DEBUG]: Hostname is localhost. Let other services handle this.
2025-02-13 17:06:44,866 - handlers.py[DEBUG]: finish: init-network/config-update_hostname: SUCCESS: config-update_hostname ran successfully and took 0.000 seconds
2025-02-13 17:06:44,866 - modules.py[DEBUG]: Running module users_groups (<module 'cloudinit.config.cc_users_groups' from '/usr/lib/python3/dist-packages/cloudinit/config/cc_users_groups.py'>) with frequency once-per-instance
2025-02-13 17:06:44,867 - handlers.py[DEBUG]: start: init-network/config-users_groups: running config-users_groups with frequency once-per-instance
2025-02-13 17:06:44,867 - helpers.py[DEBUG]: config-users_groups already ran (freq=once-per-instance)
2025-02-13 17:06:44,867 - handlers.py[DEBUG]: finish: init-network/config-users_groups: SUCCESS: config-users_groups previously ran
2025-02-13 17:06:44,867 - modules.py[DEBUG]: Running module ssh (<module 'cloudinit.config.cc_ssh' from '/usr/lib/python3/dist-packages/cloudinit/config/cc_ssh.py'>) with frequency once-per-instance
2025-02-13 17:06:44,867 - handlers.py[DEBUG]: start: init-network/config-ssh: running config-ssh with frequency once-per-instance
2025-02-13 17:06:44,868 - helpers.py[DEBUG]: config-ssh already ran (freq=once-per-instance)
2025-02-13 17:06:44,868 - handlers.py[DEBUG]: finish: init-network/config-ssh: SUCCESS: config-ssh previously ran
2025-02-13 17:06:44,868 - modules.py[DEBUG]: Running module set_passwords (<module 'cloudinit.config.cc_set_passwords' from '/usr/lib/python3/dist-packages/cloudinit/config/cc_set_passwords.py'>) with frequency once-per-instance
2025-02-13 17:06:44,868 - handlers.py[DEBUG]: start: init-network/config-set_passwords: running config-set_passwords with frequency once-per-instance
2025-02-13 17:06:44,868 - helpers.py[DEBUG]: config-set_passwords already ran (freq=once-per-instance)
2025-02-13 17:06:44,868 - handlers.py[DEBUG]: finish: init-network/config-set_passwords: SUCCESS: config-set_passwords previously ran
2025-02-13 17:06:44,868 - main.py[DEBUG]: Ran 9 modules with 0 failures
2025-02-13 17:06:44,868 - util.py[DEBUG]: Reading from /proc/uptime (quiet=False)
2025-02-13 17:06:44,868 - util.py[DEBUG]: Reading 11 bytes from /proc/uptime
2025-02-13 17:06:44,868 - atomic_helper.py[DEBUG]: Atomically writing to file /var/lib/cloud/data/status.json (via temporary file /var/lib/cloud/data/tmp400a67ed) - w: [644] 504 bytes/chars
2025-02-13 17:06:44,869 - performance.py[DEBUG]: cloud-init stage: 'init-network' took 0.247 seconds
2025-02-13 17:06:44,870 - handlers.py[DEBUG]: finish: init-network: SUCCESS: searching for network datasources
2025-02-13 17:06:46,487 - log_util.py[DEBUG]: Cloud-init v. 24.4-0ubuntu1~22.04.1 running 'modules:config' at Thu, 13 Feb 2025 17:06:46 +0000. Up 12.51 seconds.
2025-02-13 17:06:46,487 - main.py[INFO]: PID [1] started cloud-init 'modules:config'.
2025-02-13 17:06:46,504 - stages.py[DEBUG]: Using distro class <class 'cloudinit.distros.ubuntu.Distro'>
2025-02-13 17:06:46,506 - modules.py[INFO]: Skipping modules 'wireguard,snap,ubuntu_autoinstall,keyboard,apt_pipelining,ubuntu_pro,ntp,timezone,disable_ec2_metadata,runcmd' because no applicable config is provided.
2025-02-13 17:06:46,511 - modules.py[DEBUG]: Running module ssh_import_id (<module 'cloudinit.config.cc_ssh_import_id' from '/usr/lib/python3/dist-packages/cloudinit/config/cc_ssh_import_id.py'>) with frequency once-per-instance
2025-02-13 17:06:46,511 - handlers.py[DEBUG]: start: modules-config/config-ssh_import_id: running config-ssh_import_id with frequency once-per-instance
2025-02-13 17:06:46,511 - helpers.py[DEBUG]: config-ssh_import_id already ran (freq=once-per-instance)
2025-02-13 17:06:46,511 - handlers.py[DEBUG]: finish: modules-config/config-ssh_import_id: SUCCESS: config-ssh_import_id previously ran
2025-02-13 17:06:46,511 - modules.py[DEBUG]: Running module locale (<module 'cloudinit.config.cc_locale' from '/usr/lib/python3/dist-packages/cloudinit/config/cc_locale.py'>) with frequency once-per-instance
2025-02-13 17:06:46,511 - handlers.py[DEBUG]: start: modules-config/config-locale: running config-locale with frequency once-per-instance
2025-02-13 17:06:46,511 - helpers.py[DEBUG]: config-locale already ran (freq=once-per-instance)
2025-02-13 17:06:46,511 - handlers.py[DEBUG]: finish: modules-config/config-locale: SUCCESS: config-locale previously ran
2025-02-13 17:06:46,512 - modules.py[DEBUG]: Running module grub_dpkg (<module 'cloudinit.config.cc_grub_dpkg' from '/usr/lib/python3/dist-packages/cloudinit/config/cc_grub_dpkg.py'>) with frequency once-per-instance
2025-02-13 17:06:46,512 - handlers.py[DEBUG]: start: modules-config/config-grub_dpkg: running config-grub_dpkg with frequency once-per-instance
2025-02-13 17:06:46,512 - helpers.py[DEBUG]: config-grub_dpkg already ran (freq=once-per-instance)
2025-02-13 17:06:46,512 - handlers.py[DEBUG]: finish: modules-config/config-grub_dpkg: SUCCESS: config-grub_dpkg previously ran
2025-02-13 17:06:46,512 - modules.py[DEBUG]: Running module apt_configure (<module 'cloudinit.config.cc_apt_configure' from '/usr/lib/python3/dist-packages/cloudinit/config/cc_apt_configure.py'>) with frequency once-per-instance
2025-02-13 17:06:46,512 - handlers.py[DEBUG]: start: modules-config/config-apt_configure: running config-apt_configure with frequency once-per-instance
2025-02-13 17:06:46,512 - helpers.py[DEBUG]: config-apt_configure already ran (freq=once-per-instance)
2025-02-13 17:06:46,512 - handlers.py[DEBUG]: finish: modules-config/config-apt_configure: SUCCESS: config-apt_configure previously ran
2025-02-13 17:06:46,512 - modules.py[DEBUG]: Running module byobu (<module 'cloudinit.config.cc_byobu' from '/usr/lib/python3/dist-packages/cloudinit/config/cc_byobu.py'>) with frequency once-per-instance
2025-02-13 17:06:46,512 - handlers.py[DEBUG]: start: modules-config/config-byobu: running config-byobu with frequency once-per-instance
2025-02-13 17:06:46,513 - helpers.py[DEBUG]: config-byobu already ran (freq=once-per-instance)
2025-02-13 17:06:46,513 - handlers.py[DEBUG]: finish: modules-config/config-byobu: SUCCESS: config-byobu previously ran
2025-02-13 17:06:46,513 - main.py[DEBUG]: Ran 5 modules with 0 failures
2025-02-13 17:06:46,513 - util.py[DEBUG]: Reading from /proc/uptime (quiet=False)
2025-02-13 17:06:46,513 - util.py[DEBUG]: Reading 11 bytes from /proc/uptime
2025-02-13 17:06:46,513 - atomic_helper.py[DEBUG]: Atomically writing to file /var/lib/cloud/data/status.json (via temporary file /var/lib/cloud/data/tmpy61il9v5) - w: [644] 506 bytes/chars
2025-02-13 17:06:46,513 - performance.py[DEBUG]: cloud-init stage: 'modules-config' took 0.320 seconds
2025-02-13 17:06:46,515 - handlers.py[DEBUG]: finish: modules-config: SUCCESS: running modules for config
2025-02-13 17:06:46,974 - log_util.py[DEBUG]: Cloud-init v. 24.4-0ubuntu1~22.04.1 running 'modules:final' at Thu, 13 Feb 2025 17:06:46 +0000. Up 13.13 seconds.
2025-02-13 17:06:46,974 - main.py[INFO]: PID [1] started cloud-init 'modules:final'.
2025-02-13 17:06:46,998 - stages.py[DEBUG]: Using distro class <class 'cloudinit.distros.ubuntu.Distro'>
2025-02-13 17:06:47,000 - modules.py[INFO]: Skipping modules 'package_update_upgrade_install,fan,landscape,lxd,ubuntu_drivers,write_files_deferred,puppet,chef,ansible,mcollective,salt_minion,phone_home,power_state_change' because no applicable config is provided.
2025-02-13 17:06:47,000 - modules.py[DEBUG]: Running module reset_rmc (<module 'cloudinit.config.cc_reset_rmc' from '/usr/lib/python3/dist-packages/cloudinit/config/cc_reset_rmc.py'>) with frequency once-per-instance
2025-02-13 17:06:47,001 - handlers.py[DEBUG]: start: modules-final/config-reset_rmc: running config-reset_rmc with frequency once-per-instance
2025-02-13 17:06:47,001 - helpers.py[DEBUG]: config-reset_rmc already ran (freq=once-per-instance)
2025-02-13 17:06:47,001 - handlers.py[DEBUG]: finish: modules-final/config-reset_rmc: SUCCESS: config-reset_rmc previously ran
2025-02-13 17:06:47,001 - modules.py[DEBUG]: Running module scripts_vendor (<module 'cloudinit.config.cc_scripts_vendor' from '/usr/lib/python3/dist-packages/cloudinit/config/cc_scripts_vendor.py'>) with frequency once-per-instance
2025-02-13 17:06:47,001 - handlers.py[DEBUG]: start: modules-final/config-scripts_vendor: running config-scripts_vendor with frequency once-per-instance
2025-02-13 17:06:47,001 - helpers.py[DEBUG]: config-scripts_vendor already ran (freq=once-per-instance)
2025-02-13 17:06:47,001 - handlers.py[DEBUG]: finish: modules-final/config-scripts_vendor: SUCCESS: config-scripts_vendor previously ran
2025-02-13 17:06:47,001 - modules.py[DEBUG]: Running module scripts_per_once (<module 'cloudinit.config.cc_scripts_per_once' from '/usr/lib/python3/dist-packages/cloudinit/config/cc_scripts_per_once.py'>) with frequency once
2025-02-13 17:06:47,001 - handlers.py[DEBUG]: start: modules-final/config-scripts_per_once: running config-scripts_per_once with frequency once
2025-02-13 17:06:47,002 - helpers.py[DEBUG]: config-scripts_per_once already ran (freq=once)
2025-02-13 17:06:47,002 - handlers.py[DEBUG]: finish: modules-final/config-scripts_per_once: SUCCESS: config-scripts_per_once previously ran
2025-02-13 17:06:47,002 - modules.py[DEBUG]: Running module scripts_per_boot (<module 'cloudinit.config.cc_scripts_per_boot' from '/usr/lib/python3/dist-packages/cloudinit/config/cc_scripts_per_boot.py'>) with frequency always
2025-02-13 17:06:47,002 - handlers.py[DEBUG]: start: modules-final/config-scripts_per_boot: running config-scripts_per_boot with frequency always
2025-02-13 17:06:47,002 - helpers.py[DEBUG]: Running config-scripts_per_boot using lock (<cloudinit.helpers.DummyLock object at 0x7fbb7da3ba30>)
2025-02-13 17:06:47,003 - handlers.py[DEBUG]: finish: modules-final/config-scripts_per_boot: SUCCESS: config-scripts_per_boot ran successfully and took 0.000 seconds
2025-02-13 17:06:47,003 - modules.py[DEBUG]: Running module scripts_per_instance (<module 'cloudinit.config.cc_scripts_per_instance' from '/usr/lib/python3/dist-packages/cloudinit/config/cc_scripts_per_instance.py'>) with frequency once-per-instance
2025-02-13 17:06:47,003 - handlers.py[DEBUG]: start: modules-final/config-scripts_per_instance: running config-scripts_per_instance with frequency once-per-instance
2025-02-13 17:06:47,003 - helpers.py[DEBUG]: config-scripts_per_instance already ran (freq=once-per-instance)
2025-02-13 17:06:47,003 - handlers.py[DEBUG]: finish: modules-final/config-scripts_per_instance: SUCCESS: config-scripts_per_instance previously ran
2025-02-13 17:06:47,003 - modules.py[DEBUG]: Running module scripts_user (<module 'cloudinit.config.cc_scripts_user' from '/usr/lib/python3/dist-packages/cloudinit/config/cc_scripts_user.py'>) with frequency once-per-instance
2025-02-13 17:06:47,003 - handlers.py[DEBUG]: start: modules-final/config-scripts_user: running config-scripts_user with frequency once-per-instance
2025-02-13 17:06:47,004 - helpers.py[DEBUG]: config-scripts_user already ran (freq=once-per-instance)
2025-02-13 17:06:47,004 - handlers.py[DEBUG]: finish: modules-final/config-scripts_user: SUCCESS: config-scripts_user previously ran
2025-02-13 17:06:47,004 - modules.py[DEBUG]: Running module ssh_authkey_fingerprints (<module 'cloudinit.config.cc_ssh_authkey_fingerprints' from '/usr/lib/python3/dist-packages/cloudinit/config/cc_ssh_authkey_fingerprints.py'>) with frequency once-per-instance
2025-02-13 17:06:47,004 - handlers.py[DEBUG]: start: modules-final/config-ssh_authkey_fingerprints: running config-ssh_authkey_fingerprints with frequency once-per-instance
2025-02-13 17:06:47,004 - helpers.py[DEBUG]: config-ssh_authkey_fingerprints already ran (freq=once-per-instance)
2025-02-13 17:06:47,004 - handlers.py[DEBUG]: finish: modules-final/config-ssh_authkey_fingerprints: SUCCESS: config-ssh_authkey_fingerprints previously ran
2025-02-13 17:06:47,004 - modules.py[DEBUG]: Running module keys_to_console (<module 'cloudinit.config.cc_keys_to_console' from '/usr/lib/python3/dist-packages/cloudinit/config/cc_keys_to_console.py'>) with frequency once-per-instance
2025-02-13 17:06:47,004 - handlers.py[DEBUG]: start: modules-final/config-keys_to_console: running config-keys_to_console with frequency once-per-instance
2025-02-13 17:06:47,004 - helpers.py[DEBUG]: config-keys_to_console already ran (freq=once-per-instance)
2025-02-13 17:06:47,004 - handlers.py[DEBUG]: finish: modules-final/config-keys_to_console: SUCCESS: config-keys_to_console previously ran
2025-02-13 17:06:47,004 - modules.py[DEBUG]: Running module install_hotplug (<module 'cloudinit.config.cc_install_hotplug' from '/usr/lib/python3/dist-packages/cloudinit/config/cc_install_hotplug.py'>) with frequency once-per-instance
2025-02-13 17:06:47,005 - handlers.py[DEBUG]: start: modules-final/config-install_hotplug: running config-install_hotplug with frequency once-per-instance
2025-02-13 17:06:47,005 - helpers.py[DEBUG]: config-install_hotplug already ran (freq=once-per-instance)
2025-02-13 17:06:47,005 - handlers.py[DEBUG]: finish: modules-final/config-install_hotplug: SUCCESS: config-install_hotplug previously ran
2025-02-13 17:06:47,005 - modules.py[DEBUG]: Running module final_message (<module 'cloudinit.config.cc_final_message' from '/usr/lib/python3/dist-packages/cloudinit/config/cc_final_message.py'>) with frequency always
2025-02-13 17:06:47,005 - handlers.py[DEBUG]: start: modules-final/config-final_message: running config-final_message with frequency always
2025-02-13 17:06:47,005 - helpers.py[DEBUG]: Running config-final_message using lock (<cloudinit.helpers.DummyLock object at 0x7fbb7da3a530>)
2025-02-13 17:06:47,005 - util.py[DEBUG]: Reading from /proc/uptime (quiet=False)
2025-02-13 17:06:47,005 - util.py[DEBUG]: Reading 11 bytes from /proc/uptime
2025-02-13 17:06:47,014 - log_util.py[DEBUG]: Cloud-init v. 24.4-0ubuntu1~22.04.1 finished at Thu, 13 Feb 2025 17:06:47 +0000. Datasource DataSourceAkamaiLocal.  Up 13.22 seconds
2025-02-13 17:06:47,014 - util.py[DEBUG]: Writing to /var/lib/cloud/instance/boot-finished - wb: [644] 67 bytes
2025-02-13 17:06:47,014 - handlers.py[DEBUG]: finish: modules-final/config-final_message: SUCCESS: config-final_message ran successfully and took 0.009 seconds
2025-02-13 17:06:47,014 - main.py[DEBUG]: Ran 10 modules with 0 failures
2025-02-13 17:06:47,014 - util.py[DEBUG]: Reading from /proc/uptime (quiet=False)
2025-02-13 17:06:47,014 - util.py[DEBUG]: Reading 11 bytes from /proc/uptime
2025-02-13 17:06:47,015 - atomic_helper.py[DEBUG]: Atomically writing to file /var/lib/cloud/data/status.json (via temporary file /var/lib/cloud/data/tmpkl3unl27) - w: [644] 508 bytes/chars
2025-02-13 17:06:47,015 - atomic_helper.py[DEBUG]: Atomically writing to file /var/lib/cloud/data/result.json (via temporary file /var/lib/cloud/data/tmpb3gdjl5w) - w: [644] 72 bytes/chars
2025-02-13 17:06:47,015 - util.py[DEBUG]: Creating symbolic link from '/run/cloud-init/result.json' => '../../var/lib/cloud/data/result.json'
2025-02-13 17:06:47,015 - performance.py[DEBUG]: cloud-init stage: 'modules-final' took 0.124 seconds
2025-02-13 17:06:47,016 - handlers.py[DEBUG]: finish: modules-final: SUCCESS: running modules for final
