2025-02-04 15:13:19,101 - log_util.py[DEBUG]: Cloud-init v. 24.4-0ubuntu1~22.04.1 running 'init-local' at Tue, 04 Feb 2025 15:13:19 +0000. Up 6.25 seconds.
2025-02-04 15:13:19,102 - main.py[INFO]: PID [1] started cloud-init 'init-local'.
2025-02-04 15:13:19,102 - main.py[DEBUG]: No kernel command line url found.
2025-02-04 15:13:19,102 - main.py[DEBUG]: Closing stdin
2025-02-04 15:13:19,118 - util.py[DEBUG]: Writing to /var/log/cloud-init.log - ab: [640] 0 bytes
2025-02-04 15:13:19,118 - util.py[DEBUG]: Changing the ownership of /var/log/cloud-init.log to 104:4
2025-02-04 15:13:19,123 - util.py[DEBUG]: Writing to /var/lib/cloud/data/python-version - wb: [644] 4 bytes
2025-02-04 15:13:19,124 - util.py[DEBUG]: Attempting to remove /var/lib/cloud/instance/boot-finished
2025-02-04 15:13:19,124 - handlers.py[DEBUG]: start: init-local/check-cache: attempting to read from cache [check]
2025-02-04 15:13:19,124 - util.py[DEBUG]: Reading from /var/lib/cloud/instance/obj.pkl (quiet=False)
2025-02-04 15:13:19,124 - stages.py[DEBUG]: no cache found
2025-02-04 15:13:19,124 - handlers.py[DEBUG]: finish: init-local/check-cache: SUCCESS: no cache found
2025-02-04 15:13:19,135 - stages.py[DEBUG]: Using distro class <class 'cloudinit.distros.ubuntu.Distro'>
2025-02-04 15:13:19,135 - sources[DEBUG]: Looking for data source in: ['Akamai', 'None'], via packages ['', 'cloudinit.sources'] that matches dependencies ['FILESYSTEM']
2025-02-04 15:13:19,146 - sources[DEBUG]: Searching for local data source in: ['DataSourceAkamaiLocal']
2025-02-04 15:13:19,146 - handlers.py[DEBUG]: start: init-local/search-AkamaiLocal: searching for local data from DataSourceAkamaiLocal
2025-02-04 15:13:19,146 - sources[DEBUG]: Seeing if we can get any data from <class 'cloudinit.sources.DataSourceAkamai.DataSourceAkamaiLocal'>
2025-02-04 15:13:19,146 - DataSourceAkamai.py[DEBUG]: Setting up Akamai DataSource
2025-02-04 15:13:19,146 - dmi.py[DEBUG]: querying dmi data /sys/class/dmi/id/board_serial
2025-02-04 15:13:19,146 - dmi.py[DEBUG]: did not find /sys/class/dmi/id/board_serial
2025-02-04 15:13:19,146 - subp.py[DEBUG]: Running command ['/usr/sbin/dmidecode', '--string', 'baseboard-serial-number'] with allowed return codes [0] (shell=False, capture=True)
2025-02-04 15:13:19,149 - dmi.py[DEBUG]: dmidecode returned '' for 'baseboard-serial-number'
2025-02-04 15:13:19,149 - sources[DEBUG]: Update datasource metadata and network config due to events: boot-new-instance
2025-02-04 15:13:19,150 - sources[DEBUG]: Detected DataSourceAkamaiLocal
2025-02-04 15:13:19,150 - DataSourceAkamai.py[DEBUG]: Getting data from Akamai DataSource
2025-02-04 15:13:19,150 - dmi.py[DEBUG]: querying dmi data /sys/class/dmi/id/sys_vendor
2025-02-04 15:13:19,150 - dmi.py[DEBUG]: querying dmi data /sys/class/dmi/id/product_serial
2025-02-04 15:13:19,150 - util.py[DEBUG]: Reading from /sys/class/net/lo/addr_assign_type (quiet=False)
2025-02-04 15:13:19,150 - util.py[DEBUG]: Reading 2 bytes from /sys/class/net/lo/addr_assign_type
2025-02-04 15:13:19,155 - util.py[DEBUG]: Reading from /sys/class/net/lo/uevent (quiet=False)
2025-02-04 15:13:19,155 - util.py[DEBUG]: Reading 23 bytes from /sys/class/net/lo/uevent
2025-02-04 15:13:19,155 - util.py[DEBUG]: Reading from /sys/class/net/lo/address (quiet=False)
2025-02-04 15:13:19,155 - util.py[DEBUG]: Reading 18 bytes from /sys/class/net/lo/address
2025-02-04 15:13:19,155 - net[DEBUG]: ovs-vsctl not in PATH; not detecting Open vSwitch interfaces
2025-02-04 15:13:19,156 - util.py[DEBUG]: Reading from /sys/class/net/lo/device/device (quiet=False)
2025-02-04 15:13:19,156 - util.py[DEBUG]: Reading from /sys/class/net/eth0/addr_assign_type (quiet=False)
2025-02-04 15:13:19,156 - util.py[DEBUG]: Reading 2 bytes from /sys/class/net/eth0/addr_assign_type
2025-02-04 15:13:19,156 - util.py[DEBUG]: Reading from /sys/class/net/eth0/uevent (quiet=False)
2025-02-04 15:13:19,156 - util.py[DEBUG]: Reading 25 bytes from /sys/class/net/eth0/uevent
2025-02-04 15:13:19,156 - util.py[DEBUG]: Reading from /sys/class/net/eth0/address (quiet=False)
2025-02-04 15:13:19,156 - util.py[DEBUG]: Reading 18 bytes from /sys/class/net/eth0/address
2025-02-04 15:13:19,156 - util.py[DEBUG]: Reading from /sys/class/net/eth0/device/device (quiet=False)
2025-02-04 15:13:19,156 - util.py[DEBUG]: Reading 7 bytes from /sys/class/net/eth0/device/device
2025-02-04 15:13:19,156 - util.py[DEBUG]: Reading from /sys/class/net/lo/type (quiet=False)
2025-02-04 15:13:19,156 - util.py[DEBUG]: Reading 4 bytes from /sys/class/net/lo/type
2025-02-04 15:13:19,156 - util.py[DEBUG]: Reading from /sys/class/net/eth0/type (quiet=False)
2025-02-04 15:13:19,156 - util.py[DEBUG]: Reading 2 bytes from /sys/class/net/eth0/type
2025-02-04 15:13:19,157 - ephemeral.py[DEBUG]: No connectivity URLs provided. Skipping connectivity check before ephemeral network setup.
2025-02-04 15:13:19,157 - ephemeral.py[DEBUG]: No connectivity to IMDS, attempting DHCP setup.
2025-02-04 15:13:19,157 - util.py[DEBUG]: Reading from /sys/class/net/eth0/operstate (quiet=False)
2025-02-04 15:13:19,157 - util.py[DEBUG]: Reading 5 bytes from /sys/class/net/eth0/operstate
2025-02-04 15:13:19,157 - subp.py[DEBUG]: Running command ['ip', 'link', 'set', 'dev', 'eth0', 'up'] with allowed return codes [0] (shell=False, capture=True)
2025-02-04 15:13:19,169 - performance.py[DEBUG]: Running ['ip', 'link', 'set', 'dev', 'eth0', 'up'] took 0.012 seconds
2025-02-04 15:13:19,169 - ephemeral.py[DEBUG]: Successfully brought up eth0 for ephemeral ipv6 networking.
2025-02-04 15:13:19,170 - url_helper.py[DEBUG]: [0/5] open 'http://[fd00:a9fe:a9fe::1]/v1/token' with {'url': 'http://[fd00:a9fe:a9fe::1]/v1/token', 'stream': False, 'allow_redirects': True, 'method': 'PUT', 'timeout': 30.0, 'headers': {'Metadata-Token-Expiry-Seconds': '300', 'User-Agent': 'Cloud-Init/24.4-0ubuntu1~22.04.1'}} configuration
2025-02-04 15:13:19,177 - url_helper.py[DEBUG]: Please wait 2 seconds while we wait to try again
2025-02-04 15:13:21,178 - url_helper.py[DEBUG]: [1/5] open 'http://[fd00:a9fe:a9fe::1]/v1/token' with {'url': 'http://[fd00:a9fe:a9fe::1]/v1/token', 'stream': False, 'allow_redirects': True, 'method': 'PUT', 'timeout': 30.0, 'headers': {'Metadata-Token-Expiry-Seconds': '300', 'User-Agent': 'Cloud-Init/24.4-0ubuntu1~22.04.1'}} configuration
2025-02-04 15:13:21,572 - url_helper.py[DEBUG]: Read from http://[fd00:a9fe:a9fe::1]/v1/token (200, 64b) after 2 attempts
2025-02-04 15:13:21,572 - url_helper.py[DEBUG]: [0/3] open 'http://[fd00:a9fe:a9fe::1]/v1/instance' with {'url': 'http://[fd00:a9fe:a9fe::1]/v1/instance', 'stream': False, 'allow_redirects': True, 'method': 'GET', 'timeout': 30.0, 'headers': {'Accept': 'application/json', 'Metadata-Token': 'ee3b8937967f080cf58004fff9fefa4389be2b7008b9e650a25ad4a919b5d3b7', 'User-Agent': 'Cloud-Init/24.4-0ubuntu1~22.04.1'}} configuration
2025-02-04 15:13:22,589 - url_helper.py[DEBUG]: Read from http://[fd00:a9fe:a9fe::1]/v1/instance (200, 407b) after 1 attempts
2025-02-04 15:13:22,589 - url_helper.py[DEBUG]: [0/3] open 'http://[fd00:a9fe:a9fe::1]/v1/user-data' with {'url': 'http://[fd00:a9fe:a9fe::1]/v1/user-data', 'stream': False, 'allow_redirects': True, 'method': 'GET', 'timeout': 30.0, 'headers': {'Metadata-Token': 'ee3b8937967f080cf58004fff9fefa4389be2b7008b9e650a25ad4a919b5d3b7', 'User-Agent': 'Cloud-Init/24.4-0ubuntu1~22.04.1'}} configuration
2025-02-04 15:13:23,101 - url_helper.py[DEBUG]: Read from http://[fd00:a9fe:a9fe::1]/v1/user-data (200, 0b) after 1 attempts
2025-02-04 15:13:23,102 - util.py[DEBUG]: Reading from /etc/hosts (quiet=False)
2025-02-04 15:13:23,102 - util.py[DEBUG]: Reading 181 bytes from /etc/hosts
2025-02-04 15:13:23,103 - util.py[DEBUG]: Writing to /run/cloud-init/cloud-id-akamai - wb: [644] 7 bytes
2025-02-04 15:13:23,103 - util.py[DEBUG]: Creating symbolic link from '/run/cloud-init/cloud-id' => '/run/cloud-init/cloud-id-akamai'
2025-02-04 15:13:23,104 - atomic_helper.py[DEBUG]: Atomically writing to file /run/cloud-init/instance-data-sensitive.json (via temporary file /run/cloud-init/tmp2lmv2wn0) - w: [600] 8726 bytes/chars
2025-02-04 15:13:23,105 - atomic_helper.py[DEBUG]: Atomically writing to file /run/cloud-init/instance-data.json (via temporary file /run/cloud-init/tmpw8op0pht) - w: [644] 1941 bytes/chars
2025-02-04 15:13:23,105 - performance.py[DEBUG]: Getting metadata took 3.955 seconds
2025-02-04 15:13:23,105 - handlers.py[DEBUG]: finish: init-local/search-AkamaiLocal: SUCCESS: found local data from DataSourceAkamaiLocal
2025-02-04 15:13:23,105 - util.py[DEBUG]: Attempting to remove /var/lib/cloud/instance
2025-02-04 15:13:23,105 - stages.py[INFO]: Loaded datasource DataSourceAkamaiLocal - DataSourceAkamaiLocal
2025-02-04 15:13:23,105 - util.py[DEBUG]: Reading from /etc/cloud/cloud.cfg (quiet=False)
2025-02-04 15:13:23,105 - util.py[DEBUG]: Reading 3766 bytes from /etc/cloud/cloud.cfg
2025-02-04 15:13:23,105 - util.py[DEBUG]: Attempting to load yaml from string of length 3766 with allowed root types (<class 'dict'>,)
2025-02-04 15:13:23,117 - util.py[DEBUG]: Reading from /etc/cloud/cloud.cfg.d/99-linode.cfg (quiet=False)
2025-02-04 15:13:23,117 - util.py[DEBUG]: Reading 492 bytes from /etc/cloud/cloud.cfg.d/99-linode.cfg
2025-02-04 15:13:23,117 - util.py[DEBUG]: Attempting to load yaml from string of length 492 with allowed root types (<class 'dict'>,)
2025-02-04 15:13:23,119 - util.py[DEBUG]: Reading from /etc/cloud/cloud.cfg.d/90_dpkg.cfg (quiet=False)
2025-02-04 15:13:23,119 - util.py[DEBUG]: Reading 333 bytes from /etc/cloud/cloud.cfg.d/90_dpkg.cfg
2025-02-04 15:13:23,119 - util.py[DEBUG]: Attempting to load yaml from string of length 333 with allowed root types (<class 'dict'>,)
2025-02-04 15:13:23,121 - util.py[DEBUG]: Reading from /etc/cloud/cloud.cfg.d/05_logging.cfg (quiet=False)
2025-02-04 15:13:23,121 - util.py[DEBUG]: Reading 2071 bytes from /etc/cloud/cloud.cfg.d/05_logging.cfg
2025-02-04 15:13:23,121 - util.py[DEBUG]: Attempting to load yaml from string of length 2071 with allowed root types (<class 'dict'>,)
2025-02-04 15:13:23,125 - util.py[DEBUG]: Reading from /run/cloud-init/cloud.cfg (quiet=False)
2025-02-04 15:13:23,125 - util.py[DEBUG]: Reading 34 bytes from /run/cloud-init/cloud.cfg
2025-02-04 15:13:23,125 - util.py[DEBUG]: Attempting to load yaml from string of length 34 with allowed root types (<class 'dict'>,)
2025-02-04 15:13:23,125 - util.py[DEBUG]: Attempting to load yaml from string of length 0 with allowed root types (<class 'dict'>,)
2025-02-04 15:13:23,125 - util.py[DEBUG]: loaded blob returned None, returning default.
2025-02-04 15:13:23,126 - util.py[DEBUG]: Attempting to remove /var/lib/cloud/instance
2025-02-04 15:13:23,126 - util.py[DEBUG]: Creating symbolic link from '/var/lib/cloud/instance' => '/var/lib/cloud/instances/71308115'
2025-02-04 15:13:23,128 - util.py[DEBUG]: Reading from /var/lib/cloud/instances/71308115/datasource (quiet=False)
2025-02-04 15:13:23,128 - util.py[DEBUG]: Writing to /var/lib/cloud/instances/71308115/datasource - wb: [644] 45 bytes
2025-02-04 15:13:23,128 - util.py[DEBUG]: Writing to /var/lib/cloud/data/previous-datasource - wb: [644] 45 bytes
2025-02-04 15:13:23,128 - util.py[DEBUG]: Reading from /var/lib/cloud/data/instance-id (quiet=False)
2025-02-04 15:13:23,128 - stages.py[DEBUG]: previous iid found to be NO_PREVIOUS_INSTANCE_ID
2025-02-04 15:13:23,128 - util.py[DEBUG]: Writing to /var/lib/cloud/data/instance-id - wb: [644] 9 bytes
2025-02-04 15:13:23,129 - util.py[DEBUG]: Writing to /run/cloud-init/.instance-id - wb: [644] 9 bytes
2025-02-04 15:13:23,129 - util.py[DEBUG]: Writing to /var/lib/cloud/data/previous-instance-id - wb: [644] 24 bytes
2025-02-04 15:13:23,130 - util.py[DEBUG]: Writing to /var/lib/cloud/instance/obj.pkl - wb: [400] 7026 bytes
2025-02-04 15:13:23,130 - main.py[DEBUG]: [local] init will now be targeting instance id: 71308115. new=True
2025-02-04 15:13:23,130 - util.py[DEBUG]: Reading from /etc/cloud/cloud.cfg (quiet=False)
2025-02-04 15:13:23,130 - util.py[DEBUG]: Reading 3766 bytes from /etc/cloud/cloud.cfg
2025-02-04 15:13:23,130 - util.py[DEBUG]: Attempting to load yaml from string of length 3766 with allowed root types (<class 'dict'>,)
2025-02-04 15:13:23,142 - util.py[DEBUG]: Reading from /etc/cloud/cloud.cfg.d/99-linode.cfg (quiet=False)
2025-02-04 15:13:23,142 - util.py[DEBUG]: Reading 492 bytes from /etc/cloud/cloud.cfg.d/99-linode.cfg
2025-02-04 15:13:23,143 - util.py[DEBUG]: Attempting to load yaml from string of length 492 with allowed root types (<class 'dict'>,)
2025-02-04 15:13:23,144 - util.py[DEBUG]: Reading from /etc/cloud/cloud.cfg.d/90_dpkg.cfg (quiet=False)
2025-02-04 15:13:23,144 - util.py[DEBUG]: Reading 333 bytes from /etc/cloud/cloud.cfg.d/90_dpkg.cfg
2025-02-04 15:13:23,144 - util.py[DEBUG]: Attempting to load yaml from string of length 333 with allowed root types (<class 'dict'>,)
2025-02-04 15:13:23,146 - util.py[DEBUG]: Reading from /etc/cloud/cloud.cfg.d/05_logging.cfg (quiet=False)
2025-02-04 15:13:23,146 - util.py[DEBUG]: Reading 2071 bytes from /etc/cloud/cloud.cfg.d/05_logging.cfg
2025-02-04 15:13:23,146 - util.py[DEBUG]: Attempting to load yaml from string of length 2071 with allowed root types (<class 'dict'>,)
2025-02-04 15:13:23,150 - util.py[DEBUG]: Reading from /run/cloud-init/cloud.cfg (quiet=False)
2025-02-04 15:13:23,150 - util.py[DEBUG]: Reading 34 bytes from /run/cloud-init/cloud.cfg
2025-02-04 15:13:23,150 - util.py[DEBUG]: Attempting to load yaml from string of length 34 with allowed root types (<class 'dict'>,)
2025-02-04 15:13:23,150 - util.py[DEBUG]: Attempting to load yaml from string of length 0 with allowed root types (<class 'dict'>,)
2025-02-04 15:13:23,150 - util.py[DEBUG]: loaded blob returned None, returning default.
2025-02-04 15:13:23,152 - stages.py[DEBUG]: Using distro class <class 'cloudinit.distros.ubuntu.Distro'>
2025-02-04 15:13:23,153 - util.py[DEBUG]: Reading from /sys/class/net/lo/address (quiet=False)
2025-02-04 15:13:23,153 - util.py[DEBUG]: Reading 18 bytes from /sys/class/net/lo/address
2025-02-04 15:13:23,153 - util.py[DEBUG]: Reading from /sys/class/net/eth0/address (quiet=False)
2025-02-04 15:13:23,153 - util.py[DEBUG]: Reading 18 bytes from /sys/class/net/eth0/address
2025-02-04 15:13:23,153 - stages.py[DEBUG]: network config disabled by system_cfg
2025-02-04 15:13:23,153 - stages.py[INFO]: network config is disabled by system_cfg
2025-02-04 15:13:23,153 - main.py[DEBUG]: Network connectivity determined unnecessary for cloud-init's network stage. Reason: user data: no configuration found, vendor data: no configuration found, vendor data2: no configuration found
2025-02-04 15:13:23,153 - util.py[DEBUG]: Writing to /run/cloud-init/.skip-network - wb: [644] 0 bytes
2025-02-04 15:13:23,154 - main.py[DEBUG]: [local] Exiting. datasource DataSourceAkamaiLocal not in local mode.
2025-02-04 15:13:23,154 - util.py[DEBUG]: Reading from /proc/uptime (quiet=False)
2025-02-04 15:13:23,154 - util.py[DEBUG]: Reading 11 bytes from /proc/uptime
2025-02-04 15:13:23,154 - atomic_helper.py[DEBUG]: Atomically writing to file /var/lib/cloud/data/status.json (via temporary file /var/lib/cloud/data/tmpruqudkvi) - w: [644] 503 bytes/chars
2025-02-04 15:13:23,154 - performance.py[DEBUG]: cloud-init stage: 'init-local' took 4.233 seconds
2025-02-04 15:13:23,154 - handlers.py[DEBUG]: finish: init-local: SUCCESS: searching for local datasources
2025-02-04 15:13:27,051 - log_util.py[DEBUG]: Cloud-init v. 24.4-0ubuntu1~22.04.1 running 'init' at Tue, 04 Feb 2025 15:13:27 +0000. Up 14.25 seconds.
2025-02-04 15:13:27,051 - main.py[INFO]: PID [1] started cloud-init 'init'.
2025-02-04 15:13:27,051 - main.py[DEBUG]: No kernel command line url found.
2025-02-04 15:13:27,051 - main.py[DEBUG]: Closing stdin
2025-02-04 15:13:27,053 - util.py[DEBUG]: Writing to /var/log/cloud-init.log - ab: [640] 0 bytes
2025-02-04 15:13:27,053 - util.py[DEBUG]: Changing the ownership of /var/log/cloud-init.log to 104:4
2025-02-04 15:13:27,053 - util.py[DEBUG]: Reading from /var/lib/cloud/data/python-version (quiet=False)
2025-02-04 15:13:27,054 - util.py[DEBUG]: Reading 4 bytes from /var/lib/cloud/data/python-version
2025-02-04 15:13:27,054 - subp.py[DEBUG]: Running command ['ip', '--json', 'addr'] with allowed return codes [0] (shell=False, capture=True)
2025-02-04 15:13:27,059 - subp.py[DEBUG]: Running command ['ip', '-o', 'route', 'list'] with allowed return codes [0] (shell=False, capture=True)
2025-02-04 15:13:27,061 - subp.py[DEBUG]: Running command ['ip', '--oneline', '-6', 'route', 'list', 'table', 'all'] with allowed return codes [0, 1] (shell=False, capture=True)
2025-02-04 15:13:27,063 - handlers.py[DEBUG]: start: init-network/check-cache: attempting to read from cache [trust]
2025-02-04 15:13:27,063 - util.py[DEBUG]: Reading from /var/lib/cloud/instance/obj.pkl (quiet=False)
2025-02-04 15:13:27,063 - util.py[DEBUG]: Reading 7026 bytes from /var/lib/cloud/instance/obj.pkl
2025-02-04 15:13:27,066 - util.py[DEBUG]: Reading from /run/cloud-init/.instance-id (quiet=False)
2025-02-04 15:13:27,066 - util.py[DEBUG]: Reading 9 bytes from /run/cloud-init/.instance-id
2025-02-04 15:13:27,066 - stages.py[DEBUG]: restored from cache with run check: DataSourceAkamaiLocal
2025-02-04 15:13:27,066 - handlers.py[DEBUG]: finish: init-network/check-cache: SUCCESS: restored from cache with run check: DataSourceAkamaiLocal
2025-02-04 15:13:27,066 - util.py[DEBUG]: Reading from /etc/cloud/cloud.cfg (quiet=False)
2025-02-04 15:13:27,066 - util.py[DEBUG]: Reading 3766 bytes from /etc/cloud/cloud.cfg
2025-02-04 15:13:27,066 - util.py[DEBUG]: Attempting to load yaml from string of length 3766 with allowed root types (<class 'dict'>,)
2025-02-04 15:13:27,091 - util.py[DEBUG]: Reading from /etc/cloud/cloud.cfg.d/99-linode.cfg (quiet=False)
2025-02-04 15:13:27,091 - util.py[DEBUG]: Reading 492 bytes from /etc/cloud/cloud.cfg.d/99-linode.cfg
2025-02-04 15:13:27,092 - util.py[DEBUG]: Attempting to load yaml from string of length 492 with allowed root types (<class 'dict'>,)
2025-02-04 15:13:27,093 - util.py[DEBUG]: Reading from /etc/cloud/cloud.cfg.d/90_dpkg.cfg (quiet=False)
2025-02-04 15:13:27,093 - util.py[DEBUG]: Reading 333 bytes from /etc/cloud/cloud.cfg.d/90_dpkg.cfg
2025-02-04 15:13:27,093 - util.py[DEBUG]: Attempting to load yaml from string of length 333 with allowed root types (<class 'dict'>,)
2025-02-04 15:13:27,098 - util.py[DEBUG]: Reading from /etc/cloud/cloud.cfg.d/05_logging.cfg (quiet=False)
2025-02-04 15:13:27,098 - util.py[DEBUG]: Reading 2071 bytes from /etc/cloud/cloud.cfg.d/05_logging.cfg
2025-02-04 15:13:27,098 - util.py[DEBUG]: Attempting to load yaml from string of length 2071 with allowed root types (<class 'dict'>,)
2025-02-04 15:13:27,102 - util.py[DEBUG]: Reading from /run/cloud-init/cloud.cfg (quiet=False)
2025-02-04 15:13:27,105 - util.py[DEBUG]: Reading 34 bytes from /run/cloud-init/cloud.cfg
2025-02-04 15:13:27,105 - util.py[DEBUG]: Attempting to load yaml from string of length 34 with allowed root types (<class 'dict'>,)
2025-02-04 15:13:27,105 - util.py[DEBUG]: Attempting to load yaml from string of length 0 with allowed root types (<class 'dict'>,)
2025-02-04 15:13:27,105 - util.py[DEBUG]: loaded blob returned None, returning default.
2025-02-04 15:13:27,106 - stages.py[INFO]: Instance link already exists, not recreating it.
2025-02-04 15:13:27,108 - util.py[DEBUG]: Reading from /var/lib/cloud/instances/71308115/datasource (quiet=False)
2025-02-04 15:13:27,108 - util.py[DEBUG]: Reading 45 bytes from /var/lib/cloud/instances/71308115/datasource
2025-02-04 15:13:27,108 - util.py[DEBUG]: Writing to /var/lib/cloud/instances/71308115/datasource - wb: [644] 45 bytes
2025-02-04 15:13:27,108 - util.py[DEBUG]: Writing to /var/lib/cloud/data/previous-datasource - wb: [644] 45 bytes
2025-02-04 15:13:27,110 - util.py[DEBUG]: Reading from /var/lib/cloud/data/instance-id (quiet=False)
2025-02-04 15:13:27,110 - util.py[DEBUG]: Reading 9 bytes from /var/lib/cloud/data/instance-id
2025-02-04 15:13:27,110 - stages.py[DEBUG]: previous iid found to be 71308115
2025-02-04 15:13:27,110 - util.py[DEBUG]: Writing to /var/lib/cloud/data/instance-id - wb: [644] 9 bytes
2025-02-04 15:13:27,111 - util.py[DEBUG]: Writing to /run/cloud-init/.instance-id - wb: [644] 9 bytes
2025-02-04 15:13:27,111 - util.py[DEBUG]: Writing to /var/lib/cloud/data/previous-instance-id - wb: [644] 9 bytes
2025-02-04 15:13:27,111 - util.py[DEBUG]: Writing to /var/lib/cloud/instance/obj.pkl - wb: [400] 7038 bytes
2025-02-04 15:13:27,113 - stages.py[INFO]: Not re-loading configuration, instance id and datasource have not changed.
2025-02-04 15:13:27,113 - main.py[DEBUG]: [net] init will now be targeting instance id: 71308115. new=False
2025-02-04 15:13:27,114 - util.py[DEBUG]: Reading from /sys/class/net/lo/address (quiet=False)
2025-02-04 15:13:27,114 - util.py[DEBUG]: Reading 18 bytes from /sys/class/net/lo/address
2025-02-04 15:13:27,114 - util.py[DEBUG]: Reading from /sys/class/net/eth0/address (quiet=False)
2025-02-04 15:13:27,114 - util.py[DEBUG]: Reading 18 bytes from /sys/class/net/eth0/address
2025-02-04 15:13:27,116 - stages.py[DEBUG]: network config disabled by system_cfg
2025-02-04 15:13:27,116 - stages.py[INFO]: network config is disabled by system_cfg
2025-02-04 15:13:27,116 - handlers.py[DEBUG]: start: init-network/setup-datasource: setting up datasource
2025-02-04 15:13:27,116 - handlers.py[DEBUG]: finish: init-network/setup-datasource: SUCCESS: setting up datasource
2025-02-04 15:13:27,116 - util.py[DEBUG]: Writing to /var/lib/cloud/instances/71308115/user-data.txt - wb: [600] 0 bytes
2025-02-04 15:13:27,119 - util.py[DEBUG]: Writing to /var/lib/cloud/instances/71308115/user-data.txt.i - wb: [600] 308 bytes
2025-02-04 15:13:27,119 - util.py[DEBUG]: Writing to /var/lib/cloud/instances/71308115/vendor-data.txt - wb: [600] 0 bytes
2025-02-04 15:13:27,120 - util.py[DEBUG]: Writing to /var/lib/cloud/instances/71308115/vendor-data.txt.i - wb: [600] 308 bytes
2025-02-04 15:13:27,120 - util.py[DEBUG]: Writing to /var/lib/cloud/instances/71308115/vendor-data2.txt - wb: [600] 0 bytes
2025-02-04 15:13:27,121 - util.py[DEBUG]: Writing to /var/lib/cloud/instances/71308115/vendor-data2.txt.i - wb: [600] 308 bytes
2025-02-04 15:13:27,121 - stages.py[DEBUG]: Using distro class <class 'cloudinit.distros.ubuntu.Distro'>
2025-02-04 15:13:27,126 - util.py[DEBUG]: Writing to /var/lib/cloud/instances/71308115/sem/consume_data - wb: [644] 24 bytes
2025-02-04 15:13:27,126 - helpers.py[DEBUG]: Running consume_data using lock (<FileLock using file '/var/lib/cloud/instances/71308115/sem/consume_data'>)
2025-02-04 15:13:27,127 - handlers.py[DEBUG]: start: init-network/consume-user-data: reading and applying user-data
2025-02-04 15:13:27,128 - stages.py[DEBUG]: Added default handler for {'text/cloud-config', 'text/cloud-config-jsonp'} from CloudConfigPartHandler: [['text/cloud-config', 'text/cloud-config-jsonp']]
2025-02-04 15:13:27,128 - stages.py[DEBUG]: Added default handler for {'text/x-shellscript'} from ShellScriptPartHandler: [['text/x-shellscript']]
2025-02-04 15:13:27,128 - stages.py[DEBUG]: Added default handler for {'text/x-shellscript-per-boot'} from ShellScriptByFreqPartHandler: [['text/x-shellscript-per-boot']]
2025-02-04 15:13:27,128 - stages.py[DEBUG]: Added default handler for {'text/x-shellscript-per-instance'} from ShellScriptByFreqPartHandler: [['text/x-shellscript-per-instance']]
2025-02-04 15:13:27,128 - stages.py[DEBUG]: Added default handler for {'text/x-shellscript-per-once'} from ShellScriptByFreqPartHandler: [['text/x-shellscript-per-once']]
2025-02-04 15:13:27,128 - stages.py[DEBUG]: Added default handler for {'text/cloud-boothook'} from BootHookPartHandler: [['text/cloud-boothook']]
2025-02-04 15:13:27,128 - stages.py[DEBUG]: Added default handler for {'text/jinja2'} from JinjaTemplatePartHandler: [['text/jinja2']]
2025-02-04 15:13:27,128 - handlers[DEBUG]: Calling handler CloudConfigPartHandler: [['text/cloud-config', 'text/cloud-config-jsonp']] (__begin__, None, 3) with frequency once-per-instance
2025-02-04 15:13:27,128 - handlers[DEBUG]: Calling handler ShellScriptPartHandler: [['text/x-shellscript']] (__begin__, None, 2) with frequency once-per-instance
2025-02-04 15:13:27,128 - handlers[DEBUG]: Calling handler ShellScriptByFreqPartHandler: [['text/x-shellscript-per-boot']] (__begin__, None, 2) with frequency once-per-instance
2025-02-04 15:13:27,128 - handlers[DEBUG]: Calling handler ShellScriptByFreqPartHandler: [['text/x-shellscript-per-instance']] (__begin__, None, 2) with frequency once-per-instance
2025-02-04 15:13:27,128 - handlers[DEBUG]: Calling handler ShellScriptByFreqPartHandler: [['text/x-shellscript-per-once']] (__begin__, None, 2) with frequency once-per-instance
2025-02-04 15:13:27,128 - handlers[DEBUG]: Calling handler BootHookPartHandler: [['text/cloud-boothook']] (__begin__, None, 2) with frequency once-per-instance
2025-02-04 15:13:27,129 - handlers[DEBUG]: Calling handler JinjaTemplatePartHandler: [['text/jinja2']] (__begin__, None, 3) with frequency once-per-instance
2025-02-04 15:13:27,129 - handlers[DEBUG]: {'MIME-Version': '1.0', 'Content-Type': 'text/x-not-multipart', 'Content-Disposition': 'attachment; filename="part-001"'}
2025-02-04 15:13:27,129 - handlers[DEBUG]: Empty payload of type text/x-not-multipart
2025-02-04 15:13:27,129 - handlers[DEBUG]: Calling handler CloudConfigPartHandler: [['text/cloud-config', 'text/cloud-config-jsonp']] (__end__, None, 3) with frequency once-per-instance
2025-02-04 15:13:27,129 - util.py[DEBUG]: Writing to /var/lib/cloud/instances/71308115/cloud-config.txt - wb: [600] 0 bytes
2025-02-04 15:13:27,129 - handlers[DEBUG]: Calling handler ShellScriptPartHandler: [['text/x-shellscript']] (__end__, None, 2) with frequency once-per-instance
2025-02-04 15:13:27,129 - handlers[DEBUG]: Calling handler ShellScriptByFreqPartHandler: [['text/x-shellscript-per-boot']] (__end__, None, 2) with frequency once-per-instance
2025-02-04 15:13:27,129 - handlers[DEBUG]: Calling handler ShellScriptByFreqPartHandler: [['text/x-shellscript-per-instance']] (__end__, None, 2) with frequency once-per-instance
2025-02-04 15:13:27,129 - handlers[DEBUG]: Calling handler ShellScriptByFreqPartHandler: [['text/x-shellscript-per-once']] (__end__, None, 2) with frequency once-per-instance
2025-02-04 15:13:27,129 - handlers[DEBUG]: Calling handler BootHookPartHandler: [['text/cloud-boothook']] (__end__, None, 2) with frequency once-per-instance
2025-02-04 15:13:27,129 - handlers[DEBUG]: Calling handler JinjaTemplatePartHandler: [['text/jinja2']] (__end__, None, 3) with frequency once-per-instance
2025-02-04 15:13:27,129 - handlers.py[DEBUG]: finish: init-network/consume-user-data: SUCCESS: reading and applying user-data
2025-02-04 15:13:27,129 - handlers.py[DEBUG]: start: init-network/consume-vendor-data: reading and applying vendor-data
2025-02-04 15:13:27,129 - stages.py[DEBUG]: no vendordata from datasource
2025-02-04 15:13:27,130 - handlers.py[DEBUG]: finish: init-network/consume-vendor-data: SUCCESS: reading and applying vendor-data
2025-02-04 15:13:27,130 - handlers.py[DEBUG]: start: init-network/consume-vendor-data2: reading and applying vendor-data2
2025-02-04 15:13:27,130 - stages.py[DEBUG]: no vendordata2 from datasource
2025-02-04 15:13:27,130 - handlers.py[DEBUG]: finish: init-network/consume-vendor-data2: SUCCESS: reading and applying vendor-data2
2025-02-04 15:13:27,130 - util.py[DEBUG]: Reading from /etc/cloud/cloud.cfg (quiet=False)
2025-02-04 15:13:27,130 - util.py[DEBUG]: Reading 3766 bytes from /etc/cloud/cloud.cfg
2025-02-04 15:13:27,130 - util.py[DEBUG]: Attempting to load yaml from string of length 3766 with allowed root types (<class 'dict'>,)
2025-02-04 15:13:27,145 - util.py[DEBUG]: Reading from /etc/cloud/cloud.cfg.d/99-linode.cfg (quiet=False)
2025-02-04 15:13:27,145 - util.py[DEBUG]: Reading 492 bytes from /etc/cloud/cloud.cfg.d/99-linode.cfg
2025-02-04 15:13:27,145 - util.py[DEBUG]: Attempting to load yaml from string of length 492 with allowed root types (<class 'dict'>,)
2025-02-04 15:13:27,147 - util.py[DEBUG]: Reading from /etc/cloud/cloud.cfg.d/90_dpkg.cfg (quiet=False)
2025-02-04 15:13:27,147 - util.py[DEBUG]: Reading 333 bytes from /etc/cloud/cloud.cfg.d/90_dpkg.cfg
2025-02-04 15:13:27,147 - util.py[DEBUG]: Attempting to load yaml from string of length 333 with allowed root types (<class 'dict'>,)
2025-02-04 15:13:27,149 - util.py[DEBUG]: Reading from /etc/cloud/cloud.cfg.d/05_logging.cfg (quiet=False)
2025-02-04 15:13:27,149 - util.py[DEBUG]: Reading 2071 bytes from /etc/cloud/cloud.cfg.d/05_logging.cfg
2025-02-04 15:13:27,149 - util.py[DEBUG]: Attempting to load yaml from string of length 2071 with allowed root types (<class 'dict'>,)
2025-02-04 15:13:27,152 - util.py[DEBUG]: Reading from /run/cloud-init/cloud.cfg (quiet=False)
2025-02-04 15:13:27,152 - util.py[DEBUG]: Reading 34 bytes from /run/cloud-init/cloud.cfg
2025-02-04 15:13:27,152 - util.py[DEBUG]: Attempting to load yaml from string of length 34 with allowed root types (<class 'dict'>,)
2025-02-04 15:13:27,152 - util.py[DEBUG]: Attempting to load yaml from string of length 0 with allowed root types (<class 'dict'>,)
2025-02-04 15:13:27,152 - util.py[DEBUG]: loaded blob returned None, returning default.
2025-02-04 15:13:27,153 - util.py[DEBUG]: Reading from /var/lib/cloud/instance/cloud-config.txt (quiet=False)
2025-02-04 15:13:27,153 - util.py[DEBUG]: Reading 0 bytes from /var/lib/cloud/instance/cloud-config.txt
2025-02-04 15:13:27,153 - util.py[DEBUG]: Attempting to load yaml from string of length 0 with allowed root types (<class 'dict'>,)
2025-02-04 15:13:27,153 - util.py[DEBUG]: loaded blob returned None, returning default.
2025-02-04 15:13:27,154 - atomic_helper.py[DEBUG]: Atomically writing to file /run/cloud-init/combined-cloud-config.json (via temporary file /run/cloud-init/tmpuw9mlwbv) - w: [600] 5471 bytes/chars
2025-02-04 15:13:27,154 - util.py[DEBUG]: Reading from /run/cloud-init/instance-data-sensitive.json (quiet=False)
2025-02-04 15:13:27,154 - util.py[DEBUG]: Reading 8726 bytes from /run/cloud-init/instance-data-sensitive.json
2025-02-04 15:13:27,155 - atomic_helper.py[DEBUG]: Atomically writing to file /run/cloud-init/instance-data-sensitive.json (via temporary file /run/cloud-init/tmpbb9u2eom) - w: [600] 10709 bytes/chars
2025-02-04 15:13:27,155 - main.py[DEBUG]: Skipping user-data validation. No user-data found.
2025-02-04 15:13:27,155 - util.py[DEBUG]: Reading from /var/lib/cloud/instance/cloud-config.txt (quiet=False)
2025-02-04 15:13:27,155 - util.py[DEBUG]: Reading 0 bytes from /var/lib/cloud/instance/cloud-config.txt
2025-02-04 15:13:27,155 - util.py[DEBUG]: Attempting to load yaml from string of length 0 with allowed root types (<class 'dict'>,)
2025-02-04 15:13:27,155 - util.py[DEBUG]: loaded blob returned None, returning default.
2025-02-04 15:13:27,157 - handlers.py[DEBUG]: start: init-network/activate-datasource: activating datasource
2025-02-04 15:13:27,158 - util.py[DEBUG]: Writing to /var/lib/cloud/instance/obj.pkl - wb: [400] 9370 bytes
2025-02-04 15:13:27,158 - handlers.py[DEBUG]: finish: init-network/activate-datasource: SUCCESS: activating datasource
2025-02-04 15:13:27,158 - main.py[DEBUG]: no di_report found in config.
2025-02-04 15:13:27,169 - stages.py[DEBUG]: Using distro class <class 'cloudinit.distros.ubuntu.Distro'>
2025-02-04 15:13:27,170 - modules.py[INFO]: Skipping modules 'bootcmd,write_files,disk_setup,update_etc_hosts,ca_certs,rsyslog' because no applicable config is provided.
2025-02-04 15:13:27,171 - modules.py[DEBUG]: Running module seed_random (<module 'cloudinit.config.cc_seed_random' from '/usr/lib/python3/dist-packages/cloudinit/config/cc_seed_random.py'>) with frequency once-per-instance
2025-02-04 15:13:27,171 - handlers.py[DEBUG]: start: init-network/config-seed_random: running config-seed_random with frequency once-per-instance
2025-02-04 15:13:27,171 - util.py[DEBUG]: Writing to /var/lib/cloud/instances/71308115/sem/config_seed_random - wb: [644] 24 bytes
2025-02-04 15:13:27,171 - helpers.py[DEBUG]: Running config-seed_random using lock (<FileLock using file '/var/lib/cloud/instances/71308115/sem/config_seed_random'>)
2025-02-04 15:13:27,171 - cc_seed_random.py[DEBUG]: no command provided
2025-02-04 15:13:27,171 - handlers.py[DEBUG]: finish: init-network/config-seed_random: SUCCESS: config-seed_random ran successfully and took 0.000 seconds
2025-02-04 15:13:27,171 - modules.py[DEBUG]: Running module growpart (<module 'cloudinit.config.cc_growpart' from '/usr/lib/python3/dist-packages/cloudinit/config/cc_growpart.py'>) with frequency always
2025-02-04 15:13:27,171 - handlers.py[DEBUG]: start: init-network/config-growpart: running config-growpart with frequency always
2025-02-04 15:13:27,172 - helpers.py[DEBUG]: Running config-growpart using lock (<cloudinit.helpers.DummyLock object at 0x7f3a1b1acb50>)
2025-02-04 15:13:27,172 - cc_growpart.py[DEBUG]: No 'growpart' entry in cfg.  Using default: {'mode': 'auto', 'devices': ['/'], 'ignore_growroot_disabled': False}
2025-02-04 15:13:27,172 - subp.py[DEBUG]: Running command ['growpart', '--help'] with allowed return codes [0] (shell=False, capture=True)
2025-02-04 15:13:27,174 - util.py[DEBUG]: Reading from /proc/567/mountinfo (quiet=False)
2025-02-04 15:13:27,174 - util.py[DEBUG]: Reading 2056 bytes from /proc/567/mountinfo
2025-02-04 15:13:27,174 - cc_growpart.py[DEBUG]: growpart found fs=ext4
2025-02-04 15:13:27,175 - cc_growpart.py[DEBUG]: '/' SKIPPED: device_part_info(/dev/sda) failed: /dev/sda not a partition
2025-02-04 15:13:27,175 - handlers.py[DEBUG]: finish: init-network/config-growpart: SUCCESS: config-growpart ran successfully and took 0.003 seconds
2025-02-04 15:13:27,175 - modules.py[DEBUG]: Running module resizefs (<module 'cloudinit.config.cc_resizefs' from '/usr/lib/python3/dist-packages/cloudinit/config/cc_resizefs.py'>) with frequency always
2025-02-04 15:13:27,175 - handlers.py[DEBUG]: start: init-network/config-resizefs: running config-resizefs with frequency always
2025-02-04 15:13:27,175 - helpers.py[DEBUG]: Running config-resizefs using lock (<cloudinit.helpers.DummyLock object at 0x7f3a1b1ac130>)
2025-02-04 15:13:27,175 - util.py[DEBUG]: Reading from /proc/567/mountinfo (quiet=False)
2025-02-04 15:13:27,175 - util.py[DEBUG]: Reading 2056 bytes from /proc/567/mountinfo
2025-02-04 15:13:27,175 - cc_resizefs.py[DEBUG]: resize_info: dev=/dev/sda mnt_point=/ path=/
2025-02-04 15:13:27,175 - cc_resizefs.py[DEBUG]: Resizing / (ext4) using resize2fs /dev/sda
2025-02-04 15:13:27,175 - subp.py[DEBUG]: Running command ('resize2fs', '/dev/sda') with allowed return codes [0] (shell=False, capture=True)
2025-02-04 15:13:27,190 - performance.py[DEBUG]: Running ('resize2fs', '/dev/sda') took 0.015 seconds
2025-02-04 15:13:27,190 - cc_resizefs.py[DEBUG]: Resized root filesystem (type=ext4, val=True)
2025-02-04 15:13:27,190 - handlers.py[DEBUG]: finish: init-network/config-resizefs: SUCCESS: config-resizefs ran successfully and took 0.015 seconds
2025-02-04 15:13:27,190 - modules.py[DEBUG]: Running module mounts (<module 'cloudinit.config.cc_mounts' from '/usr/lib/python3/dist-packages/cloudinit/config/cc_mounts.py'>) with frequency once-per-instance
2025-02-04 15:13:27,190 - handlers.py[DEBUG]: start: init-network/config-mounts: running config-mounts with frequency once-per-instance
2025-02-04 15:13:27,191 - util.py[DEBUG]: Writing to /var/lib/cloud/instances/71308115/sem/config_mounts - wb: [644] 23 bytes
2025-02-04 15:13:27,191 - helpers.py[DEBUG]: Running config-mounts using lock (<FileLock using file '/var/lib/cloud/instances/71308115/sem/config_mounts'>)
2025-02-04 15:13:27,191 - cc_mounts.py[DEBUG]: mounts configuration is []
2025-02-04 15:13:27,191 - util.py[DEBUG]: Reading from /etc/fstab (quiet=False)
2025-02-04 15:13:27,191 - util.py[DEBUG]: Reading 481 bytes from /etc/fstab
2025-02-04 15:13:27,192 - cc_mounts.py[DEBUG]: Attempting to determine the real name of ephemeral0
2025-02-04 15:13:27,192 - cc_mounts.py[DEBUG]: changed ephemeral0 => None
2025-02-04 15:13:27,192 - cc_mounts.py[DEBUG]: Ignoring nonexistent default named mount ephemeral0
2025-02-04 15:13:27,192 - cc_mounts.py[DEBUG]: Attempting to determine the real name of swap
2025-02-04 15:13:27,192 - cc_mounts.py[DEBUG]: changed swap => None
2025-02-04 15:13:27,192 - cc_mounts.py[DEBUG]: Ignoring nonexistent default named mount swap
2025-02-04 15:13:27,192 - cc_mounts.py[DEBUG]: no need to setup swap
2025-02-04 15:13:27,192 - cc_mounts.py[DEBUG]: No modifications to fstab needed
2025-02-04 15:13:27,192 - handlers.py[DEBUG]: finish: init-network/config-mounts: SUCCESS: config-mounts ran successfully and took 0.001 seconds
2025-02-04 15:13:27,192 - modules.py[DEBUG]: Running module set_hostname (<module 'cloudinit.config.cc_set_hostname' from '/usr/lib/python3/dist-packages/cloudinit/config/cc_set_hostname.py'>) with frequency once-per-instance
2025-02-04 15:13:27,192 - handlers.py[DEBUG]: start: init-network/config-set_hostname: running config-set_hostname with frequency once-per-instance
2025-02-04 15:13:27,192 - util.py[DEBUG]: Writing to /var/lib/cloud/instances/71308115/sem/config_set_hostname - wb: [644] 24 bytes
2025-02-04 15:13:27,193 - helpers.py[DEBUG]: Running config-set_hostname using lock (<FileLock using file '/var/lib/cloud/instances/71308115/sem/config_set_hostname'>)
2025-02-04 15:13:27,193 - util.py[DEBUG]: Reading from /etc/hosts (quiet=False)
2025-02-04 15:13:27,193 - util.py[DEBUG]: Reading 181 bytes from /etc/hosts
2025-02-04 15:13:27,193 - util.py[DEBUG]: Reading from /etc/hosts (quiet=False)
2025-02-04 15:13:27,193 - util.py[DEBUG]: Reading 181 bytes from /etc/hosts
2025-02-04 15:13:27,193 - cc_set_hostname.py[DEBUG]: Hostname is localhost. Let other services handle this.
2025-02-04 15:13:27,193 - handlers.py[DEBUG]: finish: init-network/config-set_hostname: SUCCESS: config-set_hostname ran successfully and took 0.001 seconds
2025-02-04 15:13:27,193 - modules.py[DEBUG]: Running module update_hostname (<module 'cloudinit.config.cc_update_hostname' from '/usr/lib/python3/dist-packages/cloudinit/config/cc_update_hostname.py'>) with frequency always
2025-02-04 15:13:27,193 - handlers.py[DEBUG]: start: init-network/config-update_hostname: running config-update_hostname with frequency always
2025-02-04 15:13:27,193 - helpers.py[DEBUG]: Running config-update_hostname using lock (<cloudinit.helpers.DummyLock object at 0x7f3a1b1ad930>)
2025-02-04 15:13:27,193 - util.py[DEBUG]: Reading from /etc/hosts (quiet=False)
2025-02-04 15:13:27,193 - util.py[DEBUG]: Reading 181 bytes from /etc/hosts
2025-02-04 15:13:27,193 - util.py[DEBUG]: Reading from /etc/hosts (quiet=False)
2025-02-04 15:13:27,193 - util.py[DEBUG]: Reading 181 bytes from /etc/hosts
2025-02-04 15:13:27,193 - cc_update_hostname.py[DEBUG]: Hostname is localhost. Let other services handle this.
2025-02-04 15:13:27,194 - handlers.py[DEBUG]: finish: init-network/config-update_hostname: SUCCESS: config-update_hostname ran successfully and took 0.000 seconds
2025-02-04 15:13:27,194 - modules.py[DEBUG]: Running module users_groups (<module 'cloudinit.config.cc_users_groups' from '/usr/lib/python3/dist-packages/cloudinit/config/cc_users_groups.py'>) with frequency once-per-instance
2025-02-04 15:13:27,194 - handlers.py[DEBUG]: start: init-network/config-users_groups: running config-users_groups with frequency once-per-instance
2025-02-04 15:13:27,194 - util.py[DEBUG]: Writing to /var/lib/cloud/instances/71308115/sem/config_users_groups - wb: [644] 24 bytes
2025-02-04 15:13:27,194 - helpers.py[DEBUG]: Running config-users_groups using lock (<FileLock using file '/var/lib/cloud/instances/71308115/sem/config_users_groups'>)
2025-02-04 15:13:27,197 - handlers.py[DEBUG]: finish: init-network/config-users_groups: SUCCESS: config-users_groups ran successfully and took 0.000 seconds
2025-02-04 15:13:27,197 - modules.py[DEBUG]: Running module ssh (<module 'cloudinit.config.cc_ssh' from '/usr/lib/python3/dist-packages/cloudinit/config/cc_ssh.py'>) with frequency once-per-instance
2025-02-04 15:13:27,197 - handlers.py[DEBUG]: start: init-network/config-ssh: running config-ssh with frequency once-per-instance
2025-02-04 15:13:27,197 - util.py[DEBUG]: Writing to /var/lib/cloud/instances/71308115/sem/config_ssh - wb: [644] 23 bytes
2025-02-04 15:13:27,198 - helpers.py[DEBUG]: Running config-ssh using lock (<FileLock using file '/var/lib/cloud/instances/71308115/sem/config_ssh'>)
2025-02-04 15:13:27,199 - util.py[DEBUG]: Reading from /proc/sys/crypto/fips_enabled (quiet=False)
2025-02-04 15:13:27,200 - subp.py[DEBUG]: Running command ['ssh-keygen', '-t', 'rsa', '-N', '', '-f', '/etc/ssh/ssh_host_rsa_key'] with allowed return codes [0] (shell=False, capture=True)
2025-02-04 15:13:27,510 - performance.py[DEBUG]: Running ['ssh-keygen', '-t', 'rsa', '-N', '', '-f', '/etc/ssh/ssh_host_rsa_key'] took 0.310 seconds
2025-02-04 15:13:27,510 - subp.py[DEBUG]: Running command ['ssh-keygen', '-t', 'ecdsa', '-N', '', '-f', '/etc/ssh/ssh_host_ecdsa_key'] with allowed return codes [0] (shell=False, capture=True)
2025-02-04 15:13:27,516 - subp.py[DEBUG]: Running command ['ssh-keygen', '-t', 'ed25519', '-N', '', '-f', '/etc/ssh/ssh_host_ed25519_key'] with allowed return codes [0] (shell=False, capture=True)
2025-02-04 15:13:27,522 - util.py[DEBUG]: Reading from /etc/ssh/ssh_host_rsa_key.pub (quiet=False)
2025-02-04 15:13:27,522 - util.py[DEBUG]: Reading 568 bytes from /etc/ssh/ssh_host_rsa_key.pub
2025-02-04 15:13:27,522 - util.py[DEBUG]: Reading from /etc/ssh/ssh_host_ed25519_key.pub (quiet=False)
2025-02-04 15:13:27,522 - util.py[DEBUG]: Reading 96 bytes from /etc/ssh/ssh_host_ed25519_key.pub
2025-02-04 15:13:27,522 - util.py[DEBUG]: Reading from /etc/ssh/ssh_host_ecdsa_key.pub (quiet=False)
2025-02-04 15:13:27,522 - util.py[DEBUG]: Reading 176 bytes from /etc/ssh/ssh_host_ecdsa_key.pub
2025-02-04 15:13:27,523 - util.py[DEBUG]: Reading from /etc/ssh/sshd_config (quiet=False)
2025-02-04 15:13:27,523 - util.py[DEBUG]: Reading 3237 bytes from /etc/ssh/sshd_config
2025-02-04 15:13:27,524 - util.py[DEBUG]: Reading from /root/.ssh/authorized_keys (quiet=False)
2025-02-04 15:13:27,524 - util.py[DEBUG]: Reading 1486 bytes from /root/.ssh/authorized_keys
2025-02-04 15:13:27,524 - util.py[DEBUG]: Writing to /root/.ssh/authorized_keys - wb: [600] 1487 bytes
2025-02-04 15:13:27,525 - handlers.py[DEBUG]: finish: init-network/config-ssh: SUCCESS: config-ssh ran successfully and took 0.328 seconds
2025-02-04 15:13:27,525 - modules.py[DEBUG]: Running module set_passwords (<module 'cloudinit.config.cc_set_passwords' from '/usr/lib/python3/dist-packages/cloudinit/config/cc_set_passwords.py'>) with frequency once-per-instance
2025-02-04 15:13:27,525 - handlers.py[DEBUG]: start: init-network/config-set_passwords: running config-set_passwords with frequency once-per-instance
2025-02-04 15:13:27,525 - util.py[DEBUG]: Writing to /var/lib/cloud/instances/71308115/sem/config_set_passwords - wb: [644] 24 bytes
2025-02-04 15:13:27,526 - helpers.py[DEBUG]: Running config-set_passwords using lock (<FileLock using file '/var/lib/cloud/instances/71308115/sem/config_set_passwords'>)
2025-02-04 15:13:27,526 - cc_set_passwords.py[DEBUG]: Leaving SSH config 'PasswordAuthentication' unchanged. ssh_pwauth=None
2025-02-04 15:13:27,526 - handlers.py[DEBUG]: finish: init-network/config-set_passwords: SUCCESS: config-set_passwords ran successfully and took 0.000 seconds
2025-02-04 15:13:27,526 - main.py[DEBUG]: Ran 9 modules with 0 failures
2025-02-04 15:13:27,526 - util.py[DEBUG]: Reading from /proc/uptime (quiet=False)
2025-02-04 15:13:27,526 - util.py[DEBUG]: Reading 11 bytes from /proc/uptime
2025-02-04 15:13:27,526 - atomic_helper.py[DEBUG]: Atomically writing to file /var/lib/cloud/data/status.json (via temporary file /var/lib/cloud/data/tmpdpn5s5gi) - w: [644] 505 bytes/chars
2025-02-04 15:13:27,527 - performance.py[DEBUG]: cloud-init stage: 'init-network' took 0.525 seconds
2025-02-04 15:13:27,527 - handlers.py[DEBUG]: finish: init-network: SUCCESS: searching for network datasources
2025-02-04 15:13:28,734 - log_util.py[DEBUG]: Cloud-init v. 24.4-0ubuntu1~22.04.1 running 'modules:config' at Tue, 04 Feb 2025 15:13:28 +0000. Up 15.82 seconds.
2025-02-04 15:13:28,734 - main.py[INFO]: PID [1] started cloud-init 'modules:config'.
2025-02-04 15:13:28,766 - stages.py[DEBUG]: Using distro class <class 'cloudinit.distros.ubuntu.Distro'>
2025-02-04 15:13:28,768 - modules.py[INFO]: Skipping modules 'wireguard,snap,ubuntu_autoinstall,keyboard,apt_pipelining,ubuntu_pro,ntp,timezone,disable_ec2_metadata,runcmd' because no applicable config is provided.
2025-02-04 15:13:28,768 - modules.py[DEBUG]: Running module ssh_import_id (<module 'cloudinit.config.cc_ssh_import_id' from '/usr/lib/python3/dist-packages/cloudinit/config/cc_ssh_import_id.py'>) with frequency once-per-instance
2025-02-04 15:13:28,769 - handlers.py[DEBUG]: start: modules-config/config-ssh_import_id: running config-ssh_import_id with frequency once-per-instance
2025-02-04 15:13:28,769 - util.py[DEBUG]: Writing to /var/lib/cloud/instances/71308115/sem/config_ssh_import_id - wb: [644] 24 bytes
2025-02-04 15:13:28,769 - helpers.py[DEBUG]: Running config-ssh_import_id using lock (<FileLock using file '/var/lib/cloud/instances/71308115/sem/config_ssh_import_id'>)
2025-02-04 15:13:28,769 - cc_ssh_import_id.py[DEBUG]: Skipping module named ssh_import_id, no 'ssh_import_id' directives found.
2025-02-04 15:13:28,769 - handlers.py[DEBUG]: finish: modules-config/config-ssh_import_id: SUCCESS: config-ssh_import_id ran successfully and took 0.001 seconds
2025-02-04 15:13:28,770 - modules.py[DEBUG]: Running module locale (<module 'cloudinit.config.cc_locale' from '/usr/lib/python3/dist-packages/cloudinit/config/cc_locale.py'>) with frequency once-per-instance
2025-02-04 15:13:28,770 - handlers.py[DEBUG]: start: modules-config/config-locale: running config-locale with frequency once-per-instance
2025-02-04 15:13:28,770 - util.py[DEBUG]: Writing to /var/lib/cloud/instances/71308115/sem/config_locale - wb: [644] 24 bytes
2025-02-04 15:13:28,770 - helpers.py[DEBUG]: Running config-locale using lock (<FileLock using file '/var/lib/cloud/instances/71308115/sem/config_locale'>)
2025-02-04 15:13:28,771 - util.py[DEBUG]: Reading from /etc/default/locale (quiet=False)
2025-02-04 15:13:28,771 - util.py[DEBUG]: Reading 52 bytes from /etc/default/locale
2025-02-04 15:13:28,772 - cc_locale.py[DEBUG]: Setting locale to en_US.UTF-8
2025-02-04 15:13:28,773 - debian.py[DEBUG]: System locale set to en_US.UTF-8 via /etc/default/locale
2025-02-04 15:13:28,774 - debian.py[DEBUG]: System has 'LANG=en_US.UTF-8' requested 'en_US.UTF-8', skipping regeneration.
2025-02-04 15:13:28,774 - handlers.py[DEBUG]: finish: modules-config/config-locale: SUCCESS: config-locale ran successfully and took 0.004 seconds
2025-02-04 15:13:28,774 - modules.py[DEBUG]: Running module grub_dpkg (<module 'cloudinit.config.cc_grub_dpkg' from '/usr/lib/python3/dist-packages/cloudinit/config/cc_grub_dpkg.py'>) with frequency once-per-instance
2025-02-04 15:13:28,775 - handlers.py[DEBUG]: start: modules-config/config-grub_dpkg: running config-grub_dpkg with frequency once-per-instance
2025-02-04 15:13:28,775 - util.py[DEBUG]: Writing to /var/lib/cloud/instances/71308115/sem/config_grub_dpkg - wb: [644] 22 bytes
2025-02-04 15:13:28,777 - helpers.py[DEBUG]: Running config-grub_dpkg using lock (<FileLock using file '/var/lib/cloud/instances/71308115/sem/config_grub_dpkg'>)
2025-02-04 15:13:28,777 - subp.py[DEBUG]: Running command ['grub-probe', '-t', 'disk', '/boot'] with allowed return codes [0] (shell=False, capture=True)
2025-02-04 15:13:28,790 - performance.py[DEBUG]: Running ['grub-probe', '-t', 'disk', '/boot'] took 0.012 seconds
2025-02-04 15:13:28,790 - subp.py[DEBUG]: Running command ['udevadm', 'info', '--root', '--query=symlink', '/dev/sda'] with allowed return codes [0] (shell=False, capture=True)
2025-02-04 15:13:28,798 - cc_grub_dpkg.py[DEBUG]: considering these device symlinks: /dev/disk/by-id/scsi-0QEMU_QEMU_HARDDISK_drive-scsi-disk-0,/dev/disk/by-uuid/c4b52a3f-818a-c891-ac4a-b949bf511e72,/dev/disk/by-label/linode-root,/dev/disk/by-path/pci-0000:00:02.0-scsi-0:0:0:0
2025-02-04 15:13:28,798 - cc_grub_dpkg.py[DEBUG]: filtered to these disk/by-id symlinks: /dev/disk/by-id/scsi-0QEMU_QEMU_HARDDISK_drive-scsi-disk-0
2025-02-04 15:13:28,798 - cc_grub_dpkg.py[DEBUG]: selected /dev/disk/by-id/scsi-0QEMU_QEMU_HARDDISK_drive-scsi-disk-0
2025-02-04 15:13:28,798 - cc_grub_dpkg.py[DEBUG]: Setting grub debconf-set-selections with 'grub-pc grub-pc/install_devices string /dev/disk/by-id/scsi-0QEMU_QEMU_HARDDISK_drive-scsi-disk-0
grub-pc grub-pc/install_devices_empty boolean false
'
2025-02-04 15:13:28,799 - subp.py[DEBUG]: Running command ['debconf-set-selections'] with allowed return codes [0] (shell=False, capture=True)
2025-02-04 15:13:28,964 - performance.py[DEBUG]: Running ['debconf-set-selections'] took 0.165 seconds
2025-02-04 15:13:28,964 - handlers.py[DEBUG]: finish: modules-config/config-grub_dpkg: SUCCESS: config-grub_dpkg ran successfully and took 0.189 seconds
2025-02-04 15:13:28,964 - modules.py[DEBUG]: Running module apt_configure (<module 'cloudinit.config.cc_apt_configure' from '/usr/lib/python3/dist-packages/cloudinit/config/cc_apt_configure.py'>) with frequency once-per-instance
2025-02-04 15:13:28,964 - handlers.py[DEBUG]: start: modules-config/config-apt_configure: running config-apt_configure with frequency once-per-instance
2025-02-04 15:13:28,965 - util.py[DEBUG]: Writing to /var/lib/cloud/instances/71308115/sem/config_apt_configure - wb: [644] 24 bytes
2025-02-04 15:13:28,965 - helpers.py[DEBUG]: Running config-apt_configure using lock (<FileLock using file '/var/lib/cloud/instances/71308115/sem/config_apt_configure'>)
2025-02-04 15:13:28,965 - cc_apt_configure.py[DEBUG]: debconf_selections was not set in config
2025-02-04 15:13:28,966 - cc_apt_configure.py[DEBUG]: handling apt config: {'preserve_sources_list': True}
2025-02-04 15:13:28,966 - subp.py[DEBUG]: Running command ['lsb_release', '--all'] with allowed return codes [0] (shell=False, capture=True)
2025-02-04 15:13:29,014 - performance.py[DEBUG]: Running ['lsb_release', '--all'] took 0.048 seconds
2025-02-04 15:13:29,015 - subp.py[DEBUG]: Running command ['dpkg', '--print-architecture'] with allowed return codes [0] (shell=False, capture=True)
2025-02-04 15:13:29,019 - cc_apt_configure.py[DEBUG]: got primary mirror: None
2025-02-04 15:13:29,019 - cc_apt_configure.py[DEBUG]: got security mirror: None
2025-02-04 15:13:29,019 - util.py[DEBUG]: search for mirror in candidates: '['http://es-mad.clouds.archive.ubuntu.com/ubuntu/']'
2025-02-04 15:13:29,023 - util.py[DEBUG]: found working mirror: 'http://es-mad.clouds.archive.ubuntu.com/ubuntu/'
2025-02-04 15:13:29,023 - util.py[DEBUG]: search for mirror in candidates: '[]'
2025-02-04 15:13:29,023 - distros[DEBUG]: filtered distro mirror info: {'primary': 'http://es-mad.clouds.archive.ubuntu.com/ubuntu/', 'security': 'http://security.ubuntu.com/ubuntu'}
2025-02-04 15:13:29,023 - cc_apt_configure.py[DEBUG]: Apt Mirror info: {'primary': 'http://es-mad.clouds.archive.ubuntu.com/ubuntu/', 'security': 'http://security.ubuntu.com/ubuntu', 'PRIMARY': 'http://es-mad.clouds.archive.ubuntu.com/ubuntu/', 'SECURITY': 'http://security.ubuntu.com/ubuntu', 'MIRROR': 'http://es-mad.clouds.archive.ubuntu.com/ubuntu/'}
2025-02-04 15:13:29,024 - handlers.py[DEBUG]: finish: modules-config/config-apt_configure: SUCCESS: config-apt_configure ran successfully and took 0.059 seconds
2025-02-04 15:13:29,024 - modules.py[DEBUG]: Running module byobu (<module 'cloudinit.config.cc_byobu' from '/usr/lib/python3/dist-packages/cloudinit/config/cc_byobu.py'>) with frequency once-per-instance
2025-02-04 15:13:29,024 - handlers.py[DEBUG]: start: modules-config/config-byobu: running config-byobu with frequency once-per-instance
2025-02-04 15:13:29,024 - util.py[DEBUG]: Writing to /var/lib/cloud/instances/71308115/sem/config_byobu - wb: [644] 24 bytes
2025-02-04 15:13:29,025 - helpers.py[DEBUG]: Running config-byobu using lock (<FileLock using file '/var/lib/cloud/instances/71308115/sem/config_byobu'>)
2025-02-04 15:13:29,025 - cc_byobu.py[DEBUG]: Skipping module named byobu, no 'byobu' values found
2025-02-04 15:13:29,025 - handlers.py[DEBUG]: finish: modules-config/config-byobu: SUCCESS: config-byobu ran successfully and took 0.001 seconds
2025-02-04 15:13:29,025 - main.py[DEBUG]: Ran 5 modules with 0 failures
2025-02-04 15:13:29,025 - util.py[DEBUG]: Reading from /proc/uptime (quiet=False)
2025-02-04 15:13:29,025 - util.py[DEBUG]: Reading 11 bytes from /proc/uptime
2025-02-04 15:13:29,025 - atomic_helper.py[DEBUG]: Atomically writing to file /var/lib/cloud/data/status.json (via temporary file /var/lib/cloud/data/tmpry80qdvd) - w: [644] 507 bytes/chars
2025-02-04 15:13:29,026 - performance.py[DEBUG]: cloud-init stage: 'modules-config' took 0.512 seconds
2025-02-04 15:13:29,026 - handlers.py[DEBUG]: finish: modules-config: SUCCESS: running modules for config
2025-02-04 15:13:29,405 - log_util.py[DEBUG]: Cloud-init v. 24.4-0ubuntu1~22.04.1 running 'modules:final' at Tue, 04 Feb 2025 15:13:29 +0000. Up 16.57 seconds.
2025-02-04 15:13:29,405 - main.py[INFO]: PID [1] started cloud-init 'modules:final'.
2025-02-04 15:13:29,425 - stages.py[DEBUG]: Using distro class <class 'cloudinit.distros.ubuntu.Distro'>
2025-02-04 15:13:29,428 - modules.py[INFO]: Skipping modules 'package_update_upgrade_install,fan,landscape,lxd,ubuntu_drivers,write_files_deferred,puppet,chef,ansible,mcollective,salt_minion,phone_home,power_state_change' because no applicable config is provided.
2025-02-04 15:13:29,428 - modules.py[DEBUG]: Running module reset_rmc (<module 'cloudinit.config.cc_reset_rmc' from '/usr/lib/python3/dist-packages/cloudinit/config/cc_reset_rmc.py'>) with frequency once-per-instance
2025-02-04 15:13:29,428 - handlers.py[DEBUG]: start: modules-final/config-reset_rmc: running config-reset_rmc with frequency once-per-instance
2025-02-04 15:13:29,429 - util.py[DEBUG]: Writing to /var/lib/cloud/instances/71308115/sem/config_reset_rmc - wb: [644] 24 bytes
2025-02-04 15:13:29,429 - helpers.py[DEBUG]: Running config-reset_rmc using lock (<FileLock using file '/var/lib/cloud/instances/71308115/sem/config_reset_rmc'>)
2025-02-04 15:13:29,429 - cc_reset_rmc.py[DEBUG]: module disabled, RSCT_PATH not present
2025-02-04 15:13:29,429 - handlers.py[DEBUG]: finish: modules-final/config-reset_rmc: SUCCESS: config-reset_rmc ran successfully and took 0.001 seconds
2025-02-04 15:13:29,429 - modules.py[DEBUG]: Running module scripts_vendor (<module 'cloudinit.config.cc_scripts_vendor' from '/usr/lib/python3/dist-packages/cloudinit/config/cc_scripts_vendor.py'>) with frequency once-per-instance
2025-02-04 15:13:29,430 - handlers.py[DEBUG]: start: modules-final/config-scripts_vendor: running config-scripts_vendor with frequency once-per-instance
2025-02-04 15:13:29,430 - util.py[DEBUG]: Writing to /var/lib/cloud/instances/71308115/sem/config_scripts_vendor - wb: [644] 24 bytes
2025-02-04 15:13:29,430 - helpers.py[DEBUG]: Running config-scripts_vendor using lock (<FileLock using file '/var/lib/cloud/instances/71308115/sem/config_scripts_vendor'>)
2025-02-04 15:13:29,430 - handlers.py[DEBUG]: finish: modules-final/config-scripts_vendor: SUCCESS: config-scripts_vendor ran successfully and took 0.000 seconds
2025-02-04 15:13:29,430 - modules.py[DEBUG]: Running module scripts_per_once (<module 'cloudinit.config.cc_scripts_per_once' from '/usr/lib/python3/dist-packages/cloudinit/config/cc_scripts_per_once.py'>) with frequency once
2025-02-04 15:13:29,430 - handlers.py[DEBUG]: start: modules-final/config-scripts_per_once: running config-scripts_per_once with frequency once
2025-02-04 15:13:29,431 - util.py[DEBUG]: Writing to /var/lib/cloud/sem/config_scripts_per_once.once - wb: [644] 24 bytes
2025-02-04 15:13:29,431 - helpers.py[DEBUG]: Running config-scripts_per_once using lock (<FileLock using file '/var/lib/cloud/sem/config_scripts_per_once.once'>)
2025-02-04 15:13:29,431 - handlers.py[DEBUG]: finish: modules-final/config-scripts_per_once: SUCCESS: config-scripts_per_once ran successfully and took 0.000 seconds
2025-02-04 15:13:29,431 - modules.py[DEBUG]: Running module scripts_per_boot (<module 'cloudinit.config.cc_scripts_per_boot' from '/usr/lib/python3/dist-packages/cloudinit/config/cc_scripts_per_boot.py'>) with frequency always
2025-02-04 15:13:29,431 - handlers.py[DEBUG]: start: modules-final/config-scripts_per_boot: running config-scripts_per_boot with frequency always
2025-02-04 15:13:29,431 - helpers.py[DEBUG]: Running config-scripts_per_boot using lock (<cloudinit.helpers.DummyLock object at 0x7f42fbddb6d0>)
2025-02-04 15:13:29,431 - handlers.py[DEBUG]: finish: modules-final/config-scripts_per_boot: SUCCESS: config-scripts_per_boot ran successfully and took 0.000 seconds
2025-02-04 15:13:29,431 - modules.py[DEBUG]: Running module scripts_per_instance (<module 'cloudinit.config.cc_scripts_per_instance' from '/usr/lib/python3/dist-packages/cloudinit/config/cc_scripts_per_instance.py'>) with frequency once-per-instance
2025-02-04 15:13:29,432 - handlers.py[DEBUG]: start: modules-final/config-scripts_per_instance: running config-scripts_per_instance with frequency once-per-instance
2025-02-04 15:13:29,432 - util.py[DEBUG]: Writing to /var/lib/cloud/instances/71308115/sem/config_scripts_per_instance - wb: [644] 24 bytes
2025-02-04 15:13:29,432 - helpers.py[DEBUG]: Running config-scripts_per_instance using lock (<FileLock using file '/var/lib/cloud/instances/71308115/sem/config_scripts_per_instance'>)
2025-02-04 15:13:29,432 - handlers.py[DEBUG]: finish: modules-final/config-scripts_per_instance: SUCCESS: config-scripts_per_instance ran successfully and took 0.000 seconds
2025-02-04 15:13:29,432 - modules.py[DEBUG]: Running module scripts_user (<module 'cloudinit.config.cc_scripts_user' from '/usr/lib/python3/dist-packages/cloudinit/config/cc_scripts_user.py'>) with frequency once-per-instance
2025-02-04 15:13:29,432 - handlers.py[DEBUG]: start: modules-final/config-scripts_user: running config-scripts_user with frequency once-per-instance
2025-02-04 15:13:29,432 - util.py[DEBUG]: Writing to /var/lib/cloud/instances/71308115/sem/config_scripts_user - wb: [644] 24 bytes
2025-02-04 15:13:29,433 - helpers.py[DEBUG]: Running config-scripts_user using lock (<FileLock using file '/var/lib/cloud/instances/71308115/sem/config_scripts_user'>)
2025-02-04 15:13:29,433 - handlers.py[DEBUG]: finish: modules-final/config-scripts_user: SUCCESS: config-scripts_user ran successfully and took 0.000 seconds
2025-02-04 15:13:29,433 - modules.py[DEBUG]: Running module ssh_authkey_fingerprints (<module 'cloudinit.config.cc_ssh_authkey_fingerprints' from '/usr/lib/python3/dist-packages/cloudinit/config/cc_ssh_authkey_fingerprints.py'>) with frequency once-per-instance
2025-02-04 15:13:29,433 - handlers.py[DEBUG]: start: modules-final/config-ssh_authkey_fingerprints: running config-ssh_authkey_fingerprints with frequency once-per-instance
2025-02-04 15:13:29,433 - util.py[DEBUG]: Writing to /var/lib/cloud/instances/71308115/sem/config_ssh_authkey_fingerprints - wb: [644] 24 bytes
2025-02-04 15:13:29,434 - helpers.py[DEBUG]: Running config-ssh_authkey_fingerprints using lock (<FileLock using file '/var/lib/cloud/instances/71308115/sem/config_ssh_authkey_fingerprints'>)
2025-02-04 15:13:29,434 - handlers.py[DEBUG]: finish: modules-final/config-ssh_authkey_fingerprints: SUCCESS: config-ssh_authkey_fingerprints ran successfully and took 0.000 seconds
2025-02-04 15:13:29,434 - modules.py[DEBUG]: Running module keys_to_console (<module 'cloudinit.config.cc_keys_to_console' from '/usr/lib/python3/dist-packages/cloudinit/config/cc_keys_to_console.py'>) with frequency once-per-instance
2025-02-04 15:13:29,434 - handlers.py[DEBUG]: start: modules-final/config-keys_to_console: running config-keys_to_console with frequency once-per-instance
2025-02-04 15:13:29,434 - util.py[DEBUG]: Writing to /var/lib/cloud/instances/71308115/sem/config_keys_to_console - wb: [644] 24 bytes
2025-02-04 15:13:29,434 - helpers.py[DEBUG]: Running config-keys_to_console using lock (<FileLock using file '/var/lib/cloud/instances/71308115/sem/config_keys_to_console'>)
2025-02-04 15:13:29,435 - subp.py[DEBUG]: Running command ['/usr/lib/cloud-init/write-ssh-key-fingerprints', '', ''] with allowed return codes [0] (shell=False, capture=True)
2025-02-04 15:13:29,464 - performance.py[DEBUG]: Running ['/usr/lib/cloud-init/write-ssh-key-fingerprints', '', ''] took 0.029 seconds
2025-02-04 15:13:29,485 - performance.py[DEBUG]: Writing to console took 0.021 seconds
2025-02-04 15:13:29,485 - handlers.py[DEBUG]: finish: modules-final/config-keys_to_console: SUCCESS: config-keys_to_console ran successfully and took 0.051 seconds
2025-02-04 15:13:29,485 - modules.py[DEBUG]: Running module install_hotplug (<module 'cloudinit.config.cc_install_hotplug' from '/usr/lib/python3/dist-packages/cloudinit/config/cc_install_hotplug.py'>) with frequency once-per-instance
2025-02-04 15:13:29,485 - handlers.py[DEBUG]: start: modules-final/config-install_hotplug: running config-install_hotplug with frequency once-per-instance
2025-02-04 15:13:29,485 - util.py[DEBUG]: Writing to /var/lib/cloud/instances/71308115/sem/config_install_hotplug - wb: [644] 24 bytes
2025-02-04 15:13:29,486 - helpers.py[DEBUG]: Running config-install_hotplug using lock (<FileLock using file '/var/lib/cloud/instances/71308115/sem/config_install_hotplug'>)
2025-02-04 15:13:29,486 - util.py[DEBUG]: Reading from /var/lib/cloud/hotplug.enabled (quiet=False)
2025-02-04 15:13:29,486 - util.py[DEBUG]: File not found: /var/lib/cloud/hotplug.enabled
2025-02-04 15:13:29,486 - stages.py[DEBUG]: Allowed events: {<EventScope.NETWORK: 'network'>: {<EventType.BOOT_NEW_INSTANCE: 'boot-new-instance'>}}
2025-02-04 15:13:29,486 - stages.py[DEBUG]: Event Denied: scopes=['network'] EventType=hotplug
2025-02-04 15:13:29,486 - cc_install_hotplug.py[DEBUG]: Skipping hotplug install, not enabled
2025-02-04 15:13:29,486 - handlers.py[DEBUG]: finish: modules-final/config-install_hotplug: SUCCESS: config-install_hotplug ran successfully and took 0.001 seconds
2025-02-04 15:13:29,486 - modules.py[DEBUG]: Running module final_message (<module 'cloudinit.config.cc_final_message' from '/usr/lib/python3/dist-packages/cloudinit/config/cc_final_message.py'>) with frequency always
2025-02-04 15:13:29,487 - handlers.py[DEBUG]: start: modules-final/config-final_message: running config-final_message with frequency always
2025-02-04 15:13:29,487 - helpers.py[DEBUG]: Running config-final_message using lock (<cloudinit.helpers.DummyLock object at 0x7f42fbddbdc0>)
2025-02-04 15:13:29,487 - util.py[DEBUG]: Reading from /proc/uptime (quiet=False)
2025-02-04 15:13:29,487 - util.py[DEBUG]: Reading 11 bytes from /proc/uptime
2025-02-04 15:13:29,494 - log_util.py[DEBUG]: Cloud-init v. 24.4-0ubuntu1~22.04.1 finished at Tue, 04 Feb 2025 15:13:29 +0000. Datasource DataSourceAkamaiLocal.  Up 16.71 seconds
2025-02-04 15:13:29,494 - util.py[DEBUG]: Writing to /var/lib/cloud/instance/boot-finished - wb: [644] 67 bytes
2025-02-04 15:13:29,495 - handlers.py[DEBUG]: finish: modules-final/config-final_message: SUCCESS: config-final_message ran successfully and took 0.008 seconds
2025-02-04 15:13:29,495 - main.py[DEBUG]: Ran 10 modules with 0 failures
2025-02-04 15:13:29,495 - util.py[DEBUG]: Reading from /proc/uptime (quiet=False)
2025-02-04 15:13:29,495 - util.py[DEBUG]: Reading 11 bytes from /proc/uptime
2025-02-04 15:13:29,495 - atomic_helper.py[DEBUG]: Atomically writing to file /var/lib/cloud/data/status.json (via temporary file /var/lib/cloud/data/tmp4t28no6k) - w: [644] 509 bytes/chars
2025-02-04 15:13:29,495 - atomic_helper.py[DEBUG]: Atomically writing to file /var/lib/cloud/data/result.json (via temporary file /var/lib/cloud/data/tmpmtp71fn1) - w: [644] 72 bytes/chars
2025-02-04 15:13:29,496 - util.py[DEBUG]: Creating symbolic link from '/run/cloud-init/result.json' => '../../var/lib/cloud/data/result.json'
2025-02-04 15:13:29,496 - performance.py[DEBUG]: cloud-init stage: 'modules-final' took 0.178 seconds
2025-02-04 15:13:29,496 - handlers.py[DEBUG]: finish: modules-final: SUCCESS: running modules for final
2025-02-04 17:08:45,677 - log_util.py[DEBUG]: Cloud-init v. 24.4-0ubuntu1~22.04.1 running 'init-local' at Tue, 04 Feb 2025 17:08:45 +0000. Up 5.82 seconds.
2025-02-04 17:08:45,678 - main.py[INFO]: PID [1] started cloud-init 'init-local'.
2025-02-04 17:08:45,678 - main.py[DEBUG]: No kernel command line url found.
2025-02-04 17:08:45,678 - main.py[DEBUG]: Closing stdin
2025-02-04 17:08:45,683 - util.py[DEBUG]: Writing to /var/log/cloud-init.log - ab: [640] 0 bytes
2025-02-04 17:08:45,683 - util.py[DEBUG]: Changing the ownership of /var/log/cloud-init.log to 104:4
2025-02-04 17:08:45,683 - util.py[DEBUG]: Reading from /var/lib/cloud/data/python-version (quiet=False)
2025-02-04 17:08:45,689 - util.py[DEBUG]: Reading 4 bytes from /var/lib/cloud/data/python-version
2025-02-04 17:08:45,689 - util.py[DEBUG]: Attempting to remove /var/lib/cloud/instance/boot-finished
2025-02-04 17:08:45,689 - handlers.py[DEBUG]: start: init-local/check-cache: attempting to read from cache [check]
2025-02-04 17:08:45,689 - util.py[DEBUG]: Reading from /var/lib/cloud/instance/obj.pkl (quiet=False)
2025-02-04 17:08:45,691 - util.py[DEBUG]: Reading 9370 bytes from /var/lib/cloud/instance/obj.pkl
2025-02-04 17:08:45,699 - dmi.py[DEBUG]: querying dmi data /sys/class/dmi/id/product_serial
2025-02-04 17:08:45,699 - stages.py[DEBUG]: restored from checked cache: DataSourceAkamaiLocal
2025-02-04 17:08:45,699 - handlers.py[DEBUG]: finish: init-local/check-cache: SUCCESS: restored from checked cache: DataSourceAkamaiLocal
2025-02-04 17:08:45,700 - util.py[DEBUG]: Reading from /etc/cloud/cloud.cfg (quiet=False)
2025-02-04 17:08:45,700 - util.py[DEBUG]: Reading 3766 bytes from /etc/cloud/cloud.cfg
2025-02-04 17:08:45,700 - util.py[DEBUG]: Attempting to load yaml from string of length 3766 with allowed root types (<class 'dict'>,)
2025-02-04 17:08:45,725 - util.py[DEBUG]: Reading from /etc/cloud/cloud.cfg.d/99-linode.cfg (quiet=False)
2025-02-04 17:08:45,725 - util.py[DEBUG]: Reading 492 bytes from /etc/cloud/cloud.cfg.d/99-linode.cfg
2025-02-04 17:08:45,725 - util.py[DEBUG]: Attempting to load yaml from string of length 492 with allowed root types (<class 'dict'>,)
2025-02-04 17:08:45,731 - util.py[DEBUG]: Reading from /etc/cloud/cloud.cfg.d/90_dpkg.cfg (quiet=False)
2025-02-04 17:08:45,731 - util.py[DEBUG]: Reading 333 bytes from /etc/cloud/cloud.cfg.d/90_dpkg.cfg
2025-02-04 17:08:45,731 - util.py[DEBUG]: Attempting to load yaml from string of length 333 with allowed root types (<class 'dict'>,)
2025-02-04 17:08:45,733 - util.py[DEBUG]: Reading from /etc/cloud/cloud.cfg.d/05_logging.cfg (quiet=False)
2025-02-04 17:08:45,733 - util.py[DEBUG]: Reading 2071 bytes from /etc/cloud/cloud.cfg.d/05_logging.cfg
2025-02-04 17:08:45,733 - util.py[DEBUG]: Attempting to load yaml from string of length 2071 with allowed root types (<class 'dict'>,)
2025-02-04 17:08:45,740 - util.py[DEBUG]: Reading from /run/cloud-init/cloud.cfg (quiet=False)
2025-02-04 17:08:45,740 - util.py[DEBUG]: Reading 34 bytes from /run/cloud-init/cloud.cfg
2025-02-04 17:08:45,740 - util.py[DEBUG]: Attempting to load yaml from string of length 34 with allowed root types (<class 'dict'>,)
2025-02-04 17:08:45,741 - util.py[DEBUG]: Attempting to load yaml from string of length 0 with allowed root types (<class 'dict'>,)
2025-02-04 17:08:45,741 - util.py[DEBUG]: loaded blob returned None, returning default.
2025-02-04 17:08:45,741 - util.py[DEBUG]: Reading from /var/lib/cloud/instance/cloud-config.txt (quiet=False)
2025-02-04 17:08:45,741 - util.py[DEBUG]: Reading 0 bytes from /var/lib/cloud/instance/cloud-config.txt
2025-02-04 17:08:45,741 - util.py[DEBUG]: Attempting to load yaml from string of length 0 with allowed root types (<class 'dict'>,)
2025-02-04 17:08:45,742 - util.py[DEBUG]: loaded blob returned None, returning default.
2025-02-04 17:08:45,746 - util.py[DEBUG]: Reading from /etc/hosts (quiet=False)
2025-02-04 17:08:45,746 - util.py[DEBUG]: Reading 181 bytes from /etc/hosts
2025-02-04 17:08:45,748 - util.py[DEBUG]: Writing to /run/cloud-init/cloud-id-akamai - wb: [644] 7 bytes
2025-02-04 17:08:45,748 - util.py[DEBUG]: Creating symbolic link from '/run/cloud-init/cloud-id' => '/run/cloud-init/cloud-id-akamai'
2025-02-04 17:08:45,748 - atomic_helper.py[DEBUG]: Atomically writing to file /run/cloud-init/instance-data-sensitive.json (via temporary file /run/cloud-init/tmpoxm6bict) - w: [600] 8726 bytes/chars
2025-02-04 17:08:45,749 - atomic_helper.py[DEBUG]: Atomically writing to file /run/cloud-init/instance-data.json (via temporary file /run/cloud-init/tmpm3mrxj2k) - w: [644] 1941 bytes/chars
2025-02-04 17:08:45,749 - stages.py[INFO]: Instance link already exists, not recreating it.
2025-02-04 17:08:45,750 - util.py[DEBUG]: Reading from /var/lib/cloud/instances/71308115/datasource (quiet=False)
2025-02-04 17:08:45,754 - util.py[DEBUG]: Reading 45 bytes from /var/lib/cloud/instances/71308115/datasource
2025-02-04 17:08:45,754 - util.py[DEBUG]: Writing to /var/lib/cloud/instances/71308115/datasource - wb: [644] 45 bytes
2025-02-04 17:08:45,755 - util.py[DEBUG]: Writing to /var/lib/cloud/data/previous-datasource - wb: [644] 45 bytes
2025-02-04 17:08:45,755 - util.py[DEBUG]: Reading from /var/lib/cloud/data/instance-id (quiet=False)
2025-02-04 17:08:45,756 - util.py[DEBUG]: Reading 9 bytes from /var/lib/cloud/data/instance-id
2025-02-04 17:08:45,756 - stages.py[DEBUG]: previous iid found to be 71308115
2025-02-04 17:08:45,756 - util.py[DEBUG]: Writing to /var/lib/cloud/data/instance-id - wb: [644] 9 bytes
2025-02-04 17:08:45,756 - util.py[DEBUG]: Writing to /run/cloud-init/.instance-id - wb: [644] 9 bytes
2025-02-04 17:08:45,757 - util.py[DEBUG]: Writing to /var/lib/cloud/data/previous-instance-id - wb: [644] 9 bytes
2025-02-04 17:08:45,757 - util.py[DEBUG]: Writing to /var/lib/cloud/instance/obj.pkl - wb: [400] 9381 bytes
2025-02-04 17:08:45,760 - stages.py[INFO]: Not re-loading configuration, instance id and datasource have not changed.
2025-02-04 17:08:45,760 - main.py[DEBUG]: [local] init will now be targeting instance id: 71308115. new=False
2025-02-04 17:08:45,760 - stages.py[DEBUG]: Using distro class <class 'cloudinit.distros.ubuntu.Distro'>
2025-02-04 17:08:45,761 - util.py[DEBUG]: Reading from /sys/class/net/eth0/address (quiet=False)
2025-02-04 17:08:45,761 - util.py[DEBUG]: Reading 18 bytes from /sys/class/net/eth0/address
2025-02-04 17:08:45,761 - util.py[DEBUG]: Reading from /sys/class/net/lo/address (quiet=False)
2025-02-04 17:08:45,762 - util.py[DEBUG]: Reading 18 bytes from /sys/class/net/lo/address
2025-02-04 17:08:45,762 - stages.py[DEBUG]: network config disabled by system_cfg
2025-02-04 17:08:45,762 - stages.py[INFO]: network config is disabled by system_cfg
2025-02-04 17:08:45,762 - main.py[DEBUG]: Network connectivity determined unnecessary for cloud-init's network stage. Reason: user data: no configuration found, vendor data: no configuration found, vendor data2: no configuration found
2025-02-04 17:08:45,762 - util.py[DEBUG]: Writing to /run/cloud-init/.skip-network - wb: [644] 0 bytes
2025-02-04 17:08:45,765 - main.py[DEBUG]: [local] Exiting. datasource DataSourceAkamaiLocal not in local mode.
2025-02-04 17:08:45,765 - util.py[DEBUG]: Reading from /proc/uptime (quiet=False)
2025-02-04 17:08:45,765 - util.py[DEBUG]: Reading 10 bytes from /proc/uptime
2025-02-04 17:08:45,765 - atomic_helper.py[DEBUG]: Atomically writing to file /var/lib/cloud/data/status.json (via temporary file /var/lib/cloud/data/tmpzg41ddwt) - w: [644] 502 bytes/chars
2025-02-04 17:08:45,765 - performance.py[DEBUG]: cloud-init stage: 'init-local' took 0.212 seconds
2025-02-04 17:08:45,766 - handlers.py[DEBUG]: finish: init-local: SUCCESS: searching for local datasources
2025-02-04 17:08:50,993 - log_util.py[DEBUG]: Cloud-init v. 24.4-0ubuntu1~22.04.1 running 'init' at Tue, 04 Feb 2025 17:08:50 +0000. Up 11.16 seconds.
2025-02-04 17:08:50,993 - main.py[INFO]: PID [1] started cloud-init 'init'.
2025-02-04 17:08:50,993 - main.py[DEBUG]: No kernel command line url found.
2025-02-04 17:08:50,994 - main.py[DEBUG]: Closing stdin
2025-02-04 17:08:50,996 - util.py[DEBUG]: Writing to /var/log/cloud-init.log - ab: [640] 0 bytes
2025-02-04 17:08:50,996 - util.py[DEBUG]: Changing the ownership of /var/log/cloud-init.log to 104:4
2025-02-04 17:08:50,996 - util.py[DEBUG]: Reading from /var/lib/cloud/data/python-version (quiet=False)
2025-02-04 17:08:50,996 - util.py[DEBUG]: Reading 4 bytes from /var/lib/cloud/data/python-version
2025-02-04 17:08:50,997 - subp.py[DEBUG]: Running command ['ip', '--json', 'addr'] with allowed return codes [0] (shell=False, capture=True)
2025-02-04 17:08:51,008 - performance.py[DEBUG]: Running ['ip', '--json', 'addr'] took 0.012 seconds
2025-02-04 17:08:51,009 - subp.py[DEBUG]: Running command ['ip', '-o', 'route', 'list'] with allowed return codes [0] (shell=False, capture=True)
2025-02-04 17:08:51,011 - subp.py[DEBUG]: Running command ['ip', '--oneline', '-6', 'route', 'list', 'table', 'all'] with allowed return codes [0, 1] (shell=False, capture=True)
2025-02-04 17:08:51,013 - handlers.py[DEBUG]: start: init-network/check-cache: attempting to read from cache [trust]
2025-02-04 17:08:51,013 - util.py[DEBUG]: Reading from /var/lib/cloud/instance/obj.pkl (quiet=False)
2025-02-04 17:08:51,013 - util.py[DEBUG]: Reading 9381 bytes from /var/lib/cloud/instance/obj.pkl
2025-02-04 17:08:51,021 - util.py[DEBUG]: Reading from /run/cloud-init/.instance-id (quiet=False)
2025-02-04 17:08:51,021 - util.py[DEBUG]: Reading 9 bytes from /run/cloud-init/.instance-id
2025-02-04 17:08:51,021 - stages.py[DEBUG]: restored from cache with run check: DataSourceAkamaiLocal
2025-02-04 17:08:51,021 - handlers.py[DEBUG]: finish: init-network/check-cache: SUCCESS: restored from cache with run check: DataSourceAkamaiLocal
2025-02-04 17:08:51,022 - util.py[DEBUG]: Reading from /etc/cloud/cloud.cfg (quiet=False)
2025-02-04 17:08:51,022 - util.py[DEBUG]: Reading 3766 bytes from /etc/cloud/cloud.cfg
2025-02-04 17:08:51,022 - util.py[DEBUG]: Attempting to load yaml from string of length 3766 with allowed root types (<class 'dict'>,)
2025-02-04 17:08:51,051 - util.py[DEBUG]: Reading from /etc/cloud/cloud.cfg.d/99-linode.cfg (quiet=False)
2025-02-04 17:08:51,051 - util.py[DEBUG]: Reading 492 bytes from /etc/cloud/cloud.cfg.d/99-linode.cfg
2025-02-04 17:08:51,051 - util.py[DEBUG]: Attempting to load yaml from string of length 492 with allowed root types (<class 'dict'>,)
2025-02-04 17:08:51,052 - util.py[DEBUG]: Reading from /etc/cloud/cloud.cfg.d/90_dpkg.cfg (quiet=False)
2025-02-04 17:08:51,053 - util.py[DEBUG]: Reading 333 bytes from /etc/cloud/cloud.cfg.d/90_dpkg.cfg
2025-02-04 17:08:51,053 - util.py[DEBUG]: Attempting to load yaml from string of length 333 with allowed root types (<class 'dict'>,)
2025-02-04 17:08:51,060 - util.py[DEBUG]: Reading from /etc/cloud/cloud.cfg.d/05_logging.cfg (quiet=False)
2025-02-04 17:08:51,060 - util.py[DEBUG]: Reading 2071 bytes from /etc/cloud/cloud.cfg.d/05_logging.cfg
2025-02-04 17:08:51,060 - util.py[DEBUG]: Attempting to load yaml from string of length 2071 with allowed root types (<class 'dict'>,)
2025-02-04 17:08:51,065 - util.py[DEBUG]: Reading from /run/cloud-init/cloud.cfg (quiet=False)
2025-02-04 17:08:51,065 - util.py[DEBUG]: Reading 34 bytes from /run/cloud-init/cloud.cfg
2025-02-04 17:08:51,065 - util.py[DEBUG]: Attempting to load yaml from string of length 34 with allowed root types (<class 'dict'>,)
2025-02-04 17:08:51,066 - util.py[DEBUG]: Attempting to load yaml from string of length 0 with allowed root types (<class 'dict'>,)
2025-02-04 17:08:51,066 - util.py[DEBUG]: loaded blob returned None, returning default.
2025-02-04 17:08:51,070 - util.py[DEBUG]: Reading from /var/lib/cloud/instance/cloud-config.txt (quiet=False)
2025-02-04 17:08:51,070 - util.py[DEBUG]: Reading 0 bytes from /var/lib/cloud/instance/cloud-config.txt
2025-02-04 17:08:51,070 - util.py[DEBUG]: Attempting to load yaml from string of length 0 with allowed root types (<class 'dict'>,)
2025-02-04 17:08:51,070 - util.py[DEBUG]: loaded blob returned None, returning default.
2025-02-04 17:08:51,070 - stages.py[INFO]: Instance link already exists, not recreating it.
2025-02-04 17:08:51,071 - util.py[DEBUG]: Reading from /var/lib/cloud/instances/71308115/datasource (quiet=False)
2025-02-04 17:08:51,071 - util.py[DEBUG]: Reading 45 bytes from /var/lib/cloud/instances/71308115/datasource
2025-02-04 17:08:51,071 - util.py[DEBUG]: Writing to /var/lib/cloud/instances/71308115/datasource - wb: [644] 45 bytes
2025-02-04 17:08:51,073 - util.py[DEBUG]: Writing to /var/lib/cloud/data/previous-datasource - wb: [644] 45 bytes
2025-02-04 17:08:51,073 - util.py[DEBUG]: Reading from /var/lib/cloud/data/instance-id (quiet=False)
2025-02-04 17:08:51,074 - util.py[DEBUG]: Reading 9 bytes from /var/lib/cloud/data/instance-id
2025-02-04 17:08:51,074 - stages.py[DEBUG]: previous iid found to be 71308115
2025-02-04 17:08:51,074 - util.py[DEBUG]: Writing to /var/lib/cloud/data/instance-id - wb: [644] 9 bytes
2025-02-04 17:08:51,074 - util.py[DEBUG]: Writing to /run/cloud-init/.instance-id - wb: [644] 9 bytes
2025-02-04 17:08:51,074 - util.py[DEBUG]: Writing to /var/lib/cloud/data/previous-instance-id - wb: [644] 9 bytes
2025-02-04 17:08:51,077 - util.py[DEBUG]: Writing to /var/lib/cloud/instance/obj.pkl - wb: [400] 9381 bytes
2025-02-04 17:08:51,077 - stages.py[INFO]: Not re-loading configuration, instance id and datasource have not changed.
2025-02-04 17:08:51,077 - main.py[DEBUG]: [net] init will now be targeting instance id: 71308115. new=False
2025-02-04 17:08:51,078 - util.py[DEBUG]: Reading from /sys/class/net/eth0/address (quiet=False)
2025-02-04 17:08:51,078 - util.py[DEBUG]: Reading 18 bytes from /sys/class/net/eth0/address
2025-02-04 17:08:51,078 - util.py[DEBUG]: Reading from /sys/class/net/lo/address (quiet=False)
2025-02-04 17:08:51,078 - util.py[DEBUG]: Reading 18 bytes from /sys/class/net/lo/address
2025-02-04 17:08:51,080 - stages.py[DEBUG]: network config disabled by system_cfg
2025-02-04 17:08:51,080 - stages.py[INFO]: network config is disabled by system_cfg
2025-02-04 17:08:51,080 - handlers.py[DEBUG]: start: init-network/setup-datasource: setting up datasource
2025-02-04 17:08:51,080 - handlers.py[DEBUG]: finish: init-network/setup-datasource: SUCCESS: setting up datasource
2025-02-04 17:08:51,080 - util.py[DEBUG]: Writing to /var/lib/cloud/instances/71308115/user-data.txt - wb: [600] 0 bytes
2025-02-04 17:08:51,081 - util.py[DEBUG]: Writing to /var/lib/cloud/instances/71308115/user-data.txt.i - wb: [600] 308 bytes
2025-02-04 17:08:51,083 - util.py[DEBUG]: Writing to /var/lib/cloud/instances/71308115/vendor-data.txt - wb: [600] 0 bytes
2025-02-04 17:08:51,083 - util.py[DEBUG]: Writing to /var/lib/cloud/instances/71308115/vendor-data.txt.i - wb: [600] 308 bytes
2025-02-04 17:08:51,084 - util.py[DEBUG]: Writing to /var/lib/cloud/instances/71308115/vendor-data2.txt - wb: [600] 0 bytes
2025-02-04 17:08:51,084 - util.py[DEBUG]: Writing to /var/lib/cloud/instances/71308115/vendor-data2.txt.i - wb: [600] 308 bytes
2025-02-04 17:08:51,087 - stages.py[DEBUG]: Using distro class <class 'cloudinit.distros.ubuntu.Distro'>
2025-02-04 17:08:51,089 - helpers.py[DEBUG]: consume_data already ran (freq=once-per-instance)
2025-02-04 17:08:51,089 - handlers.py[DEBUG]: start: init-network/consume-user-data: reading and applying user-data
2025-02-04 17:08:51,091 - stages.py[DEBUG]: Added default handler for {'text/cloud-config-jsonp', 'text/cloud-config'} from CloudConfigPartHandler: [['text/cloud-config', 'text/cloud-config-jsonp']]
2025-02-04 17:08:51,091 - stages.py[DEBUG]: Added default handler for {'text/x-shellscript'} from ShellScriptPartHandler: [['text/x-shellscript']]
2025-02-04 17:08:51,091 - stages.py[DEBUG]: Added default handler for {'text/x-shellscript-per-boot'} from ShellScriptByFreqPartHandler: [['text/x-shellscript-per-boot']]
2025-02-04 17:08:51,091 - stages.py[DEBUG]: Added default handler for {'text/x-shellscript-per-instance'} from ShellScriptByFreqPartHandler: [['text/x-shellscript-per-instance']]
2025-02-04 17:08:51,091 - stages.py[DEBUG]: Added default handler for {'text/x-shellscript-per-once'} from ShellScriptByFreqPartHandler: [['text/x-shellscript-per-once']]
2025-02-04 17:08:51,091 - stages.py[DEBUG]: Added default handler for {'text/cloud-boothook'} from BootHookPartHandler: [['text/cloud-boothook']]
2025-02-04 17:08:51,091 - stages.py[DEBUG]: Added default handler for {'text/jinja2'} from JinjaTemplatePartHandler: [['text/jinja2']]
2025-02-04 17:08:51,092 - handlers[DEBUG]: Calling handler CloudConfigPartHandler: [['text/cloud-config', 'text/cloud-config-jsonp']] (__begin__, None, 3) with frequency always
2025-02-04 17:08:51,092 - handlers[DEBUG]: Calling handler ShellScriptPartHandler: [['text/x-shellscript']] (__begin__, None, 2) with frequency always
2025-02-04 17:08:51,092 - handlers[DEBUG]: Calling handler ShellScriptByFreqPartHandler: [['text/x-shellscript-per-boot']] (__begin__, None, 2) with frequency always
2025-02-04 17:08:51,092 - handlers[DEBUG]: Calling handler ShellScriptByFreqPartHandler: [['text/x-shellscript-per-instance']] (__begin__, None, 2) with frequency always
2025-02-04 17:08:51,092 - handlers[DEBUG]: Calling handler ShellScriptByFreqPartHandler: [['text/x-shellscript-per-once']] (__begin__, None, 2) with frequency always
2025-02-04 17:08:51,092 - handlers[DEBUG]: Calling handler BootHookPartHandler: [['text/cloud-boothook']] (__begin__, None, 2) with frequency always
2025-02-04 17:08:51,092 - handlers[DEBUG]: Calling handler JinjaTemplatePartHandler: [['text/jinja2']] (__begin__, None, 3) with frequency always
2025-02-04 17:08:51,092 - handlers[DEBUG]: {'MIME-Version': '1.0', 'Content-Type': 'text/x-not-multipart', 'Content-Disposition': 'attachment; filename="part-001"'}
2025-02-04 17:08:51,092 - handlers[DEBUG]: Empty payload of type text/x-not-multipart
2025-02-04 17:08:51,092 - handlers[DEBUG]: Calling handler CloudConfigPartHandler: [['text/cloud-config', 'text/cloud-config-jsonp']] (__end__, None, 3) with frequency always
2025-02-04 17:08:51,092 - util.py[DEBUG]: Writing to /var/lib/cloud/instances/71308115/cloud-config.txt - wb: [600] 0 bytes
2025-02-04 17:08:51,093 - handlers[DEBUG]: Calling handler ShellScriptPartHandler: [['text/x-shellscript']] (__end__, None, 2) with frequency always
2025-02-04 17:08:51,093 - handlers[DEBUG]: Calling handler ShellScriptByFreqPartHandler: [['text/x-shellscript-per-boot']] (__end__, None, 2) with frequency always
2025-02-04 17:08:51,093 - handlers[DEBUG]: Calling handler ShellScriptByFreqPartHandler: [['text/x-shellscript-per-instance']] (__end__, None, 2) with frequency always
2025-02-04 17:08:51,093 - handlers[DEBUG]: Calling handler ShellScriptByFreqPartHandler: [['text/x-shellscript-per-once']] (__end__, None, 2) with frequency always
2025-02-04 17:08:51,093 - handlers[DEBUG]: Calling handler BootHookPartHandler: [['text/cloud-boothook']] (__end__, None, 2) with frequency always
2025-02-04 17:08:51,093 - handlers[DEBUG]: Calling handler JinjaTemplatePartHandler: [['text/jinja2']] (__end__, None, 3) with frequency always
2025-02-04 17:08:51,093 - handlers.py[DEBUG]: finish: init-network/consume-user-data: SUCCESS: reading and applying user-data
2025-02-04 17:08:51,093 - handlers.py[DEBUG]: start: init-network/consume-vendor-data: reading and applying vendor-data
2025-02-04 17:08:51,093 - stages.py[DEBUG]: no vendordata from datasource
2025-02-04 17:08:51,093 - handlers.py[DEBUG]: finish: init-network/consume-vendor-data: SUCCESS: reading and applying vendor-data
2025-02-04 17:08:51,093 - handlers.py[DEBUG]: start: init-network/consume-vendor-data2: reading and applying vendor-data2
2025-02-04 17:08:51,093 - stages.py[DEBUG]: no vendordata2 from datasource
2025-02-04 17:08:51,096 - handlers.py[DEBUG]: finish: init-network/consume-vendor-data2: SUCCESS: reading and applying vendor-data2
2025-02-04 17:08:51,096 - util.py[DEBUG]: Reading from /etc/cloud/cloud.cfg (quiet=False)
2025-02-04 17:08:51,096 - util.py[DEBUG]: Reading 3766 bytes from /etc/cloud/cloud.cfg
2025-02-04 17:08:51,096 - util.py[DEBUG]: Attempting to load yaml from string of length 3766 with allowed root types (<class 'dict'>,)
2025-02-04 17:08:51,113 - util.py[DEBUG]: Reading from /etc/cloud/cloud.cfg.d/99-linode.cfg (quiet=False)
2025-02-04 17:08:51,113 - util.py[DEBUG]: Reading 492 bytes from /etc/cloud/cloud.cfg.d/99-linode.cfg
2025-02-04 17:08:51,113 - util.py[DEBUG]: Attempting to load yaml from string of length 492 with allowed root types (<class 'dict'>,)
2025-02-04 17:08:51,115 - util.py[DEBUG]: Reading from /etc/cloud/cloud.cfg.d/90_dpkg.cfg (quiet=False)
2025-02-04 17:08:51,115 - util.py[DEBUG]: Reading 333 bytes from /etc/cloud/cloud.cfg.d/90_dpkg.cfg
2025-02-04 17:08:51,115 - util.py[DEBUG]: Attempting to load yaml from string of length 333 with allowed root types (<class 'dict'>,)
2025-02-04 17:08:51,117 - util.py[DEBUG]: Reading from /etc/cloud/cloud.cfg.d/05_logging.cfg (quiet=False)
2025-02-04 17:08:51,117 - util.py[DEBUG]: Reading 2071 bytes from /etc/cloud/cloud.cfg.d/05_logging.cfg
2025-02-04 17:08:51,117 - util.py[DEBUG]: Attempting to load yaml from string of length 2071 with allowed root types (<class 'dict'>,)
2025-02-04 17:08:51,121 - util.py[DEBUG]: Reading from /run/cloud-init/cloud.cfg (quiet=False)
2025-02-04 17:08:51,121 - util.py[DEBUG]: Reading 34 bytes from /run/cloud-init/cloud.cfg
2025-02-04 17:08:51,121 - util.py[DEBUG]: Attempting to load yaml from string of length 34 with allowed root types (<class 'dict'>,)
2025-02-04 17:08:51,121 - util.py[DEBUG]: Attempting to load yaml from string of length 0 with allowed root types (<class 'dict'>,)
2025-02-04 17:08:51,121 - util.py[DEBUG]: loaded blob returned None, returning default.
2025-02-04 17:08:51,122 - util.py[DEBUG]: Reading from /var/lib/cloud/instance/cloud-config.txt (quiet=False)
2025-02-04 17:08:51,122 - util.py[DEBUG]: Reading 0 bytes from /var/lib/cloud/instance/cloud-config.txt
2025-02-04 17:08:51,122 - util.py[DEBUG]: Attempting to load yaml from string of length 0 with allowed root types (<class 'dict'>,)
2025-02-04 17:08:51,122 - util.py[DEBUG]: loaded blob returned None, returning default.
2025-02-04 17:08:51,123 - atomic_helper.py[DEBUG]: Atomically writing to file /run/cloud-init/combined-cloud-config.json (via temporary file /run/cloud-init/tmp3ptt2lvx) - w: [600] 5471 bytes/chars
2025-02-04 17:08:51,123 - util.py[DEBUG]: Reading from /run/cloud-init/instance-data-sensitive.json (quiet=False)
2025-02-04 17:08:51,124 - util.py[DEBUG]: Reading 8726 bytes from /run/cloud-init/instance-data-sensitive.json
2025-02-04 17:08:51,124 - atomic_helper.py[DEBUG]: Atomically writing to file /run/cloud-init/instance-data-sensitive.json (via temporary file /run/cloud-init/tmpnd2slyll) - w: [600] 10709 bytes/chars
2025-02-04 17:08:51,124 - main.py[DEBUG]: Skipping user-data validation. No user-data found.
2025-02-04 17:08:51,125 - util.py[DEBUG]: Reading from /var/lib/cloud/instance/cloud-config.txt (quiet=False)
2025-02-04 17:08:51,125 - util.py[DEBUG]: Reading 0 bytes from /var/lib/cloud/instance/cloud-config.txt
2025-02-04 17:08:51,125 - util.py[DEBUG]: Attempting to load yaml from string of length 0 with allowed root types (<class 'dict'>,)
2025-02-04 17:08:51,125 - util.py[DEBUG]: loaded blob returned None, returning default.
2025-02-04 17:08:51,127 - handlers.py[DEBUG]: start: init-network/activate-datasource: activating datasource
2025-02-04 17:08:51,128 - util.py[DEBUG]: Writing to /var/lib/cloud/instance/obj.pkl - wb: [400] 9372 bytes
2025-02-04 17:08:51,128 - handlers.py[DEBUG]: finish: init-network/activate-datasource: SUCCESS: activating datasource
2025-02-04 17:08:51,129 - main.py[DEBUG]: no di_report found in config.
2025-02-04 17:08:51,140 - stages.py[DEBUG]: Using distro class <class 'cloudinit.distros.ubuntu.Distro'>
2025-02-04 17:08:51,142 - modules.py[INFO]: Skipping modules 'bootcmd,write_files,disk_setup,update_etc_hosts,ca_certs,rsyslog' because no applicable config is provided.
2025-02-04 17:08:51,142 - modules.py[DEBUG]: Running module seed_random (<module 'cloudinit.config.cc_seed_random' from '/usr/lib/python3/dist-packages/cloudinit/config/cc_seed_random.py'>) with frequency once-per-instance
2025-02-04 17:08:51,142 - handlers.py[DEBUG]: start: init-network/config-seed_random: running config-seed_random with frequency once-per-instance
2025-02-04 17:08:51,142 - helpers.py[DEBUG]: config-seed_random already ran (freq=once-per-instance)
2025-02-04 17:08:51,143 - handlers.py[DEBUG]: finish: init-network/config-seed_random: SUCCESS: config-seed_random previously ran
2025-02-04 17:08:51,143 - modules.py[DEBUG]: Running module growpart (<module 'cloudinit.config.cc_growpart' from '/usr/lib/python3/dist-packages/cloudinit/config/cc_growpart.py'>) with frequency always
2025-02-04 17:08:51,143 - handlers.py[DEBUG]: start: init-network/config-growpart: running config-growpart with frequency always
2025-02-04 17:08:51,143 - helpers.py[DEBUG]: Running config-growpart using lock (<cloudinit.helpers.DummyLock object at 0x7fd9bdf04f10>)
2025-02-04 17:08:51,143 - cc_growpart.py[DEBUG]: No 'growpart' entry in cfg.  Using default: {'mode': 'auto', 'devices': ['/'], 'ignore_growroot_disabled': False}
2025-02-04 17:08:51,143 - subp.py[DEBUG]: Running command ['growpart', '--help'] with allowed return codes [0] (shell=False, capture=True)
2025-02-04 17:08:51,146 - util.py[DEBUG]: Reading from /proc/569/mountinfo (quiet=False)
2025-02-04 17:08:51,146 - util.py[DEBUG]: Reading 2056 bytes from /proc/569/mountinfo
2025-02-04 17:08:51,146 - cc_growpart.py[DEBUG]: growpart found fs=ext4
2025-02-04 17:08:51,146 - cc_growpart.py[DEBUG]: '/' SKIPPED: device_part_info(/dev/sda) failed: /dev/sda not a partition
2025-02-04 17:08:51,146 - handlers.py[DEBUG]: finish: init-network/config-growpart: SUCCESS: config-growpart ran successfully and took 0.004 seconds
2025-02-04 17:08:51,146 - modules.py[DEBUG]: Running module resizefs (<module 'cloudinit.config.cc_resizefs' from '/usr/lib/python3/dist-packages/cloudinit/config/cc_resizefs.py'>) with frequency always
2025-02-04 17:08:51,147 - handlers.py[DEBUG]: start: init-network/config-resizefs: running config-resizefs with frequency always
2025-02-04 17:08:51,147 - helpers.py[DEBUG]: Running config-resizefs using lock (<cloudinit.helpers.DummyLock object at 0x7fd9bdf05b10>)
2025-02-04 17:08:51,147 - util.py[DEBUG]: Reading from /proc/569/mountinfo (quiet=False)
2025-02-04 17:08:51,147 - util.py[DEBUG]: Reading 2056 bytes from /proc/569/mountinfo
2025-02-04 17:08:51,147 - cc_resizefs.py[DEBUG]: resize_info: dev=/dev/sda mnt_point=/ path=/
2025-02-04 17:08:51,147 - cc_resizefs.py[DEBUG]: Resizing / (ext4) using resize2fs /dev/sda
2025-02-04 17:08:51,147 - subp.py[DEBUG]: Running command ('resize2fs', '/dev/sda') with allowed return codes [0] (shell=False, capture=True)
2025-02-04 17:08:51,161 - performance.py[DEBUG]: Running ('resize2fs', '/dev/sda') took 0.014 seconds
2025-02-04 17:08:51,161 - cc_resizefs.py[DEBUG]: Resized root filesystem (type=ext4, val=True)
2025-02-04 17:08:51,161 - handlers.py[DEBUG]: finish: init-network/config-resizefs: SUCCESS: config-resizefs ran successfully and took 0.014 seconds
2025-02-04 17:08:51,161 - modules.py[DEBUG]: Running module mounts (<module 'cloudinit.config.cc_mounts' from '/usr/lib/python3/dist-packages/cloudinit/config/cc_mounts.py'>) with frequency once-per-instance
2025-02-04 17:08:51,161 - handlers.py[DEBUG]: start: init-network/config-mounts: running config-mounts with frequency once-per-instance
2025-02-04 17:08:51,162 - helpers.py[DEBUG]: config-mounts already ran (freq=once-per-instance)
2025-02-04 17:08:51,162 - handlers.py[DEBUG]: finish: init-network/config-mounts: SUCCESS: config-mounts previously ran
2025-02-04 17:08:51,162 - modules.py[DEBUG]: Running module set_hostname (<module 'cloudinit.config.cc_set_hostname' from '/usr/lib/python3/dist-packages/cloudinit/config/cc_set_hostname.py'>) with frequency once-per-instance
2025-02-04 17:08:51,162 - handlers.py[DEBUG]: start: init-network/config-set_hostname: running config-set_hostname with frequency once-per-instance
2025-02-04 17:08:51,162 - helpers.py[DEBUG]: config-set_hostname already ran (freq=once-per-instance)
2025-02-04 17:08:51,162 - handlers.py[DEBUG]: finish: init-network/config-set_hostname: SUCCESS: config-set_hostname previously ran
2025-02-04 17:08:51,162 - modules.py[DEBUG]: Running module update_hostname (<module 'cloudinit.config.cc_update_hostname' from '/usr/lib/python3/dist-packages/cloudinit/config/cc_update_hostname.py'>) with frequency always
2025-02-04 17:08:51,163 - handlers.py[DEBUG]: start: init-network/config-update_hostname: running config-update_hostname with frequency always
2025-02-04 17:08:51,163 - helpers.py[DEBUG]: Running config-update_hostname using lock (<cloudinit.helpers.DummyLock object at 0x7fd9bdf06c20>)
2025-02-04 17:08:51,163 - util.py[DEBUG]: Reading from /etc/hosts (quiet=False)
2025-02-04 17:08:51,163 - util.py[DEBUG]: Reading 181 bytes from /etc/hosts
2025-02-04 17:08:51,163 - util.py[DEBUG]: Reading from /etc/hosts (quiet=False)
2025-02-04 17:08:51,163 - util.py[DEBUG]: Reading 181 bytes from /etc/hosts
2025-02-04 17:08:51,163 - cc_update_hostname.py[DEBUG]: Hostname is localhost. Let other services handle this.
2025-02-04 17:08:51,163 - handlers.py[DEBUG]: finish: init-network/config-update_hostname: SUCCESS: config-update_hostname ran successfully and took 0.000 seconds
2025-02-04 17:08:51,163 - modules.py[DEBUG]: Running module users_groups (<module 'cloudinit.config.cc_users_groups' from '/usr/lib/python3/dist-packages/cloudinit/config/cc_users_groups.py'>) with frequency once-per-instance
2025-02-04 17:08:51,163 - handlers.py[DEBUG]: start: init-network/config-users_groups: running config-users_groups with frequency once-per-instance
2025-02-04 17:08:51,163 - helpers.py[DEBUG]: config-users_groups already ran (freq=once-per-instance)
2025-02-04 17:08:51,164 - handlers.py[DEBUG]: finish: init-network/config-users_groups: SUCCESS: config-users_groups previously ran
2025-02-04 17:08:51,164 - modules.py[DEBUG]: Running module ssh (<module 'cloudinit.config.cc_ssh' from '/usr/lib/python3/dist-packages/cloudinit/config/cc_ssh.py'>) with frequency once-per-instance
2025-02-04 17:08:51,164 - handlers.py[DEBUG]: start: init-network/config-ssh: running config-ssh with frequency once-per-instance
2025-02-04 17:08:51,164 - helpers.py[DEBUG]: config-ssh already ran (freq=once-per-instance)
2025-02-04 17:08:51,164 - handlers.py[DEBUG]: finish: init-network/config-ssh: SUCCESS: config-ssh previously ran
2025-02-04 17:08:51,164 - modules.py[DEBUG]: Running module set_passwords (<module 'cloudinit.config.cc_set_passwords' from '/usr/lib/python3/dist-packages/cloudinit/config/cc_set_passwords.py'>) with frequency once-per-instance
2025-02-04 17:08:51,164 - handlers.py[DEBUG]: start: init-network/config-set_passwords: running config-set_passwords with frequency once-per-instance
2025-02-04 17:08:51,164 - helpers.py[DEBUG]: config-set_passwords already ran (freq=once-per-instance)
2025-02-04 17:08:51,164 - handlers.py[DEBUG]: finish: init-network/config-set_passwords: SUCCESS: config-set_passwords previously ran
2025-02-04 17:08:51,164 - main.py[DEBUG]: Ran 9 modules with 0 failures
2025-02-04 17:08:51,165 - util.py[DEBUG]: Reading from /proc/uptime (quiet=False)
2025-02-04 17:08:51,165 - util.py[DEBUG]: Reading 11 bytes from /proc/uptime
2025-02-04 17:08:51,165 - atomic_helper.py[DEBUG]: Atomically writing to file /var/lib/cloud/data/status.json (via temporary file /var/lib/cloud/data/tmpfyezmx76) - w: [644] 504 bytes/chars
2025-02-04 17:08:51,166 - performance.py[DEBUG]: cloud-init stage: 'init-network' took 0.229 seconds
2025-02-04 17:08:51,166 - handlers.py[DEBUG]: finish: init-network: SUCCESS: searching for network datasources
2025-02-04 17:08:52,343 - log_util.py[DEBUG]: Cloud-init v. 24.4-0ubuntu1~22.04.1 running 'modules:config' at Tue, 04 Feb 2025 17:08:52 +0000. Up 12.41 seconds.
2025-02-04 17:08:52,343 - main.py[INFO]: PID [1] started cloud-init 'modules:config'.
2025-02-04 17:08:52,363 - stages.py[DEBUG]: Using distro class <class 'cloudinit.distros.ubuntu.Distro'>
2025-02-04 17:08:52,365 - modules.py[INFO]: Skipping modules 'wireguard,snap,ubuntu_autoinstall,keyboard,apt_pipelining,ubuntu_pro,ntp,timezone,disable_ec2_metadata,runcmd' because no applicable config is provided.
2025-02-04 17:08:52,365 - modules.py[DEBUG]: Running module ssh_import_id (<module 'cloudinit.config.cc_ssh_import_id' from '/usr/lib/python3/dist-packages/cloudinit/config/cc_ssh_import_id.py'>) with frequency once-per-instance
2025-02-04 17:08:52,365 - handlers.py[DEBUG]: start: modules-config/config-ssh_import_id: running config-ssh_import_id with frequency once-per-instance
2025-02-04 17:08:52,365 - helpers.py[DEBUG]: config-ssh_import_id already ran (freq=once-per-instance)
2025-02-04 17:08:52,365 - handlers.py[DEBUG]: finish: modules-config/config-ssh_import_id: SUCCESS: config-ssh_import_id previously ran
2025-02-04 17:08:52,365 - modules.py[DEBUG]: Running module locale (<module 'cloudinit.config.cc_locale' from '/usr/lib/python3/dist-packages/cloudinit/config/cc_locale.py'>) with frequency once-per-instance
2025-02-04 17:08:52,366 - handlers.py[DEBUG]: start: modules-config/config-locale: running config-locale with frequency once-per-instance
2025-02-04 17:08:52,366 - helpers.py[DEBUG]: config-locale already ran (freq=once-per-instance)
2025-02-04 17:08:52,366 - handlers.py[DEBUG]: finish: modules-config/config-locale: SUCCESS: config-locale previously ran
2025-02-04 17:08:52,366 - modules.py[DEBUG]: Running module grub_dpkg (<module 'cloudinit.config.cc_grub_dpkg' from '/usr/lib/python3/dist-packages/cloudinit/config/cc_grub_dpkg.py'>) with frequency once-per-instance
2025-02-04 17:08:52,366 - handlers.py[DEBUG]: start: modules-config/config-grub_dpkg: running config-grub_dpkg with frequency once-per-instance
2025-02-04 17:08:52,366 - helpers.py[DEBUG]: config-grub_dpkg already ran (freq=once-per-instance)
2025-02-04 17:08:52,366 - handlers.py[DEBUG]: finish: modules-config/config-grub_dpkg: SUCCESS: config-grub_dpkg previously ran
2025-02-04 17:08:52,366 - modules.py[DEBUG]: Running module apt_configure (<module 'cloudinit.config.cc_apt_configure' from '/usr/lib/python3/dist-packages/cloudinit/config/cc_apt_configure.py'>) with frequency once-per-instance
2025-02-04 17:08:52,371 - handlers.py[DEBUG]: start: modules-config/config-apt_configure: running config-apt_configure with frequency once-per-instance
2025-02-04 17:08:52,371 - helpers.py[DEBUG]: config-apt_configure already ran (freq=once-per-instance)
2025-02-04 17:08:52,372 - handlers.py[DEBUG]: finish: modules-config/config-apt_configure: SUCCESS: config-apt_configure previously ran
2025-02-04 17:08:52,372 - modules.py[DEBUG]: Running module byobu (<module 'cloudinit.config.cc_byobu' from '/usr/lib/python3/dist-packages/cloudinit/config/cc_byobu.py'>) with frequency once-per-instance
2025-02-04 17:08:52,375 - handlers.py[DEBUG]: start: modules-config/config-byobu: running config-byobu with frequency once-per-instance
2025-02-04 17:08:52,375 - helpers.py[DEBUG]: config-byobu already ran (freq=once-per-instance)
2025-02-04 17:08:52,375 - handlers.py[DEBUG]: finish: modules-config/config-byobu: SUCCESS: config-byobu previously ran
2025-02-04 17:08:52,375 - main.py[DEBUG]: Ran 5 modules with 0 failures
2025-02-04 17:08:52,375 - util.py[DEBUG]: Reading from /proc/uptime (quiet=False)
2025-02-04 17:08:52,375 - util.py[DEBUG]: Reading 11 bytes from /proc/uptime
2025-02-04 17:08:52,376 - atomic_helper.py[DEBUG]: Atomically writing to file /var/lib/cloud/data/status.json (via temporary file /var/lib/cloud/data/tmp2azlb_2d) - w: [644] 506 bytes/chars
2025-02-04 17:08:52,377 - performance.py[DEBUG]: cloud-init stage: 'modules-config' took 0.224 seconds
2025-02-04 17:08:52,377 - handlers.py[DEBUG]: finish: modules-config: SUCCESS: running modules for config
2025-02-04 17:08:52,784 - log_util.py[DEBUG]: Cloud-init v. 24.4-0ubuntu1~22.04.1 running 'modules:final' at Tue, 04 Feb 2025 17:08:52 +0000. Up 12.93 seconds.
2025-02-04 17:08:52,784 - main.py[INFO]: PID [1] started cloud-init 'modules:final'.
2025-02-04 17:08:52,807 - stages.py[DEBUG]: Using distro class <class 'cloudinit.distros.ubuntu.Distro'>
2025-02-04 17:08:52,809 - modules.py[INFO]: Skipping modules 'package_update_upgrade_install,fan,landscape,lxd,ubuntu_drivers,write_files_deferred,puppet,chef,ansible,mcollective,salt_minion,phone_home,power_state_change' because no applicable config is provided.
2025-02-04 17:08:52,810 - modules.py[DEBUG]: Running module reset_rmc (<module 'cloudinit.config.cc_reset_rmc' from '/usr/lib/python3/dist-packages/cloudinit/config/cc_reset_rmc.py'>) with frequency once-per-instance
2025-02-04 17:08:52,810 - handlers.py[DEBUG]: start: modules-final/config-reset_rmc: running config-reset_rmc with frequency once-per-instance
2025-02-04 17:08:52,810 - helpers.py[DEBUG]: config-reset_rmc already ran (freq=once-per-instance)
2025-02-04 17:08:52,810 - handlers.py[DEBUG]: finish: modules-final/config-reset_rmc: SUCCESS: config-reset_rmc previously ran
2025-02-04 17:08:52,810 - modules.py[DEBUG]: Running module scripts_vendor (<module 'cloudinit.config.cc_scripts_vendor' from '/usr/lib/python3/dist-packages/cloudinit/config/cc_scripts_vendor.py'>) with frequency once-per-instance
2025-02-04 17:08:52,810 - handlers.py[DEBUG]: start: modules-final/config-scripts_vendor: running config-scripts_vendor with frequency once-per-instance
2025-02-04 17:08:52,810 - helpers.py[DEBUG]: config-scripts_vendor already ran (freq=once-per-instance)
2025-02-04 17:08:52,810 - handlers.py[DEBUG]: finish: modules-final/config-scripts_vendor: SUCCESS: config-scripts_vendor previously ran
2025-02-04 17:08:52,811 - modules.py[DEBUG]: Running module scripts_per_once (<module 'cloudinit.config.cc_scripts_per_once' from '/usr/lib/python3/dist-packages/cloudinit/config/cc_scripts_per_once.py'>) with frequency once
2025-02-04 17:08:52,811 - handlers.py[DEBUG]: start: modules-final/config-scripts_per_once: running config-scripts_per_once with frequency once
2025-02-04 17:08:52,811 - helpers.py[DEBUG]: config-scripts_per_once already ran (freq=once)
2025-02-04 17:08:52,811 - handlers.py[DEBUG]: finish: modules-final/config-scripts_per_once: SUCCESS: config-scripts_per_once previously ran
2025-02-04 17:08:52,811 - modules.py[DEBUG]: Running module scripts_per_boot (<module 'cloudinit.config.cc_scripts_per_boot' from '/usr/lib/python3/dist-packages/cloudinit/config/cc_scripts_per_boot.py'>) with frequency always
2025-02-04 17:08:52,811 - handlers.py[DEBUG]: start: modules-final/config-scripts_per_boot: running config-scripts_per_boot with frequency always
2025-02-04 17:08:52,811 - helpers.py[DEBUG]: Running config-scripts_per_boot using lock (<cloudinit.helpers.DummyLock object at 0x7f6dd8017be0>)
2025-02-04 17:08:52,812 - handlers.py[DEBUG]: finish: modules-final/config-scripts_per_boot: SUCCESS: config-scripts_per_boot ran successfully and took 0.000 seconds
2025-02-04 17:08:52,812 - modules.py[DEBUG]: Running module scripts_per_instance (<module 'cloudinit.config.cc_scripts_per_instance' from '/usr/lib/python3/dist-packages/cloudinit/config/cc_scripts_per_instance.py'>) with frequency once-per-instance
2025-02-04 17:08:52,812 - handlers.py[DEBUG]: start: modules-final/config-scripts_per_instance: running config-scripts_per_instance with frequency once-per-instance
2025-02-04 17:08:52,812 - helpers.py[DEBUG]: config-scripts_per_instance already ran (freq=once-per-instance)
2025-02-04 17:08:52,812 - handlers.py[DEBUG]: finish: modules-final/config-scripts_per_instance: SUCCESS: config-scripts_per_instance previously ran
2025-02-04 17:08:52,812 - modules.py[DEBUG]: Running module scripts_user (<module 'cloudinit.config.cc_scripts_user' from '/usr/lib/python3/dist-packages/cloudinit/config/cc_scripts_user.py'>) with frequency once-per-instance
2025-02-04 17:08:52,813 - handlers.py[DEBUG]: start: modules-final/config-scripts_user: running config-scripts_user with frequency once-per-instance
2025-02-04 17:08:52,813 - helpers.py[DEBUG]: config-scripts_user already ran (freq=once-per-instance)
2025-02-04 17:08:52,813 - handlers.py[DEBUG]: finish: modules-final/config-scripts_user: SUCCESS: config-scripts_user previously ran
2025-02-04 17:08:52,813 - modules.py[DEBUG]: Running module ssh_authkey_fingerprints (<module 'cloudinit.config.cc_ssh_authkey_fingerprints' from '/usr/lib/python3/dist-packages/cloudinit/config/cc_ssh_authkey_fingerprints.py'>) with frequency once-per-instance
2025-02-04 17:08:52,813 - handlers.py[DEBUG]: start: modules-final/config-ssh_authkey_fingerprints: running config-ssh_authkey_fingerprints with frequency once-per-instance
2025-02-04 17:08:52,813 - helpers.py[DEBUG]: config-ssh_authkey_fingerprints already ran (freq=once-per-instance)
2025-02-04 17:08:52,813 - handlers.py[DEBUG]: finish: modules-final/config-ssh_authkey_fingerprints: SUCCESS: config-ssh_authkey_fingerprints previously ran
2025-02-04 17:08:52,813 - modules.py[DEBUG]: Running module keys_to_console (<module 'cloudinit.config.cc_keys_to_console' from '/usr/lib/python3/dist-packages/cloudinit/config/cc_keys_to_console.py'>) with frequency once-per-instance
2025-02-04 17:08:52,813 - handlers.py[DEBUG]: start: modules-final/config-keys_to_console: running config-keys_to_console with frequency once-per-instance
2025-02-04 17:08:52,813 - helpers.py[DEBUG]: config-keys_to_console already ran (freq=once-per-instance)
2025-02-04 17:08:52,813 - handlers.py[DEBUG]: finish: modules-final/config-keys_to_console: SUCCESS: config-keys_to_console previously ran
2025-02-04 17:08:52,814 - modules.py[DEBUG]: Running module install_hotplug (<module 'cloudinit.config.cc_install_hotplug' from '/usr/lib/python3/dist-packages/cloudinit/config/cc_install_hotplug.py'>) with frequency once-per-instance
2025-02-04 17:08:52,814 - handlers.py[DEBUG]: start: modules-final/config-install_hotplug: running config-install_hotplug with frequency once-per-instance
2025-02-04 17:08:52,814 - helpers.py[DEBUG]: config-install_hotplug already ran (freq=once-per-instance)
2025-02-04 17:08:52,814 - handlers.py[DEBUG]: finish: modules-final/config-install_hotplug: SUCCESS: config-install_hotplug previously ran
2025-02-04 17:08:52,814 - modules.py[DEBUG]: Running module final_message (<module 'cloudinit.config.cc_final_message' from '/usr/lib/python3/dist-packages/cloudinit/config/cc_final_message.py'>) with frequency always
2025-02-04 17:08:52,814 - handlers.py[DEBUG]: start: modules-final/config-final_message: running config-final_message with frequency always
2025-02-04 17:08:52,814 - helpers.py[DEBUG]: Running config-final_message using lock (<cloudinit.helpers.DummyLock object at 0x7f6dd8017fa0>)
2025-02-04 17:08:52,814 - util.py[DEBUG]: Reading from /proc/uptime (quiet=False)
2025-02-04 17:08:52,814 - util.py[DEBUG]: Reading 11 bytes from /proc/uptime
2025-02-04 17:08:52,822 - log_util.py[DEBUG]: Cloud-init v. 24.4-0ubuntu1~22.04.1 finished at Tue, 04 Feb 2025 17:08:52 +0000. Datasource DataSourceAkamaiLocal.  Up 13.01 seconds
2025-02-04 17:08:52,822 - util.py[DEBUG]: Writing to /var/lib/cloud/instance/boot-finished - wb: [644] 67 bytes
2025-02-04 17:08:52,823 - handlers.py[DEBUG]: finish: modules-final/config-final_message: SUCCESS: config-final_message ran successfully and took 0.008 seconds
2025-02-04 17:08:52,823 - main.py[DEBUG]: Ran 10 modules with 0 failures
2025-02-04 17:08:52,823 - util.py[DEBUG]: Reading from /proc/uptime (quiet=False)
2025-02-04 17:08:52,823 - util.py[DEBUG]: Reading 11 bytes from /proc/uptime
2025-02-04 17:08:52,823 - atomic_helper.py[DEBUG]: Atomically writing to file /var/lib/cloud/data/status.json (via temporary file /var/lib/cloud/data/tmpxk292ju5) - w: [644] 508 bytes/chars
2025-02-04 17:08:52,824 - atomic_helper.py[DEBUG]: Atomically writing to file /var/lib/cloud/data/result.json (via temporary file /var/lib/cloud/data/tmp9tnf6f9f) - w: [644] 72 bytes/chars
2025-02-04 17:08:52,824 - util.py[DEBUG]: Creating symbolic link from '/run/cloud-init/result.json' => '../../var/lib/cloud/data/result.json'
2025-02-04 17:08:52,824 - performance.py[DEBUG]: cloud-init stage: 'modules-final' took 0.126 seconds
2025-02-04 17:08:52,824 - handlers.py[DEBUG]: finish: modules-final: SUCCESS: running modules for final
